Workbook
Name curve_key: 'Reference'!$A$5:$A$37
Name curve_x1: 'Reference'!$G$5:$G$37
Name curve_y1: 'Reference'!$O$5:$O$37
Name curve_x2: 'Reference'!$H$5:$H$37
Name curve_y2: 'Reference'!$P$5:$P$37
Name curve_x3: 'Reference'!$I$5:$I$37
Name curve_y3: 'Reference'!$Q$5:$Q$37
Name curve_x4: 'Reference'!$J$5:$J$37
Name curve_y4: 'Reference'!$R$5:$R$37
Name curve_x5: 'Reference'!$K$5:$K$37
Name curve_y5: 'Reference'!$S$5:$S$37
Name curve_x6: 'Reference'!$L$5:$L$37
Name curve_y6: 'Reference'!$T$5:$T$37
Name curve_x7: 'Reference'!$M$5:$M$37
Name curve_y7: 'Reference'!$U$5:$U$37
Name curve_x8: 'Reference'!$N$5:$N$37
Name curve_y8: 'Reference'!$V$5:$V$37
Name strata_spring_phab_bfwd_rat: 'Reference'!$A$41:$A$43
Name strata_spring_phab_xbkf_h: 'Reference'!$A$44:$A$46
Name idx_spring_pctimp2019ws: 'Metrics'!$V$5
Name idx_spring_pctag2019ws: 'Metrics'!$V$6
Name idx_spring_pctwet2019ws: 'Metrics'!$V$7
Name idx_spring_rddensws: 'Metrics'!$V$8
Name idx_spring_bfiws: 'Metrics'!$V$9
Name idx_spring_dorws: 'Metrics'!$V$10
Name idx_spring_phab_bfwd_rat: 'Metrics'!$V$11
Name idx_spring_phab_rp100_cm: 'Metrics'!$V$12
Name idx_spring_phab_xbkf_h: 'Metrics'!$V$13
Name idx_spring_phab_pct_safn: 'Metrics'!$V$14
Name idx_spring_phab_xembed: 'Metrics'!$V$15
Name idx_spring_phab_sinu: 'Metrics'!$V$16
Name idx_spring_phab_xbka: 'Metrics'!$V$17
Name idx_spring_phab_lrbs_use: 'Metrics'!$V$18
Name idx_spring_phab_lwdeqvolm100: 'Metrics'!$V$19
Name idx_spring_chem_chla: 'Metrics'!$V$20
Name idx_spring_phab_xcdenmid: 'Metrics'!$V$21
Name idx_spring_phab_xcmgw: 'Metrics'!$V$22
Name idx_spring_chem_ntl: 'Metrics'!$V$23
Name idx_spring_chem_ptl: 'Metrics'!$V$24
Name idx_spring_chem_ph: 'Metrics'!$V$25
Name idx_spring_chem_turb: 'Metrics'!$V$26
Name idx_spring_phab_pct_fast: 'Metrics'!$V$27
Name idx_spring_phab_xfc_nat: 'Metrics'!$V$28
Name idx_spring_fish_nat_totlntax: 'Metrics'!$V$29
Name idx_spring_bent_totlntax: 'Metrics'!$V$30
Name idx_spring_bent_ept_ntax: 'Metrics'!$V$31
Name idx_spring_bent_hprime: 'Metrics'!$V$32
Name idx_spring_nid_dams_1mi: 'Metrics'!$V$33
Name fs_catchment_hydrology: 'Results'!$B$4
Name fs_surface_water_storage: 'Results'!$B$5
Name fs_reach_inflow: 'Results'!$B$6
Name fs_streamflow_regime: 'Results'!$B$7
Name fs_low_flow_baseflow_dynamics: 'Results'!$B$8
Name fs_high_flow_dynamics: 'Results'!$B$9
Name fs_floodplain_connectivity: 'Results'!$B$10
Name fs_hyporheic_connectivity: 'Results'!$B$11
Name fs_channel_evolution: 'Results'!$B$12
Name fs_channel_floodplain_dynamics: 'Results'!$B$13
Name fs_sediment_continuity: 'Results'!$B$14
Name fs_bed_composition_bedform_dynamics: 'Results'!$B$15

Sheet Instructions
A1: Detailed Evaluation of Ecosystem Processes (DEEP) Calculator
A2: Cross Timbers reference assessment
A3: Assessment status: Draft. For research and regional assessment development only.
A4: This workbook scores one detailed assessment. It carries the assessment's metrics and their reference curves, and it scores exactly as the DEEP web application does.
A5: Reference condition. Reference condition is set by a fixed landscape-pressure screen, never by a score. 1 curve is fitted to this ecoregion's own streams under the documented regional screen, which relaxes agriculture only. 20 borrow comparable least-disturbed stations from a wider region, stating the region and the transfer risk. 4 carry the national reference label: reference curve fitted to comparable least-disturbed stations drawn from the national pool, because this ecoregion and its parents hold too few of their own. 5 carry the published benchmark label: scored against a published criterion rather than against stations from this ecoregion. The criterion carries its own definition of reference, which need not match this assessment's. 12 rest on a flagged transfer: a comparable least-disturbed pool the recovery test did not confirm for this ecoregion, used because no validated source supports the metric here, with transfer risk unvalidated and confidence capped. 1 function rests on a method adopted from EASI's national screening method (provisional), because no reference pool, national donor, model, published benchmark or flagged transfer supported the function in this ecoregion. A metric that no basis supports is not scored, and the function it would have scored is reported as unassessed.
A6: 1. On the DEEP Score sheet, fill the site block and type each metric's measured value in its orange cell, in the units shown.
A7: 2. Where a metric has several curve sets, choose the set that fits the reach from the list beside the value. Left alone, the default set applies.
A8: 3. Leave a value blank when the metric does not apply. It drops out of the score.
A9: 4. A metric that serves more than one function is entered once. The grey cells repeat it.
A10: 5. The index of each metric (0 to 1) is read from its reference curve. The function score is the mean index of the function's metrics times 15.
A11: 6. The outcome sub-indices weigh each function's score by its direct or indirect contribution, and the Ecosystem Condition Index is the mean of the three.
A12: Condition classes. Index at or below 0.39 Non-Functioning, at or below 0.69 Functioning At-Risk, above Functioning. Function score at or below 5 Non-Functioning, at or below 10 Functioning At-Risk, above Functioning.
... A14: The sheets are protected against accidental edits. The password is deep.

Sheet DEEP Score
A1: Detailed Evaluation of Ecosystem Processes (DEEP) Calculator
A2: Cross Timbers reference assessment
A3: Version 1 | Draft | USEPA NRSA 2013-24 (L3 ecoregion 29), StreamCurves regional analysis, methodology 0.16-provisional
A4: Assessment status: Draft. For research and regional assessment development only.
A5: Stream or site
A6: Reach ID
A7: Coordinates
A8: Date
A9: Assessor(s)
A11: Category | B11: Function | C11: Metric | D11: Units | E11: Value | F11: Curve set | G11: Index | H11: Function score (0 to 15) | I11: Condition
A12: Hydrology | B12: Catchment hydrology | C12: Impervious surface | D12: % | G12: =IF('Metrics'!$V$5="","",'Metrics'!$V$5) | H12: =IF('Results'!$B$4="","",'Results'!$B$4) | I12: =IF('DEEP Score'!$H$12="","",IF('DEEP Score'!$H$12<=5,"Non-Functioning",IF('DEEP Score'!$H$12<=10,"Functioning At-Risk","Functioning")))
C13: Agriculture, crop and hay | D13: % | G13: =IF('Metrics'!$V$6="","",'Metrics'!$V$6)
A14: Hydrology | B14: Surface water storage | C14: Wetland cover of the watershed | D14: % | G14: =IF('Metrics'!$V$7="","",'Metrics'!$V$7) | H14: =IF('Results'!$B$5="","",'Results'!$B$5) | I14: =IF('DEEP Score'!$H$14="","",IF('DEEP Score'!$H$14<=5,"Non-Functioning",IF('DEEP Score'!$H$14<=10,"Functioning At-Risk","Functioning")))
A15: Hydrology | B15: Reach inflow | C15: Road density | D15: km/sq km | G15: =IF('Metrics'!$V$8="","",'Metrics'!$V$8) | H15: =IF('Results'!$B$6="","",'Results'!$B$6) | I15: =IF('DEEP Score'!$H$15="","",IF('DEEP Score'!$H$15<=5,"Non-Functioning",IF('DEEP Score'!$H$15<=10,"Functioning At-Risk","Functioning")))
A16: Hydrology | B16: Streamflow regime | C16: Base flow index | D16: % | G16: =IF('Metrics'!$V$9="","",'Metrics'!$V$9) | H16: =IF('Results'!$B$7="","",'Results'!$B$7) | I16: =IF('DEEP Score'!$H$16="","",IF('DEEP Score'!$H$16<=5,"Non-Functioning",IF('DEEP Score'!$H$16<=10,"Functioning At-Risk","Functioning")))
C17: Degree of regulation | D17: % | G17: =IF('Metrics'!$V$10="","",'Metrics'!$V$10)
A18: Hydraulics | B18: Low flow and baseflow dynamics | C18: Bankfull width:depth ratio | F18: All streams (pooled) | G18: =IF('Metrics'!$V$11="","",'Metrics'!$V$11) | H18: =IF('Results'!$B$8="","",'Results'!$B$8) | I18: =IF('DEEP Score'!$H$18="","",IF('DEEP Score'!$H$18<=5,"Non-Functioning",IF('DEEP Score'!$H$18<=10,"Functioning At-Risk","Functioning")))
C19: Residual pool depth | D19: cm | G19: =IF('Metrics'!$V$12="","",'Metrics'!$V$12)
A20: Hydraulics | B20: High flow dynamics | C20: Impervious surface | D20: % | E20: =IF('DEEP Score'!$E$12="","",'DEEP Score'!$E$12) | G20: =IF('Metrics'!$V$5="","",'Metrics'!$V$5) | H20: =IF('Results'!$B$9="","",'Results'!$B$9) | I20: =IF('DEEP Score'!$H$20="","",IF('DEEP Score'!$H$20<=5,"Non-Functioning",IF('DEEP Score'!$H$20<=10,"Functioning At-Risk","Functioning")))
A21: Hydraulics | B21: Floodplain connectivity | C21: Bankfull width:depth ratio | E21: =IF('DEEP Score'!$E$18="","",'DEEP Score'!$E$18) | F21: =IF('DEEP Score'!$F$18="","",'DEEP Score'!$F$18) | G21: =IF('Metrics'!$V$11="","",'Metrics'!$V$11) | H21: =IF('Results'!$B$10="","",'Results'!$B$10) | I21: =IF('DEEP Score'!$H$21="","",IF('DEEP Score'!$H$21<=5,"Non-Functioning",IF('DEEP Score'!$H$21<=10,"Functioning At-Risk","Functioning")))
C22: Bankfull height above channel | D22: m | F22: All streams (pooled) | G22: =IF('Metrics'!$V$13="","",'Metrics'!$V$13)
A23: Hydraulics | B23: Hyporheic connectivity | C23: Sand + fines | D23: % | G23: =IF('Metrics'!$V$14="","",'Metrics'!$V$14) | H23: =IF('Results'!$B$11="","",'Results'!$B$11) | I23: =IF('DEEP Score'!$H$23="","",IF('DEEP Score'!$H$23<=5,"Non-Functioning",IF('DEEP Score'!$H$23<=10,"Functioning At-Risk","Functioning")))
C24: Embeddedness | D24: % | G24: =IF('Metrics'!$V$15="","",'Metrics'!$V$15)
A25: Geomorphology | B25: Channel evolution | C25: Bankfull width:depth ratio | E25: =IF('DEEP Score'!$E$18="","",'DEEP Score'!$E$18) | F25: =IF('DEEP Score'!$F$18="","",'DEEP Score'!$F$18) | G25: =IF('Metrics'!$V$11="","",'Metrics'!$V$11) | H25: =IF('Results'!$B$12="","",'Results'!$B$12) | I25: =IF('DEEP Score'!$H$25="","",IF('DEEP Score'!$H$25<=5,"Non-Functioning",IF('DEEP Score'!$H$25<=10,"Functioning At-Risk","Functioning")))
C26: Bankfull height above channel | D26: m | E26: =IF('DEEP Score'!$E$22="","",'DEEP Score'!$E$22) | F26: =IF('DEEP Score'!$F$22="","",'DEEP Score'!$F$22) | G26: =IF('Metrics'!$V$13="","",'Metrics'!$V$13)
A27: Geomorphology | B27: Channel and floodplain dynamics | C27: Sinuosity | G27: =IF('Metrics'!$V$16="","",'Metrics'!$V$16) | H27: =IF('Results'!$B$13="","",'Results'!$B$13) | I27: =IF('DEEP Score'!$H$27="","",IF('DEEP Score'!$H$27<=5,"Non-Functioning",IF('DEEP Score'!$H$27<=10,"Functioning At-Risk","Functioning")))
C28: Bank angle | D28: degrees | G28: =IF('Metrics'!$V$17="","",'Metrics'!$V$17)
A29: Geomorphology | B29: Sediment continuity | C29: Relative bed stability | D29: log | G29: =IF('Metrics'!$V$18="","",'Metrics'!$V$18) | H29: =IF('Results'!$B$14="","",'Results'!$B$14) | I29: =IF('DEEP Score'!$H$29="","",IF('DEEP Score'!$H$29<=5,"Non-Functioning",IF('DEEP Score'!$H$29<=10,"Functioning At-Risk","Functioning")))
C30: Sand + fines | D30: % | E30: =IF('DEEP Score'!$E$23="","",'DEEP Score'!$E$23) | G30: =IF('Metrics'!$V$14="","",'Metrics'!$V$14)
A31: Geomorphology | B31: Bed composition and bedform dynamics | C31: Embeddedness | D31: % | E31: =IF('DEEP Score'!$E$24="","",'DEEP Score'!$E$24) | G31: =IF('Metrics'!$V$15="","",'Metrics'!$V$15) | H31: =IF('Results'!$B$15="","",'Results'!$B$15) | I31: =IF('DEEP Score'!$H$31="","",IF('DEEP Score'!$H$31<=5,"Non-Functioning",IF('DEEP Score'!$H$31<=10,"Functioning At-Risk","Functioning")))
C32: Large wood volume | D32: m3/100m | G32: =IF('Metrics'!$V$19="","",'Metrics'!$V$19)
A33: Physicochemistry | B33: Light & thermal regime | C33: Chlorophyll a | D33: ug/L | G33: =IF('Metrics'!$V$20="","",'Metrics'!$V$20) | H33: =IF('Results'!$B$16="","",'Results'!$B$16) | I33: =IF('DEEP Score'!$H$33="","",IF('DEEP Score'!$H$33<=5,"Non-Functioning",IF('DEEP Score'!$H$33<=10,"Functioning At-Risk","Functioning")))
C34: Canopy density, mid-channel | D34: % | G34: =IF('Metrics'!$V$21="","",'Metrics'!$V$21)
A35: Physicochemistry | B35: Carbon processing | C35: Riparian veg cover, woody | D35: frac | G35: =IF('Metrics'!$V$22="","",'Metrics'!$V$22) | H35: =IF('Results'!$B$17="","",'Results'!$B$17) | I35: =IF('DEEP Score'!$H$35="","",IF('DEEP Score'!$H$35<=5,"Non-Functioning",IF('DEEP Score'!$H$35<=10,"Functioning At-Risk","Functioning")))
A36: Physicochemistry | B36: Nutrient cycling | C36: Total nitrogen | D36: mg N/L | G36: =IF('Metrics'!$V$23="","",'Metrics'!$V$23) | H36: =IF('Results'!$B$18="","",'Results'!$B$18) | I36: =IF('DEEP Score'!$H$36="","",IF('DEEP Score'!$H$36<=5,"Non-Functioning",IF('DEEP Score'!$H$36<=10,"Functioning At-Risk","Functioning")))
C37: Total phosphorus | D37: ug/L | G37: =IF('Metrics'!$V$24="","",'Metrics'!$V$24)
A38: Physicochemistry | B38: Water & soil quality | C38: pH | D38: Std. Units | G38: =IF('Metrics'!$V$25="","",'Metrics'!$V$25) | H38: =IF('Results'!$B$19="","",'Results'!$B$19) | I38: =IF('DEEP Score'!$H$38="","",IF('DEEP Score'!$H$38<=5,"Non-Functioning",IF('DEEP Score'!$H$38<=10,"Functioning At-Risk","Functioning")))
C39: Turbidity | D39: NTU | G39: =IF('Metrics'!$V$26="","",'Metrics'!$V$26)
A40: Biology | B40: Habitat provision | C40: Fast-water / riffle habitat | D40: % | G40: =IF('Metrics'!$V$27="","",'Metrics'!$V$27) | H40: =IF('Results'!$B$20="","",'Results'!$B$20) | I40: =IF('DEEP Score'!$H$40="","",IF('DEEP Score'!$H$40<=5,"Non-Functioning",IF('DEEP Score'!$H$40<=10,"Functioning At-Risk","Functioning")))
C41: Natural fish cover | D41: frac | G41: =IF('Metrics'!$V$28="","",'Metrics'!$V$28)
...

Sheet Metrics
A1: Metric indices
A2: One row per metric. The value and the curve set come from the DEEP Score sheet, the knots from the Reference sheet, and the index is DEEP's piecewise-linear interpolation.
A3: Assessment status: Draft. For research and regional assessment development only.
A4: Metric | B4: Value | C4: Curve set in use | D4: Curve key | E4: Curve row | F4: x1 | G4: x2 | H4: x3 | I4: x4 | J4: x5 | K4: x6 | L4: x7 | M4: x8 | N4: y1 | O4: y2 | P4: y3 | Q4: y4 | R4: y5 | S4: y6 | T4: y7 | U4: y8 | V4: Index
A5: Impervious surface | B5: =IF('DEEP Score'!$E$12="","",'DEEP Score'!$E$12) | C5: ="" | D5: ="spring_pctimp2019ws|"&'Metrics'!$C$5 | E5: =IFERROR(MATCH('Metrics'!$D$5,curve_key,0),MATCH("spring_pctimp2019ws|",curve_key,0)) | F5: =INDEX(curve_x1,'Metrics'!$E$5) | G5: =INDEX(curve_x2,'Metrics'!$E$5) | H5: =INDEX(curve_x3,'Metrics'!$E$5) | I5: =INDEX(curve_x4,'Metrics'!$E$5) | J5: =INDEX(curve_x5,'Metrics'!$E$5) | K5: =INDEX(curve_x6,'Metrics'!$E$5) | L5: =INDEX(curve_x7,'Metrics'!$E$5) | M5: =INDEX(curve_x8,'Metrics'!$E$5) | N5: =INDEX(curve_y1,'Metrics'!$E$5) | O5: =INDEX(curve_y2,'Metrics'!$E$5) | P5: =INDEX(curve_y3,'Metrics'!$E$5) | Q5: =INDEX(curve_y4,'Metrics'!$E$5) | R5: =INDEX(curve_y5,'Metrics'!$E$5) | S5: =INDEX(curve_y6,'Metrics'!$E$5) | T5: =INDEX(curve_y7,'Metrics'!$E$5) | U5: =INDEX(curve_y8,'Metrics'!$E$5) | V5: =IF(ISNUMBER('Metrics'!$B$5),MAX(0,MIN(1,IF('Metrics'!$B$5<='Metrics'!$F$5,'Metrics'!$N$5,IF('Metrics'!$B$5>='Metrics'!$M$5,'Metrics'!$U$5,IF('Metrics'!$B$5<='Metrics'!$G$5,IF('Metrics'!$G$5-'Metrics'!$F$5<=0,'Metrics'!$O$5,'Metrics'!$N$5+('Metrics'!$B$5-'Metrics'!$F$5)/('Metrics'!$G$5-'Metrics'!$F$5)*('Metrics'!$O$5-'Metrics'!$N$5)),IF('Metrics'!$B$5<='Metrics'!$H$5,IF('Metrics'!$H$5-'Metrics'!$G$5<=0,'Metrics'!$P$5,'Metrics'!$O$5+('Metrics'!$B$5-'Metrics'!$G$5)/('Metrics'!$H$5-'Metrics'!$G$5)*('Metrics'!$P$5-'Metrics'!$O$5)),IF('Metrics'!$B$5<='Metrics'!$I$5,IF('Metrics'!$I$5-'Metrics'!$H$5<=0,'Metrics'!$Q$5,'Metrics'!$P$5+('Metrics'!$B$5-'Metrics'!$H$5)/('Metrics'!$I$5-'Metrics'!$H$5)*('Metrics'!$Q$5-'Metrics'!$P$5)),IF('Metrics'!$B$5<='Metrics'!$J$5,IF('Metrics'!$J$5-'Metrics'!$I$5<=0,'Metrics'!$R$5,'Metrics'!$Q$5+('Metrics'!$B$5-'Metrics'!$I$5)/('Metrics'!$J$5-'Metrics'!$I$5)*('Metrics'!$R$5-'Metrics'!$Q$5)),IF('Metrics'!$B$5<='Metrics'!$K$5,IF('Metrics'!$K$5-'Metrics'!$J$5<=0,'Metrics'!$S$5,'Metrics'!$R$5+('Metrics'!$B$5-'Metrics'!$J$5)/('Metrics'!$K$5-'Metrics'!$J$5)*('Metrics'!$S$5-'Metrics'!$R$5)),IF('Metrics'!$B$5<='Metrics'!$L$5,IF('Metrics'!$L$5-'Metrics'!$K$5<=0,'Metrics'!$T$5,'Metrics'!$S$5+('Metrics'!$B$5-'Metrics'!$K$5)/('Metrics'!$L$5-'Metrics'!$K$5)*('Metrics'!$T$5-'Metrics'!$S$5)),IF('Metrics'!$M$5-'Metrics'!$L$5<=0,'Metrics'!$U$5,'Metrics'!$T$5+('Metrics'!$B$5-'Metrics'!$L$5)/('Metrics'!$M$5-'Metrics'!$L$5)*('Metrics'!$U$5-'Metrics'!$T$5)))))))))))),"")
A6: Agriculture, crop and hay | B6: =IF('DEEP Score'!$E$13="","",'DEEP Score'!$E$13) | C6: ="" | D6: ="spring_pctag2019ws|"&'Metrics'!$C$6 | E6: =IFERROR(MATCH('Metrics'!$D$6,curve_key,0),MATCH("spring_pctag2019ws|",curve_key,0)) | F6: =INDEX(curve_x1,'Metrics'!$E$6) | G6: =INDEX(curve_x2,'Metrics'!$E$6) | H6: =INDEX(curve_x3,'Metrics'!$E$6) | I6: =INDEX(curve_x4,'Metrics'!$E$6) | J6: =INDEX(curve_x5,'Metrics'!$E$6) | K6: =INDEX(curve_x6,'Metrics'!$E$6) | L6: =INDEX(curve_x7,'Metrics'!$E$6) | M6: =INDEX(curve_x8,'Metrics'!$E$6) | N6: =INDEX(curve_y1,'Metrics'!$E$6) | O6: =INDEX(curve_y2,'Metrics'!$E$6) | P6: =INDEX(curve_y3,'Metrics'!$E$6) | Q6: =INDEX(curve_y4,'Metrics'!$E$6) | R6: =INDEX(curve_y5,'Metrics'!$E$6) | S6: =INDEX(curve_y6,'Metrics'!$E$6) | T6: =INDEX(curve_y7,'Metrics'!$E$6) | U6: =INDEX(curve_y8,'Metrics'!$E$6) | V6: =IF(ISNUMBER('Metrics'!$B$6),MAX(0,MIN(1,IF('Metrics'!$B$6<='Metrics'!$F$6,'Metrics'!$N$6,IF('Metrics'!$B$6>='Metrics'!$M$6,'Metrics'!$U$6,IF('Metrics'!$B$6<='Metrics'!$G$6,IF('Metrics'!$G$6-'Metrics'!$F$6<=0,'Metrics'!$O$6,'Metrics'!$N$6+('Metrics'!$B$6-'Metrics'!$F$6)/('Metrics'!$G$6-'Metrics'!$F$6)*('Metrics'!$O$6-'Metrics'!$N$6)),IF('Metrics'!$B$6<='Metrics'!$H$6,IF('Metrics'!$H$6-'Metrics'!$G$6<=0,'Metrics'!$P$6,'Metrics'!$O$6+('Metrics'!$B$6-'Metrics'!$G$6)/('Metrics'!$H$6-'Metrics'!$G$6)*('Metrics'!$P$6-'Metrics'!$O$6)),IF('Metrics'!$B$6<='Metrics'!$I$6,IF('Metrics'!$I$6-'Metrics'!$H$6<=0,'Metrics'!$Q$6,'Metrics'!$P$6+('Metrics'!$B$6-'Metrics'!$H$6)/('Metrics'!$I$6-'Metrics'!$H$6)*('Metrics'!$Q$6-'Metrics'!$P$6)),IF('Metrics'!$B$6<='Metrics'!$J$6,IF('Metrics'!$J$6-'Metrics'!$I$6<=0,'Metrics'!$R$6,'Metrics'!$Q$6+('Metrics'!$B$6-'Metrics'!$I$6)/('Metrics'!$J$6-'Metrics'!$I$6)*('Metrics'!$R$6-'Metrics'!$Q$6)),IF('Metrics'!$B$6<='Metrics'!$K$6,IF('Metrics'!$K$6-'Metrics'!$J$6<=0,'Metrics'!$S$6,'Metrics'!$R$6+('Metrics'!$B$6-'Metrics'!$J$6)/('Metrics'!$K$6-'Metrics'!$J$6)*('Metrics'!$S$6-'Metrics'!$R$6)),IF('Metrics'!$B$6<='Metrics'!$L$6,IF('Metrics'!$L$6-'Metrics'!$K$6<=0,'Metrics'!$T$6,'Metrics'!$S$6+('Metrics'!$B$6-'Metrics'!$K$6)/('Metrics'!$L$6-'Metrics'!$K$6)*('Metrics'!$T$6-'Metrics'!$S$6)),IF('Metrics'!$M$6-'Metrics'!$L$6<=0,'Metrics'!$U$6,'Metrics'!$T$6+('Metrics'!$B$6-'Metrics'!$L$6)/('Metrics'!$M$6-'Metrics'!$L$6)*('Metrics'!$U$6-'Metrics'!$T$6)))))))))))),"")
A7: Wetland cover of the watershed | B7: =IF('DEEP Score'!$E$14="","",'DEEP Score'!$E$14) | C7: ="" | D7: ="spring_pctwet2019ws|"&'Metrics'!$C$7 | E7: =IFERROR(MATCH('Metrics'!$D$7,curve_key,0),MATCH("spring_pctwet2019ws|",curve_key,0)) | F7: =INDEX(curve_x1,'Metrics'!$E$7) | G7: =INDEX(curve_x2,'Metrics'!$E$7) | H7: =INDEX(curve_x3,'Metrics'!$E$7) | I7: =INDEX(curve_x4,'Metrics'!$E$7) | J7: =INDEX(curve_x5,'Metrics'!$E$7) | K7: =INDEX(curve_x6,'Metrics'!$E$7) | L7: =INDEX(curve_x7,'Metrics'!$E$7) | M7: =INDEX(curve_x8,'Metrics'!$E$7) | N7: =INDEX(curve_y1,'Metrics'!$E$7) | O7: =INDEX(curve_y2,'Metrics'!$E$7) | P7: =INDEX(curve_y3,'Metrics'!$E$7) | Q7: =INDEX(curve_y4,'Metrics'!$E$7) | R7: =INDEX(curve_y5,'Metrics'!$E$7) | S7: =INDEX(curve_y6,'Metrics'!$E$7) | T7: =INDEX(curve_y7,'Metrics'!$E$7) | U7: =INDEX(curve_y8,'Metrics'!$E$7) | V7: =IF(ISNUMBER('Metrics'!$B$7),MAX(0,MIN(1,IF('Metrics'!$B$7<='Metrics'!$F$7,'Metrics'!$N$7,IF('Metrics'!$B$7>='Metrics'!$M$7,'Metrics'!$U$7,IF('Metrics'!$B$7<='Metrics'!$G$7,IF('Metrics'!$G$7-'Metrics'!$F$7<=0,'Metrics'!$O$7,'Metrics'!$N$7+('Metrics'!$B$7-'Metrics'!$F$7)/('Metrics'!$G$7-'Metrics'!$F$7)*('Metrics'!$O$7-'Metrics'!$N$7)),IF('Metrics'!$B$7<='Metrics'!$H$7,IF('Metrics'!$H$7-'Metrics'!$G$7<=0,'Metrics'!$P$7,'Metrics'!$O$7+('Metrics'!$B$7-'Metrics'!$G$7)/('Metrics'!$H$7-'Metrics'!$G$7)*('Metrics'!$P$7-'Metrics'!$O$7)),IF('Metrics'!$B$7<='Metrics'!$I$7,IF('Metrics'!$I$7-'Metrics'!$H$7<=0,'Metrics'!$Q$7,'Metrics'!$P$7+('Metrics'!$B$7-'Metrics'!$H$7)/('Metrics'!$I$7-'Metrics'!$H$7)*('Metrics'!$Q$7-'Metrics'!$P$7)),IF('Metrics'!$B$7<='Metrics'!$J$7,IF('Metrics'!$J$7-'Metrics'!$I$7<=0,'Metrics'!$R$7,'Metrics'!$Q$7+('Metrics'!$B$7-'Metrics'!$I$7)/('Metrics'!$J$7-'Metrics'!$I$7)*('Metrics'!$R$7-'Metrics'!$Q$7)),IF('Metrics'!$B$7<='Metrics'!$K$7,IF('Metrics'!$K$7-'Metrics'!$J$7<=0,'Metrics'!$S$7,'Metrics'!$R$7+('Metrics'!$B$7-'Metrics'!$J$7)/('Metrics'!$K$7-'Metrics'!$J$7)*('Metrics'!$S$7-'Metrics'!$R$7)),IF('Metrics'!$B$7<='Metrics'!$L$7,IF('Metrics'!$L$7-'Metrics'!$K$7<=0,'Metrics'!$T$7,'Metrics'!$S$7+('Metrics'!$B$7-'Metrics'!$K$7)/('Metrics'!$L$7-'Metrics'!$K$7)*('Metrics'!$T$7-'Metrics'!$S$7)),IF('Metrics'!$M$7-'Metrics'!$L$7<=0,'Metrics'!$U$7,'Metrics'!$T$7+('Metrics'!$B$7-'Metrics'!$L$7)/('Metrics'!$M$7-'Metrics'!$L$7)*('Metrics'!$U$7-'Metrics'!$T$7)))))))))))),"")
A8: Road density | B8: =IF('DEEP Score'!$E$15="","",'DEEP Score'!$E$15) | C8: ="" | D8: ="spring_rddensws|"&'Metrics'!$C$8 | E8: =IFERROR(MATCH('Metrics'!$D$8,curve_key,0),MATCH("spring_rddensws|",curve_key,0)) | F8: =INDEX(curve_x1,'Metrics'!$E$8) | G8: =INDEX(curve_x2,'Metrics'!$E$8) | H8: =INDEX(curve_x3,'Metrics'!$E$8) | I8: =INDEX(curve_x4,'Metrics'!$E$8) | J8: =INDEX(curve_x5,'Metrics'!$E$8) | K8: =INDEX(curve_x6,'Metrics'!$E$8) | L8: =INDEX(curve_x7,'Metrics'!$E$8) | M8: =INDEX(curve_x8,'Metrics'!$E$8) | N8: =INDEX(curve_y1,'Metrics'!$E$8) | O8: =INDEX(curve_y2,'Metrics'!$E$8) | P8: =INDEX(curve_y3,'Metrics'!$E$8) | Q8: =INDEX(curve_y4,'Metrics'!$E$8) | R8: =INDEX(curve_y5,'Metrics'!$E$8) | S8: =INDEX(curve_y6,'Metrics'!$E$8) | T8: =INDEX(curve_y7,'Metrics'!$E$8) | U8: =INDEX(curve_y8,'Metrics'!$E$8) | V8: =IF(ISNUMBER('Metrics'!$B$8),MAX(0,MIN(1,IF('Metrics'!$B$8<='Metrics'!$F$8,'Metrics'!$N$8,IF('Metrics'!$B$8>='Metrics'!$M$8,'Metrics'!$U$8,IF('Metrics'!$B$8<='Metrics'!$G$8,IF('Metrics'!$G$8-'Metrics'!$F$8<=0,'Metrics'!$O$8,'Metrics'!$N$8+('Metrics'!$B$8-'Metrics'!$F$8)/('Metrics'!$G$8-'Metrics'!$F$8)*('Metrics'!$O$8-'Metrics'!$N$8)),IF('Metrics'!$B$8<='Metrics'!$H$8,IF('Metrics'!$H$8-'Metrics'!$G$8<=0,'Metrics'!$P$8,'Metrics'!$O$8+('Metrics'!$B$8-'Metrics'!$G$8)/('Metrics'!$H$8-'Metrics'!$G$8)*('Metrics'!$P$8-'Metrics'!$O$8)),IF('Metrics'!$B$8<='Metrics'!$I$8,IF('Metrics'!$I$8-'Metrics'!$H$8<=0,'Metrics'!$Q$8,'Metrics'!$P$8+('Metrics'!$B$8-'Metrics'!$H$8)/('Metrics'!$I$8-'Metrics'!$H$8)*('Metrics'!$Q$8-'Metrics'!$P$8)),IF('Metrics'!$B$8<='Metrics'!$J$8,IF('Metrics'!$J$8-'Metrics'!$I$8<=0,'Metrics'!$R$8,'Metrics'!$Q$8+('Metrics'!$B$8-'Metrics'!$I$8)/('Metrics'!$J$8-'Metrics'!$I$8)*('Metrics'!$R$8-'Metrics'!$Q$8)),IF('Metrics'!$B$8<='Metrics'!$K$8,IF('Metrics'!$K$8-'Metrics'!$J$8<=0,'Metrics'!$S$8,'Metrics'!$R$8+('Metrics'!$B$8-'Metrics'!$J$8)/('Metrics'!$K$8-'Metrics'!$J$8)*('Metrics'!$S$8-'Metrics'!$R$8)),IF('Metrics'!$B$8<='Metrics'!$L$8,IF('Metrics'!$L$8-'Metrics'!$K$8<=0,'Metrics'!$T$8,'Metrics'!$S$8+('Metrics'!$B$8-'Metrics'!$K$8)/('Metrics'!$L$8-'Metrics'!$K$8)*('Metrics'!$T$8-'Metrics'!$S$8)),IF('Metrics'!$M$8-'Metrics'!$L$8<=0,'Metrics'!$U$8,'Metrics'!$T$8+('Metrics'!$B$8-'Metrics'!$L$8)/('Metrics'!$M$8-'Metrics'!$L$8)*('Metrics'!$U$8-'Metrics'!$T$8)))))))))))),"")
A9: Base flow index | B9: =IF('DEEP Score'!$E$16="","",'DEEP Score'!$E$16) | C9: ="" | D9: ="spring_bfiws|"&'Metrics'!$C$9 | E9: =IFERROR(MATCH('Metrics'!$D$9,curve_key,0),MATCH("spring_bfiws|",curve_key,0)) | F9: =INDEX(curve_x1,'Metrics'!$E$9) | G9: =INDEX(curve_x2,'Metrics'!$E$9) | H9: =INDEX(curve_x3,'Metrics'!$E$9) | I9: =INDEX(curve_x4,'Metrics'!$E$9) | J9: =INDEX(curve_x5,'Metrics'!$E$9) | K9: =INDEX(curve_x6,'Metrics'!$E$9) | L9: =INDEX(curve_x7,'Metrics'!$E$9) | M9: =INDEX(curve_x8,'Metrics'!$E$9) | N9: =INDEX(curve_y1,'Metrics'!$E$9) | O9: =INDEX(curve_y2,'Metrics'!$E$9) | P9: =INDEX(curve_y3,'Metrics'!$E$9) | Q9: =INDEX(curve_y4,'Metrics'!$E$9) | R9: =INDEX(curve_y5,'Metrics'!$E$9) | S9: =INDEX(curve_y6,'Metrics'!$E$9) | T9: =INDEX(curve_y7,'Metrics'!$E$9) | U9: =INDEX(curve_y8,'Metrics'!$E$9) | V9: =IF(ISNUMBER('Metrics'!$B$9),MAX(0,MIN(1,IF('Metrics'!$B$9<='Metrics'!$F$9,'Metrics'!$N$9,IF('Metrics'!$B$9>='Metrics'!$M$9,'Metrics'!$U$9,IF('Metrics'!$B$9<='Metrics'!$G$9,IF('Metrics'!$G$9-'Metrics'!$F$9<=0,'Metrics'!$O$9,'Metrics'!$N$9+('Metrics'!$B$9-'Metrics'!$F$9)/('Metrics'!$G$9-'Metrics'!$F$9)*('Metrics'!$O$9-'Metrics'!$N$9)),IF('Metrics'!$B$9<='Metrics'!$H$9,IF('Metrics'!$H$9-'Metrics'!$G$9<=0,'Metrics'!$P$9,'Metrics'!$O$9+('Metrics'!$B$9-'Metrics'!$G$9)/('Metrics'!$H$9-'Metrics'!$G$9)*('Metrics'!$P$9-'Metrics'!$O$9)),IF('Metrics'!$B$9<='Metrics'!$I$9,IF('Metrics'!$I$9-'Metrics'!$H$9<=0,'Metrics'!$Q$9,'Metrics'!$P$9+('Metrics'!$B$9-'Metrics'!$H$9)/('Metrics'!$I$9-'Metrics'!$H$9)*('Metrics'!$Q$9-'Metrics'!$P$9)),IF('Metrics'!$B$9<='Metrics'!$J$9,IF('Metrics'!$J$9-'Metrics'!$I$9<=0,'Metrics'!$R$9,'Metrics'!$Q$9+('Metrics'!$B$9-'Metrics'!$I$9)/('Metrics'!$J$9-'Metrics'!$I$9)*('Metrics'!$R$9-'Metrics'!$Q$9)),IF('Metrics'!$B$9<='Metrics'!$K$9,IF('Metrics'!$K$9-'Metrics'!$J$9<=0,'Metrics'!$S$9,'Metrics'!$R$9+('Metrics'!$B$9-'Metrics'!$J$9)/('Metrics'!$K$9-'Metrics'!$J$9)*('Metrics'!$S$9-'Metrics'!$R$9)),IF('Metrics'!$B$9<='Metrics'!$L$9,IF('Metrics'!$L$9-'Metrics'!$K$9<=0,'Metrics'!$T$9,'Metrics'!$S$9+('Metrics'!$B$9-'Metrics'!$K$9)/('Metrics'!$L$9-'Metrics'!$K$9)*('Metrics'!$T$9-'Metrics'!$S$9)),IF('Metrics'!$M$9-'Metrics'!$L$9<=0,'Metrics'!$U$9,'Metrics'!$T$9+('Metrics'!$B$9-'Metrics'!$L$9)/('Metrics'!$M$9-'Metrics'!$L$9)*('Metrics'!$U$9-'Metrics'!$T$9)))))))))))),"")
A10: Degree of regulation | B10: =IF('DEEP Score'!$E$17="","",'DEEP Score'!$E$17) | C10: ="" | D10: ="spring_dorws|"&'Metrics'!$C$10 | E10: =IFERROR(MATCH('Metrics'!$D$10,curve_key,0),MATCH("spring_dorws|",curve_key,0)) | F10: =INDEX(curve_x1,'Metrics'!$E$10) | G10: =INDEX(curve_x2,'Metrics'!$E$10) | H10: =INDEX(curve_x3,'Metrics'!$E$10) | I10: =INDEX(curve_x4,'Metrics'!$E$10) | J10: =INDEX(curve_x5,'Metrics'!$E$10) | K10: =INDEX(curve_x6,'Metrics'!$E$10) | L10: =INDEX(curve_x7,'Metrics'!$E$10) | M10: =INDEX(curve_x8,'Metrics'!$E$10) | N10: =INDEX(curve_y1,'Metrics'!$E$10) | O10: =INDEX(curve_y2,'Metrics'!$E$10) | P10: =INDEX(curve_y3,'Metrics'!$E$10) | Q10: =INDEX(curve_y4,'Metrics'!$E$10) | R10: =INDEX(curve_y5,'Metrics'!$E$10) | S10: =INDEX(curve_y6,'Metrics'!$E$10) | T10: =INDEX(curve_y7,'Metrics'!$E$10) | U10: =INDEX(curve_y8,'Metrics'!$E$10) | V10: =IF(ISNUMBER('Metrics'!$B$10),MAX(0,MIN(1,IF('Metrics'!$B$10<='Metrics'!$F$10,'Metrics'!$N$10,IF('Metrics'!$B$10>='Metrics'!$M$10,'Metrics'!$U$10,IF('Metrics'!$B$10<='Metrics'!$G$10,IF('Metrics'!$G$10-'Metrics'!$F$10<=0,'Metrics'!$O$10,'Metrics'!$N$10+('Metrics'!$B$10-'Metrics'!$F$10)/('Metrics'!$G$10-'Metrics'!$F$10)*('Metrics'!$O$10-'Metrics'!$N$10)),IF('Metrics'!$B$10<='Metrics'!$H$10,IF('Metrics'!$H$10-'Metrics'!$G$10<=0,'Metrics'!$P$10,'Metrics'!$O$10+('Metrics'!$B$10-'Metrics'!$G$10)/('Metrics'!$H$10-'Metrics'!$G$10)*('Metrics'!$P$10-'Metrics'!$O$10)),IF('Metrics'!$B$10<='Metrics'!$I$10,IF('Metrics'!$I$10-'Metrics'!$H$10<=0,'Metrics'!$Q$10,'Metrics'!$P$10+('Metrics'!$B$10-'Metrics'!$H$10)/('Metrics'!$I$10-'Metrics'!$H$10)*('Metrics'!$Q$10-'Metrics'!$P$10)),IF('Metrics'!$B$10<='Metrics'!$J$10,IF('Metrics'!$J$10-'Metrics'!$I$10<=0,'Metrics'!$R$10,'Metrics'!$Q$10+('Metrics'!$B$10-'Metrics'!$I$10)/('Metrics'!$J$10-'Metrics'!$I$10)*('Metrics'!$R$10-'Metrics'!$Q$10)),IF('Metrics'!$B$10<='Metrics'!$K$10,IF('Metrics'!$K$10-'Metrics'!$J$10<=0,'Metrics'!$S$10,'Metrics'!$R$10+('Metrics'!$B$10-'Metrics'!$J$10)/('Metrics'!$K$10-'Metrics'!$J$10)*('Metrics'!$S$10-'Metrics'!$R$10)),IF('Metrics'!$B$10<='Metrics'!$L$10,IF('Metrics'!$L$10-'Metrics'!$K$10<=0,'Metrics'!$T$10,'Metrics'!$S$10+('Metrics'!$B$10-'Metrics'!$K$10)/('Metrics'!$L$10-'Metrics'!$K$10)*('Metrics'!$T$10-'Metrics'!$S$10)),IF('Metrics'!$M$10-'Metrics'!$L$10<=0,'Metrics'!$U$10,'Metrics'!$T$10+('Metrics'!$B$10-'Metrics'!$L$10)/('Metrics'!$M$10-'Metrics'!$L$10)*('Metrics'!$U$10-'Metrics'!$T$10)))))))))))),"")
A11: Bankfull width:depth ratio | B11: =IF('DEEP Score'!$E$18="","",'DEEP Score'!$E$18) | C11: =IF('DEEP Score'!$F$18="","All streams (pooled)",'DEEP Score'!$F$18) | D11: ="spring_phab_bfwd_rat|"&'Metrics'!$C$11 | E11: =IFERROR(MATCH('Metrics'!$D$11,curve_key,0),MATCH("spring_phab_bfwd_rat|All streams (pooled)",curve_key,0)) | F11: =INDEX(curve_x1,'Metrics'!$E$11) | G11: =INDEX(curve_x2,'Metrics'!$E$11) | H11: =INDEX(curve_x3,'Metrics'!$E$11) | I11: =INDEX(curve_x4,'Metrics'!$E$11) | J11: =INDEX(curve_x5,'Metrics'!$E$11) | K11: =INDEX(curve_x6,'Metrics'!$E$11) | L11: =INDEX(curve_x7,'Metrics'!$E$11) | M11: =INDEX(curve_x8,'Metrics'!$E$11) | N11: =INDEX(curve_y1,'Metrics'!$E$11) | O11: =INDEX(curve_y2,'Metrics'!$E$11) | P11: =INDEX(curve_y3,'Metrics'!$E$11) | Q11: =INDEX(curve_y4,'Metrics'!$E$11) | R11: =INDEX(curve_y5,'Metrics'!$E$11) | S11: =INDEX(curve_y6,'Metrics'!$E$11) | T11: =INDEX(curve_y7,'Metrics'!$E$11) | U11: =INDEX(curve_y8,'Metrics'!$E$11) | V11: =IF(ISNUMBER('Metrics'!$B$11),MAX(0,MIN(1,IF('Metrics'!$B$11<='Metrics'!$F$11,'Metrics'!$N$11,IF('Metrics'!$B$11>='Metrics'!$M$11,'Metrics'!$U$11,IF('Metrics'!$B$11<='Metrics'!$G$11,IF('Metrics'!$G$11-'Metrics'!$F$11<=0,'Metrics'!$O$11,'Metrics'!$N$11+('Metrics'!$B$11-'Metrics'!$F$11)/('Metrics'!$G$11-'Metrics'!$F$11)*('Metrics'!$O$11-'Metrics'!$N$11)),IF('Metrics'!$B$11<='Metrics'!$H$11,IF('Metrics'!$H$11-'Metrics'!$G$11<=0,'Metrics'!$P$11,'Metrics'!$O$11+('Metrics'!$B$11-'Metrics'!$G$11)/('Metrics'!$H$11-'Metrics'!$G$11)*('Metrics'!$P$11-'Metrics'!$O$11)),IF('Metrics'!$B$11<='Metrics'!$I$11,IF('Metrics'!$I$11-'Metrics'!$H$11<=0,'Metrics'!$Q$11,'Metrics'!$P$11+('Metrics'!$B$11-'Metrics'!$H$11)/('Metrics'!$I$11-'Metrics'!$H$11)*('Metrics'!$Q$11-'Metrics'!$P$11)),IF('Metrics'!$B$11<='Metrics'!$J$11,IF('Metrics'!$J$11-'Metrics'!$I$11<=0,'Metrics'!$R$11,'Metrics'!$Q$11+('Metrics'!$B$11-'Metrics'!$I$11)/('Metrics'!$J$11-'Metrics'!$I$11)*('Metrics'!$R$11-'Metrics'!$Q$11)),IF('Metrics'!$B$11<='Metrics'!$K$11,IF('Metrics'!$K$11-'Metrics'!$J$11<=0,'Metrics'!$S$11,'Metrics'!$R$11+('Metrics'!$B$11-'Metrics'!$J$11)/('Metrics'!$K$11-'Metrics'!$J$11)*('Metrics'!$S$11-'Metrics'!$R$11)),IF('Metrics'!$B$11<='Metrics'!$L$11,IF('Metrics'!$L$11-'Metrics'!$K$11<=0,'Metrics'!$T$11,'Metrics'!$S$11+('Metrics'!$B$11-'Metrics'!$K$11)/('Metrics'!$L$11-'Metrics'!$K$11)*('Metrics'!$T$11-'Metrics'!$S$11)),IF('Metrics'!$M$11-'Metrics'!$L$11<=0,'Metrics'!$U$11,'Metrics'!$T$11+('Metrics'!$B$11-'Metrics'!$L$11)/('Metrics'!$M$11-'Metrics'!$L$11)*('Metrics'!$U$11-'Metrics'!$T$11)))))))))))),"")
A12: Residual pool depth | B12: =IF('DEEP Score'!$E$19="","",'DEEP Score'!$E$19) | C12: ="" | D12: ="spring_phab_rp100_cm|"&'Metrics'!$C$12 | E12: =IFERROR(MATCH('Metrics'!$D$12,curve_key,0),MATCH("spring_phab_rp100_cm|",curve_key,0)) | F12: =INDEX(curve_x1,'Metrics'!$E$12) | G12: =INDEX(curve_x2,'Metrics'!$E$12) | H12: =INDEX(curve_x3,'Metrics'!$E$12) | I12: =INDEX(curve_x4,'Metrics'!$E$12) | J12: =INDEX(curve_x5,'Metrics'!$E$12) | K12: =INDEX(curve_x6,'Metrics'!$E$12) | L12: =INDEX(curve_x7,'Metrics'!$E$12) | M12: =INDEX(curve_x8,'Metrics'!$E$12) | N12: =INDEX(curve_y1,'Metrics'!$E$12) | O12: =INDEX(curve_y2,'Metrics'!$E$12) | P12: =INDEX(curve_y3,'Metrics'!$E$12) | Q12: =INDEX(curve_y4,'Metrics'!$E$12) | R12: =INDEX(curve_y5,'Metrics'!$E$12) | S12: =INDEX(curve_y6,'Metrics'!$E$12) | T12: =INDEX(curve_y7,'Metrics'!$E$12) | U12: =INDEX(curve_y8,'Metrics'!$E$12) | V12: =IF(ISNUMBER('Metrics'!$B$12),MAX(0,MIN(1,IF('Metrics'!$B$12<='Metrics'!$F$12,'Metrics'!$N$12,IF('Metrics'!$B$12>='Metrics'!$M$12,'Metrics'!$U$12,IF('Metrics'!$B$12<='Metrics'!$G$12,IF('Metrics'!$G$12-'Metrics'!$F$12<=0,'Metrics'!$O$12,'Metrics'!$N$12+('Metrics'!$B$12-'Metrics'!$F$12)/('Metrics'!$G$12-'Metrics'!$F$12)*('Metrics'!$O$12-'Metrics'!$N$12)),IF('Metrics'!$B$12<='Metrics'!$H$12,IF('Metrics'!$H$12-'Metrics'!$G$12<=0,'Metrics'!$P$12,'Metrics'!$O$12+('Metrics'!$B$12-'Metrics'!$G$12)/('Metrics'!$H$12-'Metrics'!$G$12)*('Metrics'!$P$12-'Metrics'!$O$12)),IF('Metrics'!$B$12<='Metrics'!$I$12,IF('Metrics'!$I$12-'Metrics'!$H$12<=0,'Metrics'!$Q$12,'Metrics'!$P$12+('Metrics'!$B$12-'Metrics'!$H$12)/('Metrics'!$I$12-'Metrics'!$H$12)*('Metrics'!$Q$12-'Metrics'!$P$12)),IF('Metrics'!$B$12<='Metrics'!$J$12,IF('Metrics'!$J$12-'Metrics'!$I$12<=0,'Metrics'!$R$12,'Metrics'!$Q$12+('Metrics'!$B$12-'Metrics'!$I$12)/('Metrics'!$J$12-'Metrics'!$I$12)*('Metrics'!$R$12-'Metrics'!$Q$12)),IF('Metrics'!$B$12<='Metrics'!$K$12,IF('Metrics'!$K$12-'Metrics'!$J$12<=0,'Metrics'!$S$12,'Metrics'!$R$12+('Metrics'!$B$12-'Metrics'!$J$12)/('Metrics'!$K$12-'Metrics'!$J$12)*('Metrics'!$S$12-'Metrics'!$R$12)),IF('Metrics'!$B$12<='Metrics'!$L$12,IF('Metrics'!$L$12-'Metrics'!$K$12<=0,'Metrics'!$T$12,'Metrics'!$S$12+('Metrics'!$B$12-'Metrics'!$K$12)/('Metrics'!$L$12-'Metrics'!$K$12)*('Metrics'!$T$12-'Metrics'!$S$12)),IF('Metrics'!$M$12-'Metrics'!$L$12<=0,'Metrics'!$U$12,'Metrics'!$T$12+('Metrics'!$B$12-'Metrics'!$L$12)/('Metrics'!$M$12-'Metrics'!$L$12)*('Metrics'!$U$12-'Metrics'!$T$12)))))))))))),"")
A13: Bankfull height above channel | B13: =IF('DEEP Score'!$E$22="","",'DEEP Score'!$E$22) | C13: =IF('DEEP Score'!$F$22="","All streams (pooled)",'DEEP Score'!$F$22) | D13: ="spring_phab_xbkf_h|"&'Metrics'!$C$13 | E13: =IFERROR(MATCH('Metrics'!$D$13,curve_key,0),MATCH("spring_phab_xbkf_h|All streams (pooled)",curve_key,0)) | F13: =INDEX(curve_x1,'Metrics'!$E$13) | G13: =INDEX(curve_x2,'Metrics'!$E$13) | H13: =INDEX(curve_x3,'Metrics'!$E$13) | I13: =INDEX(curve_x4,'Metrics'!$E$13) | J13: =INDEX(curve_x5,'Metrics'!$E$13) | K13: =INDEX(curve_x6,'Metrics'!$E$13) | L13: =INDEX(curve_x7,'Metrics'!$E$13) | M13: =INDEX(curve_x8,'Metrics'!$E$13) | N13: =INDEX(curve_y1,'Metrics'!$E$13) | O13: =INDEX(curve_y2,'Metrics'!$E$13) | P13: =INDEX(curve_y3,'Metrics'!$E$13) | Q13: =INDEX(curve_y4,'Metrics'!$E$13) | R13: =INDEX(curve_y5,'Metrics'!$E$13) | S13: =INDEX(curve_y6,'Metrics'!$E$13) | T13: =INDEX(curve_y7,'Metrics'!$E$13) | U13: =INDEX(curve_y8,'Metrics'!$E$13) | V13: =IF(ISNUMBER('Metrics'!$B$13),MAX(0,MIN(1,IF('Metrics'!$B$13<='Metrics'!$F$13,'Metrics'!$N$13,IF('Metrics'!$B$13>='Metrics'!$M$13,'Metrics'!$U$13,IF('Metrics'!$B$13<='Metrics'!$G$13,IF('Metrics'!$G$13-'Metrics'!$F$13<=0,'Metrics'!$O$13,'Metrics'!$N$13+('Metrics'!$B$13-'Metrics'!$F$13)/('Metrics'!$G$13-'Metrics'!$F$13)*('Metrics'!$O$13-'Metrics'!$N$13)),IF('Metrics'!$B$13<='Metrics'!$H$13,IF('Metrics'!$H$13-'Metrics'!$G$13<=0,'Metrics'!$P$13,'Metrics'!$O$13+('Metrics'!$B$13-'Metrics'!$G$13)/('Metrics'!$H$13-'Metrics'!$G$13)*('Metrics'!$P$13-'Metrics'!$O$13)),IF('Metrics'!$B$13<='Metrics'!$I$13,IF('Metrics'!$I$13-'Metrics'!$H$13<=0,'Metrics'!$Q$13,'Metrics'!$P$13+('Metrics'!$B$13-'Metrics'!$H$13)/('Metrics'!$I$13-'Metrics'!$H$13)*('Metrics'!$Q$13-'Metrics'!$P$13)),IF('Metrics'!$B$13<='Metrics'!$J$13,IF('Metrics'!$J$13-'Metrics'!$I$13<=0,'Metrics'!$R$13,'Metrics'!$Q$13+('Metrics'!$B$13-'Metrics'!$I$13)/('Metrics'!$J$13-'Metrics'!$I$13)*('Metrics'!$R$13-'Metrics'!$Q$13)),IF('Metrics'!$B$13<='Metrics'!$K$13,IF('Metrics'!$K$13-'Metrics'!$J$13<=0,'Metrics'!$S$13,'Metrics'!$R$13+('Metrics'!$B$13-'Metrics'!$J$13)/('Metrics'!$K$13-'Metrics'!$J$13)*('Metrics'!$S$13-'Metrics'!$R$13)),IF('Metrics'!$B$13<='Metrics'!$L$13,IF('Metrics'!$L$13-'Metrics'!$K$13<=0,'Metrics'!$T$13,'Metrics'!$S$13+('Metrics'!$B$13-'Metrics'!$K$13)/('Metrics'!$L$13-'Metrics'!$K$13)*('Metrics'!$T$13-'Metrics'!$S$13)),IF('Metrics'!$M$13-'Metrics'!$L$13<=0,'Metrics'!$U$13,'Metrics'!$T$13+('Metrics'!$B$13-'Metrics'!$L$13)/('Metrics'!$M$13-'Metrics'!$L$13)*('Metrics'!$U$13-'Metrics'!$T$13)))))))))))),"")
A14: Sand + fines | B14: =IF('DEEP Score'!$E$23="","",'DEEP Score'!$E$23) | C14: ="" | D14: ="spring_phab_pct_safn|"&'Metrics'!$C$14 | E14: =IFERROR(MATCH('Metrics'!$D$14,curve_key,0),MATCH("spring_phab_pct_safn|",curve_key,0)) | F14: =INDEX(curve_x1,'Metrics'!$E$14) | G14: =INDEX(curve_x2,'Metrics'!$E$14) | H14: =INDEX(curve_x3,'Metrics'!$E$14) | I14: =INDEX(curve_x4,'Metrics'!$E$14) | J14: =INDEX(curve_x5,'Metrics'!$E$14) | K14: =INDEX(curve_x6,'Metrics'!$E$14) | L14: =INDEX(curve_x7,'Metrics'!$E$14) | M14: =INDEX(curve_x8,'Metrics'!$E$14) | N14: =INDEX(curve_y1,'Metrics'!$E$14) | O14: =INDEX(curve_y2,'Metrics'!$E$14) | P14: =INDEX(curve_y3,'Metrics'!$E$14) | Q14: =INDEX(curve_y4,'Metrics'!$E$14) | R14: =INDEX(curve_y5,'Metrics'!$E$14) | S14: =INDEX(curve_y6,'Metrics'!$E$14) | T14: =INDEX(curve_y7,'Metrics'!$E$14) | U14: =INDEX(curve_y8,'Metrics'!$E$14) | V14: =IF(ISNUMBER('Metrics'!$B$14),MAX(0,MIN(1,IF('Metrics'!$B$14<='Metrics'!$F$14,'Metrics'!$N$14,IF('Metrics'!$B$14>='Metrics'!$M$14,'Metrics'!$U$14,IF('Metrics'!$B$14<='Metrics'!$G$14,IF('Metrics'!$G$14-'Metrics'!$F$14<=0,'Metrics'!$O$14,'Metrics'!$N$14+('Metrics'!$B$14-'Metrics'!$F$14)/('Metrics'!$G$14-'Metrics'!$F$14)*('Metrics'!$O$14-'Metrics'!$N$14)),IF('Metrics'!$B$14<='Metrics'!$H$14,IF('Metrics'!$H$14-'Metrics'!$G$14<=0,'Metrics'!$P$14,'Metrics'!$O$14+('Metrics'!$B$14-'Metrics'!$G$14)/('Metrics'!$H$14-'Metrics'!$G$14)*('Metrics'!$P$14-'Metrics'!$O$14)),IF('Metrics'!$B$14<='Metrics'!$I$14,IF('Metrics'!$I$14-'Metrics'!$H$14<=0,'Metrics'!$Q$14,'Metrics'!$P$14+('Metrics'!$B$14-'Metrics'!$H$14)/('Metrics'!$I$14-'Metrics'!$H$14)*('Metrics'!$Q$14-'Metrics'!$P$14)),IF('Metrics'!$B$14<='Metrics'!$J$14,IF('Metrics'!$J$14-'Metrics'!$I$14<=0,'Metrics'!$R$14,'Metrics'!$Q$14+('Metrics'!$B$14-'Metrics'!$I$14)/('Metrics'!$J$14-'Metrics'!$I$14)*('Metrics'!$R$14-'Metrics'!$Q$14)),IF('Metrics'!$B$14<='Metrics'!$K$14,IF('Metrics'!$K$14-'Metrics'!$J$14<=0,'Metrics'!$S$14,'Metrics'!$R$14+('Metrics'!$B$14-'Metrics'!$J$14)/('Metrics'!$K$14-'Metrics'!$J$14)*('Metrics'!$S$14-'Metrics'!$R$14)),IF('Metrics'!$B$14<='Metrics'!$L$14,IF('Metrics'!$L$14-'Metrics'!$K$14<=0,'Metrics'!$T$14,'Metrics'!$S$14+('Metrics'!$B$14-'Metrics'!$K$14)/('Metrics'!$L$14-'Metrics'!$K$14)*('Metrics'!$T$14-'Metrics'!$S$14)),IF('Metrics'!$M$14-'Metrics'!$L$14<=0,'Metrics'!$U$14,'Metrics'!$T$14+('Metrics'!$B$14-'Metrics'!$L$14)/('Metrics'!$M$14-'Metrics'!$L$14)*('Metrics'!$U$14-'Metrics'!$T$14)))))))))))),"")
A15: Embeddedness | B15: =IF('DEEP Score'!$E$24="","",'DEEP Score'!$E$24) | C15: ="" | D15: ="spring_phab_xembed|"&'Metrics'!$C$15 | E15: =IFERROR(MATCH('Metrics'!$D$15,curve_key,0),MATCH("spring_phab_xembed|",curve_key,0)) | F15: =INDEX(curve_x1,'Metrics'!$E$15) | G15: =INDEX(curve_x2,'Metrics'!$E$15) | H15: =INDEX(curve_x3,'Metrics'!$E$15) | I15: =INDEX(curve_x4,'Metrics'!$E$15) | J15: =INDEX(curve_x5,'Metrics'!$E$15) | K15: =INDEX(curve_x6,'Metrics'!$E$15) | L15: =INDEX(curve_x7,'Metrics'!$E$15) | M15: =INDEX(curve_x8,'Metrics'!$E$15) | N15: =INDEX(curve_y1,'Metrics'!$E$15) | O15: =INDEX(curve_y2,'Metrics'!$E$15) | P15: =INDEX(curve_y3,'Metrics'!$E$15) | Q15: =INDEX(curve_y4,'Metrics'!$E$15) | R15: =INDEX(curve_y5,'Metrics'!$E$15) | S15: =INDEX(curve_y6,'Metrics'!$E$15) | T15: =INDEX(curve_y7,'Metrics'!$E$15) | U15: =INDEX(curve_y8,'Metrics'!$E$15) | V15: =IF(ISNUMBER('Metrics'!$B$15),MAX(0,MIN(1,IF('Metrics'!$B$15<='Metrics'!$F$15,'Metrics'!$N$15,IF('Metrics'!$B$15>='Metrics'!$M$15,'Metrics'!$U$15,IF('Metrics'!$B$15<='Metrics'!$G$15,IF('Metrics'!$G$15-'Metrics'!$F$15<=0,'Metrics'!$O$15,'Metrics'!$N$15+('Metrics'!$B$15-'Metrics'!$F$15)/('Metrics'!$G$15-'Metrics'!$F$15)*('Metrics'!$O$15-'Metrics'!$N$15)),IF('Metrics'!$B$15<='Metrics'!$H$15,IF('Metrics'!$H$15-'Metrics'!$G$15<=0,'Metrics'!$P$15,'Metrics'!$O$15+('Metrics'!$B$15-'Metrics'!$G$15)/('Metrics'!$H$15-'Metrics'!$G$15)*('Metrics'!$P$15-'Metrics'!$O$15)),IF('Metrics'!$B$15<='Metrics'!$I$15,IF('Metrics'!$I$15-'Metrics'!$H$15<=0,'Metrics'!$Q$15,'Metrics'!$P$15+('Metrics'!$B$15-'Metrics'!$H$15)/('Metrics'!$I$15-'Metrics'!$H$15)*('Metrics'!$Q$15-'Metrics'!$P$15)),IF('Metrics'!$B$15<='Metrics'!$J$15,IF('Metrics'!$J$15-'Metrics'!$I$15<=0,'Metrics'!$R$15,'Metrics'!$Q$15+('Metrics'!$B$15-'Metrics'!$I$15)/('Metrics'!$J$15-'Metrics'!$I$15)*('Metrics'!$R$15-'Metrics'!$Q$15)),IF('Metrics'!$B$15<='Metrics'!$K$15,IF('Metrics'!$K$15-'Metrics'!$J$15<=0,'Metrics'!$S$15,'Metrics'!$R$15+('Metrics'!$B$15-'Metrics'!$J$15)/('Metrics'!$K$15-'Metrics'!$J$15)*('Metrics'!$S$15-'Metrics'!$R$15)),IF('Metrics'!$B$15<='Metrics'!$L$15,IF('Metrics'!$L$15-'Metrics'!$K$15<=0,'Metrics'!$T$15,'Metrics'!$S$15+('Metrics'!$B$15-'Metrics'!$K$15)/('Metrics'!$L$15-'Metrics'!$K$15)*('Metrics'!$T$15-'Metrics'!$S$15)),IF('Metrics'!$M$15-'Metrics'!$L$15<=0,'Metrics'!$U$15,'Metrics'!$T$15+('Metrics'!$B$15-'Metrics'!$L$15)/('Metrics'!$M$15-'Metrics'!$L$15)*('Metrics'!$U$15-'Metrics'!$T$15)))))))))))),"")
A16: Sinuosity | B16: =IF('DEEP Score'!$E$27="","",'DEEP Score'!$E$27) | C16: ="" | D16: ="spring_phab_sinu|"&'Metrics'!$C$16 | E16: =IFERROR(MATCH('Metrics'!$D$16,curve_key,0),MATCH("spring_phab_sinu|",curve_key,0)) | F16: =INDEX(curve_x1,'Metrics'!$E$16) | G16: =INDEX(curve_x2,'Metrics'!$E$16) | H16: =INDEX(curve_x3,'Metrics'!$E$16) | I16: =INDEX(curve_x4,'Metrics'!$E$16) | J16: =INDEX(curve_x5,'Metrics'!$E$16) | K16: =INDEX(curve_x6,'Metrics'!$E$16) | L16: =INDEX(curve_x7,'Metrics'!$E$16) | M16: =INDEX(curve_x8,'Metrics'!$E$16) | N16: =INDEX(curve_y1,'Metrics'!$E$16) | O16: =INDEX(curve_y2,'Metrics'!$E$16) | P16: =INDEX(curve_y3,'Metrics'!$E$16) | Q16: =INDEX(curve_y4,'Metrics'!$E$16) | R16: =INDEX(curve_y5,'Metrics'!$E$16) | S16: =INDEX(curve_y6,'Metrics'!$E$16) | T16: =INDEX(curve_y7,'Metrics'!$E$16) | U16: =INDEX(curve_y8,'Metrics'!$E$16) | V16: =IF(ISNUMBER('Metrics'!$B$16),MAX(0,MIN(1,IF('Metrics'!$B$16<='Metrics'!$F$16,'Metrics'!$N$16,IF('Metrics'!$B$16>='Metrics'!$M$16,'Metrics'!$U$16,IF('Metrics'!$B$16<='Metrics'!$G$16,IF('Metrics'!$G$16-'Metrics'!$F$16<=0,'Metrics'!$O$16,'Metrics'!$N$16+('Metrics'!$B$16-'Metrics'!$F$16)/('Metrics'!$G$16-'Metrics'!$F$16)*('Metrics'!$O$16-'Metrics'!$N$16)),IF('Metrics'!$B$16<='Metrics'!$H$16,IF('Metrics'!$H$16-'Metrics'!$G$16<=0,'Metrics'!$P$16,'Metrics'!$O$16+('Metrics'!$B$16-'Metrics'!$G$16)/('Metrics'!$H$16-'Metrics'!$G$16)*('Metrics'!$P$16-'Metrics'!$O$16)),IF('Metrics'!$B$16<='Metrics'!$I$16,IF('Metrics'!$I$16-'Metrics'!$H$16<=0,'Metrics'!$Q$16,'Metrics'!$P$16+('Metrics'!$B$16-'Metrics'!$H$16)/('Metrics'!$I$16-'Metrics'!$H$16)*('Metrics'!$Q$16-'Metrics'!$P$16)),IF('Metrics'!$B$16<='Metrics'!$J$16,IF('Metrics'!$J$16-'Metrics'!$I$16<=0,'Metrics'!$R$16,'Metrics'!$Q$16+('Metrics'!$B$16-'Metrics'!$I$16)/('Metrics'!$J$16-'Metrics'!$I$16)*('Metrics'!$R$16-'Metrics'!$Q$16)),IF('Metrics'!$B$16<='Metrics'!$K$16,IF('Metrics'!$K$16-'Metrics'!$J$16<=0,'Metrics'!$S$16,'Metrics'!$R$16+('Metrics'!$B$16-'Metrics'!$J$16)/('Metrics'!$K$16-'Metrics'!$J$16)*('Metrics'!$S$16-'Metrics'!$R$16)),IF('Metrics'!$B$16<='Metrics'!$L$16,IF('Metrics'!$L$16-'Metrics'!$K$16<=0,'Metrics'!$T$16,'Metrics'!$S$16+('Metrics'!$B$16-'Metrics'!$K$16)/('Metrics'!$L$16-'Metrics'!$K$16)*('Metrics'!$T$16-'Metrics'!$S$16)),IF('Metrics'!$M$16-'Metrics'!$L$16<=0,'Metrics'!$U$16,'Metrics'!$T$16+('Metrics'!$B$16-'Metrics'!$L$16)/('Metrics'!$M$16-'Metrics'!$L$16)*('Metrics'!$U$16-'Metrics'!$T$16)))))))))))),"")
A17: Bank angle | B17: =IF('DEEP Score'!$E$28="","",'DEEP Score'!$E$28) | C17: ="" | D17: ="spring_phab_xbka|"&'Metrics'!$C$17 | E17: =IFERROR(MATCH('Metrics'!$D$17,curve_key,0),MATCH("spring_phab_xbka|",curve_key,0)) | F17: =INDEX(curve_x1,'Metrics'!$E$17) | G17: =INDEX(curve_x2,'Metrics'!$E$17) | H17: =INDEX(curve_x3,'Metrics'!$E$17) | I17: =INDEX(curve_x4,'Metrics'!$E$17) | J17: =INDEX(curve_x5,'Metrics'!$E$17) | K17: =INDEX(curve_x6,'Metrics'!$E$17) | L17: =INDEX(curve_x7,'Metrics'!$E$17) | M17: =INDEX(curve_x8,'Metrics'!$E$17) | N17: =INDEX(curve_y1,'Metrics'!$E$17) | O17: =INDEX(curve_y2,'Metrics'!$E$17) | P17: =INDEX(curve_y3,'Metrics'!$E$17) | Q17: =INDEX(curve_y4,'Metrics'!$E$17) | R17: =INDEX(curve_y5,'Metrics'!$E$17) | S17: =INDEX(curve_y6,'Metrics'!$E$17) | T17: =INDEX(curve_y7,'Metrics'!$E$17) | U17: =INDEX(curve_y8,'Metrics'!$E$17) | V17: =IF(ISNUMBER('Metrics'!$B$17),MAX(0,MIN(1,IF('Metrics'!$B$17<='Metrics'!$F$17,'Metrics'!$N$17,IF('Metrics'!$B$17>='Metrics'!$M$17,'Metrics'!$U$17,IF('Metrics'!$B$17<='Metrics'!$G$17,IF('Metrics'!$G$17-'Metrics'!$F$17<=0,'Metrics'!$O$17,'Metrics'!$N$17+('Metrics'!$B$17-'Metrics'!$F$17)/('Metrics'!$G$17-'Metrics'!$F$17)*('Metrics'!$O$17-'Metrics'!$N$17)),IF('Metrics'!$B$17<='Metrics'!$H$17,IF('Metrics'!$H$17-'Metrics'!$G$17<=0,'Metrics'!$P$17,'Metrics'!$O$17+('Metrics'!$B$17-'Metrics'!$G$17)/('Metrics'!$H$17-'Metrics'!$G$17)*('Metrics'!$P$17-'Metrics'!$O$17)),IF('Metrics'!$B$17<='Metrics'!$I$17,IF('Metrics'!$I$17-'Metrics'!$H$17<=0,'Metrics'!$Q$17,'Metrics'!$P$17+('Metrics'!$B$17-'Metrics'!$H$17)/('Metrics'!$I$17-'Metrics'!$H$17)*('Metrics'!$Q$17-'Metrics'!$P$17)),IF('Metrics'!$B$17<='Metrics'!$J$17,IF('Metrics'!$J$17-'Metrics'!$I$17<=0,'Metrics'!$R$17,'Metrics'!$Q$17+('Metrics'!$B$17-'Metrics'!$I$17)/('Metrics'!$J$17-'Metrics'!$I$17)*('Metrics'!$R$17-'Metrics'!$Q$17)),IF('Metrics'!$B$17<='Metrics'!$K$17,IF('Metrics'!$K$17-'Metrics'!$J$17<=0,'Metrics'!$S$17,'Metrics'!$R$17+('Metrics'!$B$17-'Metrics'!$J$17)/('Metrics'!$K$17-'Metrics'!$J$17)*('Metrics'!$S$17-'Metrics'!$R$17)),IF('Metrics'!$B$17<='Metrics'!$L$17,IF('Metrics'!$L$17-'Metrics'!$K$17<=0,'Metrics'!$T$17,'Metrics'!$S$17+('Metrics'!$B$17-'Metrics'!$K$17)/('Metrics'!$L$17-'Metrics'!$K$17)*('Metrics'!$T$17-'Metrics'!$S$17)),IF('Metrics'!$M$17-'Metrics'!$L$17<=0,'Metrics'!$U$17,'Metrics'!$T$17+('Metrics'!$B$17-'Metrics'!$L$17)/('Metrics'!$M$17-'Metrics'!$L$17)*('Metrics'!$U$17-'Metrics'!$T$17)))))))))))),"")
A18: Relative bed stability | B18: =IF('DEEP Score'!$E$29="","",'DEEP Score'!$E$29) | C18: ="" | D18: ="spring_phab_lrbs_use|"&'Metrics'!$C$18 | E18: =IFERROR(MATCH('Metrics'!$D$18,curve_key,0),MATCH("spring_phab_lrbs_use|",curve_key,0)) | F18: =INDEX(curve_x1,'Metrics'!$E$18) | G18: =INDEX(curve_x2,'Metrics'!$E$18) | H18: =INDEX(curve_x3,'Metrics'!$E$18) | I18: =INDEX(curve_x4,'Metrics'!$E$18) | J18: =INDEX(curve_x5,'Metrics'!$E$18) | K18: =INDEX(curve_x6,'Metrics'!$E$18) | L18: =INDEX(curve_x7,'Metrics'!$E$18) | M18: =INDEX(curve_x8,'Metrics'!$E$18) | N18: =INDEX(curve_y1,'Metrics'!$E$18) | O18: =INDEX(curve_y2,'Metrics'!$E$18) | P18: =INDEX(curve_y3,'Metrics'!$E$18) | Q18: =INDEX(curve_y4,'Metrics'!$E$18) | R18: =INDEX(curve_y5,'Metrics'!$E$18) | S18: =INDEX(curve_y6,'Metrics'!$E$18) | T18: =INDEX(curve_y7,'Metrics'!$E$18) | U18: =INDEX(curve_y8,'Metrics'!$E$18) | V18: =IF(ISNUMBER('Metrics'!$B$18),MAX(0,MIN(1,IF('Metrics'!$B$18<='Metrics'!$F$18,'Metrics'!$N$18,IF('Metrics'!$B$18>='Metrics'!$M$18,'Metrics'!$U$18,IF('Metrics'!$B$18<='Metrics'!$G$18,IF('Metrics'!$G$18-'Metrics'!$F$18<=0,'Metrics'!$O$18,'Metrics'!$N$18+('Metrics'!$B$18-'Metrics'!$F$18)/('Metrics'!$G$18-'Metrics'!$F$18)*('Metrics'!$O$18-'Metrics'!$N$18)),IF('Metrics'!$B$18<='Metrics'!$H$18,IF('Metrics'!$H$18-'Metrics'!$G$18<=0,'Metrics'!$P$18,'Metrics'!$O$18+('Metrics'!$B$18-'Metrics'!$G$18)/('Metrics'!$H$18-'Metrics'!$G$18)*('Metrics'!$P$18-'Metrics'!$O$18)),IF('Metrics'!$B$18<='Metrics'!$I$18,IF('Metrics'!$I$18-'Metrics'!$H$18<=0,'Metrics'!$Q$18,'Metrics'!$P$18+('Metrics'!$B$18-'Metrics'!$H$18)/('Metrics'!$I$18-'Metrics'!$H$18)*('Metrics'!$Q$18-'Metrics'!$P$18)),IF('Metrics'!$B$18<='Metrics'!$J$18,IF('Metrics'!$J$18-'Metrics'!$I$18<=0,'Metrics'!$R$18,'Metrics'!$Q$18+('Metrics'!$B$18-'Metrics'!$I$18)/('Metrics'!$J$18-'Metrics'!$I$18)*('Metrics'!$R$18-'Metrics'!$Q$18)),IF('Metrics'!$B$18<='Metrics'!$K$18,IF('Metrics'!$K$18-'Metrics'!$J$18<=0,'Metrics'!$S$18,'Metrics'!$R$18+('Metrics'!$B$18-'Metrics'!$J$18)/('Metrics'!$K$18-'Metrics'!$J$18)*('Metrics'!$S$18-'Metrics'!$R$18)),IF('Metrics'!$B$18<='Metrics'!$L$18,IF('Metrics'!$L$18-'Metrics'!$K$18<=0,'Metrics'!$T$18,'Metrics'!$S$18+('Metrics'!$B$18-'Metrics'!$K$18)/('Metrics'!$L$18-'Metrics'!$K$18)*('Metrics'!$T$18-'Metrics'!$S$18)),IF('Metrics'!$M$18-'Metrics'!$L$18<=0,'Metrics'!$U$18,'Metrics'!$T$18+('Metrics'!$B$18-'Metrics'!$L$18)/('Metrics'!$M$18-'Metrics'!$L$18)*('Metrics'!$U$18-'Metrics'!$T$18)))))))))))),"")
A19: Large wood volume | B19: =IF('DEEP Score'!$E$32="","",'DEEP Score'!$E$32) | C19: ="" | D19: ="spring_phab_lwdeqvolm100|"&'Metrics'!$C$19 | E19: =IFERROR(MATCH('Metrics'!$D$19,curve_key,0),MATCH("spring_phab_lwdeqvolm100|",curve_key,0)) | F19: =INDEX(curve_x1,'Metrics'!$E$19) | G19: =INDEX(curve_x2,'Metrics'!$E$19) | H19: =INDEX(curve_x3,'Metrics'!$E$19) | I19: =INDEX(curve_x4,'Metrics'!$E$19) | J19: =INDEX(curve_x5,'Metrics'!$E$19) | K19: =INDEX(curve_x6,'Metrics'!$E$19) | L19: =INDEX(curve_x7,'Metrics'!$E$19) | M19: =INDEX(curve_x8,'Metrics'!$E$19) | N19: =INDEX(curve_y1,'Metrics'!$E$19) | O19: =INDEX(curve_y2,'Metrics'!$E$19) | P19: =INDEX(curve_y3,'Metrics'!$E$19) | Q19: =INDEX(curve_y4,'Metrics'!$E$19) | R19: =INDEX(curve_y5,'Metrics'!$E$19) | S19: =INDEX(curve_y6,'Metrics'!$E$19) | T19: =INDEX(curve_y7,'Metrics'!$E$19) | U19: =INDEX(curve_y8,'Metrics'!$E$19) | V19: =IF(ISNUMBER('Metrics'!$B$19),MAX(0,MIN(1,IF('Metrics'!$B$19<='Metrics'!$F$19,'Metrics'!$N$19,IF('Metrics'!$B$19>='Metrics'!$M$19,'Metrics'!$U$19,IF('Metrics'!$B$19<='Metrics'!$G$19,IF('Metrics'!$G$19-'Metrics'!$F$19<=0,'Metrics'!$O$19,'Metrics'!$N$19+('Metrics'!$B$19-'Metrics'!$F$19)/('Metrics'!$G$19-'Metrics'!$F$19)*('Metrics'!$O$19-'Metrics'!$N$19)),IF('Metrics'!$B$19<='Metrics'!$H$19,IF('Metrics'!$H$19-'Metrics'!$G$19<=0,'Metrics'!$P$19,'Metrics'!$O$19+('Metrics'!$B$19-'Metrics'!$G$19)/('Metrics'!$H$19-'Metrics'!$G$19)*('Metrics'!$P$19-'Metrics'!$O$19)),IF('Metrics'!$B$19<='Metrics'!$I$19,IF('Metrics'!$I$19-'Metrics'!$H$19<=0,'Metrics'!$Q$19,'Metrics'!$P$19+('Metrics'!$B$19-'Metrics'!$H$19)/('Metrics'!$I$19-'Metrics'!$H$19)*('Metrics'!$Q$19-'Metrics'!$P$19)),IF('Metrics'!$B$19<='Metrics'!$J$19,IF('Metrics'!$J$19-'Metrics'!$I$19<=0,'Metrics'!$R$19,'Metrics'!$Q$19+('Metrics'!$B$19-'Metrics'!$I$19)/('Metrics'!$J$19-'Metrics'!$I$19)*('Metrics'!$R$19-'Metrics'!$Q$19)),IF('Metrics'!$B$19<='Metrics'!$K$19,IF('Metrics'!$K$19-'Metrics'!$J$19<=0,'Metrics'!$S$19,'Metrics'!$R$19+('Metrics'!$B$19-'Metrics'!$J$19)/('Metrics'!$K$19-'Metrics'!$J$19)*('Metrics'!$S$19-'Metrics'!$R$19)),IF('Metrics'!$B$19<='Metrics'!$L$19,IF('Metrics'!$L$19-'Metrics'!$K$19<=0,'Metrics'!$T$19,'Metrics'!$S$19+('Metrics'!$B$19-'Metrics'!$K$19)/('Metrics'!$L$19-'Metrics'!$K$19)*('Metrics'!$T$19-'Metrics'!$S$19)),IF('Metrics'!$M$19-'Metrics'!$L$19<=0,'Metrics'!$U$19,'Metrics'!$T$19+('Metrics'!$B$19-'Metrics'!$L$19)/('Metrics'!$M$19-'Metrics'!$L$19)*('Metrics'!$U$19-'Metrics'!$T$19)))))))))))),"")
A20: Chlorophyll a | B20: =IF('DEEP Score'!$E$33="","",'DEEP Score'!$E$33) | C20: ="" | D20: ="spring_chem_chla|"&'Metrics'!$C$20 | E20: =IFERROR(MATCH('Metrics'!$D$20,curve_key,0),MATCH("spring_chem_chla|",curve_key,0)) | F20: =INDEX(curve_x1,'Metrics'!$E$20) | G20: =INDEX(curve_x2,'Metrics'!$E$20) | H20: =INDEX(curve_x3,'Metrics'!$E$20) | I20: =INDEX(curve_x4,'Metrics'!$E$20) | J20: =INDEX(curve_x5,'Metrics'!$E$20) | K20: =INDEX(curve_x6,'Metrics'!$E$20) | L20: =INDEX(curve_x7,'Metrics'!$E$20) | M20: =INDEX(curve_x8,'Metrics'!$E$20) | N20: =INDEX(curve_y1,'Metrics'!$E$20) | O20: =INDEX(curve_y2,'Metrics'!$E$20) | P20: =INDEX(curve_y3,'Metrics'!$E$20) | Q20: =INDEX(curve_y4,'Metrics'!$E$20) | R20: =INDEX(curve_y5,'Metrics'!$E$20) | S20: =INDEX(curve_y6,'Metrics'!$E$20) | T20: =INDEX(curve_y7,'Metrics'!$E$20) | U20: =INDEX(curve_y8,'Metrics'!$E$20) | V20: =IF(ISNUMBER('Metrics'!$B$20),MAX(0,MIN(1,IF('Metrics'!$B$20<='Metrics'!$F$20,'Metrics'!$N$20,IF('Metrics'!$B$20>='Metrics'!$M$20,'Metrics'!$U$20,IF('Metrics'!$B$20<='Metrics'!$G$20,IF('Metrics'!$G$20-'Metrics'!$F$20<=0,'Metrics'!$O$20,'Metrics'!$N$20+('Metrics'!$B$20-'Metrics'!$F$20)/('Metrics'!$G$20-'Metrics'!$F$20)*('Metrics'!$O$20-'Metrics'!$N$20)),IF('Metrics'!$B$20<='Metrics'!$H$20,IF('Metrics'!$H$20-'Metrics'!$G$20<=0,'Metrics'!$P$20,'Metrics'!$O$20+('Metrics'!$B$20-'Metrics'!$G$20)/('Metrics'!$H$20-'Metrics'!$G$20)*('Metrics'!$P$20-'Metrics'!$O$20)),IF('Metrics'!$B$20<='Metrics'!$I$20,IF('Metrics'!$I$20-'Metrics'!$H$20<=0,'Metrics'!$Q$20,'Metrics'!$P$20+('Metrics'!$B$20-'Metrics'!$H$20)/('Metrics'!$I$20-'Metrics'!$H$20)*('Metrics'!$Q$20-'Metrics'!$P$20)),IF('Metrics'!$B$20<='Metrics'!$J$20,IF('Metrics'!$J$20-'Metrics'!$I$20<=0,'Metrics'!$R$20,'Metrics'!$Q$20+('Metrics'!$B$20-'Metrics'!$I$20)/('Metrics'!$J$20-'Metrics'!$I$20)*('Metrics'!$R$20-'Metrics'!$Q$20)),IF('Metrics'!$B$20<='Metrics'!$K$20,IF('Metrics'!$K$20-'Metrics'!$J$20<=0,'Metrics'!$S$20,'Metrics'!$R$20+('Metrics'!$B$20-'Metrics'!$J$20)/('Metrics'!$K$20-'Metrics'!$J$20)*('Metrics'!$S$20-'Metrics'!$R$20)),IF('Metrics'!$B$20<='Metrics'!$L$20,IF('Metrics'!$L$20-'Metrics'!$K$20<=0,'Metrics'!$T$20,'Metrics'!$S$20+('Metrics'!$B$20-'Metrics'!$K$20)/('Metrics'!$L$20-'Metrics'!$K$20)*('Metrics'!$T$20-'Metrics'!$S$20)),IF('Metrics'!$M$20-'Metrics'!$L$20<=0,'Metrics'!$U$20,'Metrics'!$T$20+('Metrics'!$B$20-'Metrics'!$L$20)/('Metrics'!$M$20-'Metrics'!$L$20)*('Metrics'!$U$20-'Metrics'!$T$20)))))))))))),"")
A21: Canopy density, mid-channel | B21: =IF('DEEP Score'!$E$34="","",'DEEP Score'!$E$34) | C21: ="" | D21: ="spring_phab_xcdenmid|"&'Metrics'!$C$21 | E21: =IFERROR(MATCH('Metrics'!$D$21,curve_key,0),MATCH("spring_phab_xcdenmid|",curve_key,0)) | F21: =INDEX(curve_x1,'Metrics'!$E$21) | G21: =INDEX(curve_x2,'Metrics'!$E$21) | H21: =INDEX(curve_x3,'Metrics'!$E$21) | I21: =INDEX(curve_x4,'Metrics'!$E$21) | J21: =INDEX(curve_x5,'Metrics'!$E$21) | K21: =INDEX(curve_x6,'Metrics'!$E$21) | L21: =INDEX(curve_x7,'Metrics'!$E$21) | M21: =INDEX(curve_x8,'Metrics'!$E$21) | N21: =INDEX(curve_y1,'Metrics'!$E$21) | O21: =INDEX(curve_y2,'Metrics'!$E$21) | P21: =INDEX(curve_y3,'Metrics'!$E$21) | Q21: =INDEX(curve_y4,'Metrics'!$E$21) | R21: =INDEX(curve_y5,'Metrics'!$E$21) | S21: =INDEX(curve_y6,'Metrics'!$E$21) | T21: =INDEX(curve_y7,'Metrics'!$E$21) | U21: =INDEX(curve_y8,'Metrics'!$E$21) | V21: =IF(ISNUMBER('Metrics'!$B$21),MAX(0,MIN(1,IF('Metrics'!$B$21<='Metrics'!$F$21,'Metrics'!$N$21,IF('Metrics'!$B$21>='Metrics'!$M$21,'Metrics'!$U$21,IF('Metrics'!$B$21<='Metrics'!$G$21,IF('Metrics'!$G$21-'Metrics'!$F$21<=0,'Metrics'!$O$21,'Metrics'!$N$21+('Metrics'!$B$21-'Metrics'!$F$21)/('Metrics'!$G$21-'Metrics'!$F$21)*('Metrics'!$O$21-'Metrics'!$N$21)),IF('Metrics'!$B$21<='Metrics'!$H$21,IF('Metrics'!$H$21-'Metrics'!$G$21<=0,'Metrics'!$P$21,'Metrics'!$O$21+('Metrics'!$B$21-'Metrics'!$G$21)/('Metrics'!$H$21-'Metrics'!$G$21)*('Metrics'!$P$21-'Metrics'!$O$21)),IF('Metrics'!$B$21<='Metrics'!$I$21,IF('Metrics'!$I$21-'Metrics'!$H$21<=0,'Metrics'!$Q$21,'Metrics'!$P$21+('Metrics'!$B$21-'Metrics'!$H$21)/('Metrics'!$I$21-'Metrics'!$H$21)*('Metrics'!$Q$21-'Metrics'!$P$21)),IF('Metrics'!$B$21<='Metrics'!$J$21,IF('Metrics'!$J$21-'Metrics'!$I$21<=0,'Metrics'!$R$21,'Metrics'!$Q$21+('Metrics'!$B$21-'Metrics'!$I$21)/('Metrics'!$J$21-'Metrics'!$I$21)*('Metrics'!$R$21-'Metrics'!$Q$21)),IF('Metrics'!$B$21<='Metrics'!$K$21,IF('Metrics'!$K$21-'Metrics'!$J$21<=0,'Metrics'!$S$21,'Metrics'!$R$21+('Metrics'!$B$21-'Metrics'!$J$21)/('Metrics'!$K$21-'Metrics'!$J$21)*('Metrics'!$S$21-'Metrics'!$R$21)),IF('Metrics'!$B$21<='Metrics'!$L$21,IF('Metrics'!$L$21-'Metrics'!$K$21<=0,'Metrics'!$T$21,'Metrics'!$S$21+('Metrics'!$B$21-'Metrics'!$K$21)/('Metrics'!$L$21-'Metrics'!$K$21)*('Metrics'!$T$21-'Metrics'!$S$21)),IF('Metrics'!$M$21-'Metrics'!$L$21<=0,'Metrics'!$U$21,'Metrics'!$T$21+('Metrics'!$B$21-'Metrics'!$L$21)/('Metrics'!$M$21-'Metrics'!$L$21)*('Metrics'!$U$21-'Metrics'!$T$21)))))))))))),"")
A22: Riparian veg cover, woody | B22: =IF('DEEP Score'!$E$35="","",'DEEP Score'!$E$35) | C22: ="" | D22: ="spring_phab_xcmgw|"&'Metrics'!$C$22 | E22: =IFERROR(MATCH('Metrics'!$D$22,curve_key,0),MATCH("spring_phab_xcmgw|",curve_key,0)) | F22: =INDEX(curve_x1,'Metrics'!$E$22) | G22: =INDEX(curve_x2,'Metrics'!$E$22) | H22: =INDEX(curve_x3,'Metrics'!$E$22) | I22: =INDEX(curve_x4,'Metrics'!$E$22) | J22: =INDEX(curve_x5,'Metrics'!$E$22) | K22: =INDEX(curve_x6,'Metrics'!$E$22) | L22: =INDEX(curve_x7,'Metrics'!$E$22) | M22: =INDEX(curve_x8,'Metrics'!$E$22) | N22: =INDEX(curve_y1,'Metrics'!$E$22) | O22: =INDEX(curve_y2,'Metrics'!$E$22) | P22: =INDEX(curve_y3,'Metrics'!$E$22) | Q22: =INDEX(curve_y4,'Metrics'!$E$22) | R22: =INDEX(curve_y5,'Metrics'!$E$22) | S22: =INDEX(curve_y6,'Metrics'!$E$22) | T22: =INDEX(curve_y7,'Metrics'!$E$22) | U22: =INDEX(curve_y8,'Metrics'!$E$22) | V22: =IF(ISNUMBER('Metrics'!$B$22),MAX(0,MIN(1,IF('Metrics'!$B$22<='Metrics'!$F$22,'Metrics'!$N$22,IF('Metrics'!$B$22>='Metrics'!$M$22,'Metrics'!$U$22,IF('Metrics'!$B$22<='Metrics'!$G$22,IF('Metrics'!$G$22-'Metrics'!$F$22<=0,'Metrics'!$O$22,'Metrics'!$N$22+('Metrics'!$B$22-'Metrics'!$F$22)/('Metrics'!$G$22-'Metrics'!$F$22)*('Metrics'!$O$22-'Metrics'!$N$22)),IF('Metrics'!$B$22<='Metrics'!$H$22,IF('Metrics'!$H$22-'Metrics'!$G$22<=0,'Metrics'!$P$22,'Metrics'!$O$22+('Metrics'!$B$22-'Metrics'!$G$22)/('Metrics'!$H$22-'Metrics'!$G$22)*('Metrics'!$P$22-'Metrics'!$O$22)),IF('Metrics'!$B$22<='Metrics'!$I$22,IF('Metrics'!$I$22-'Metrics'!$H$22<=0,'Metrics'!$Q$22,'Metrics'!$P$22+('Metrics'!$B$22-'Metrics'!$H$22)/('Metrics'!$I$22-'Metrics'!$H$22)*('Metrics'!$Q$22-'Metrics'!$P$22)),IF('Metrics'!$B$22<='Metrics'!$J$22,IF('Metrics'!$J$22-'Metrics'!$I$22<=0,'Metrics'!$R$22,'Metrics'!$Q$22+('Metrics'!$B$22-'Metrics'!$I$22)/('Metrics'!$J$22-'Metrics'!$I$22)*('Metrics'!$R$22-'Metrics'!$Q$22)),IF('Metrics'!$B$22<='Metrics'!$K$22,IF('Metrics'!$K$22-'Metrics'!$J$22<=0,'Metrics'!$S$22,'Metrics'!$R$22+('Metrics'!$B$22-'Metrics'!$J$22)/('Metrics'!$K$22-'Metrics'!$J$22)*('Metrics'!$S$22-'Metrics'!$R$22)),IF('Metrics'!$B$22<='Metrics'!$L$22,IF('Metrics'!$L$22-'Metrics'!$K$22<=0,'Metrics'!$T$22,'Metrics'!$S$22+('Metrics'!$B$22-'Metrics'!$K$22)/('Metrics'!$L$22-'Metrics'!$K$22)*('Metrics'!$T$22-'Metrics'!$S$22)),IF('Metrics'!$M$22-'Metrics'!$L$22<=0,'Metrics'!$U$22,'Metrics'!$T$22+('Metrics'!$B$22-'Metrics'!$L$22)/('Metrics'!$M$22-'Metrics'!$L$22)*('Metrics'!$U$22-'Metrics'!$T$22)))))))))))),"")
A23: Total nitrogen | B23: =IF('DEEP Score'!$E$36="","",'DEEP Score'!$E$36) | C23: ="" | D23: ="spring_chem_ntl|"&'Metrics'!$C$23 | E23: =IFERROR(MATCH('Metrics'!$D$23,curve_key,0),MATCH("spring_chem_ntl|",curve_key,0)) | F23: =INDEX(curve_x1,'Metrics'!$E$23) | G23: =INDEX(curve_x2,'Metrics'!$E$23) | H23: =INDEX(curve_x3,'Metrics'!$E$23) | I23: =INDEX(curve_x4,'Metrics'!$E$23) | J23: =INDEX(curve_x5,'Metrics'!$E$23) | K23: =INDEX(curve_x6,'Metrics'!$E$23) | L23: =INDEX(curve_x7,'Metrics'!$E$23) | M23: =INDEX(curve_x8,'Metrics'!$E$23) | N23: =INDEX(curve_y1,'Metrics'!$E$23) | O23: =INDEX(curve_y2,'Metrics'!$E$23) | P23: =INDEX(curve_y3,'Metrics'!$E$23) | Q23: =INDEX(curve_y4,'Metrics'!$E$23) | R23: =INDEX(curve_y5,'Metrics'!$E$23) | S23: =INDEX(curve_y6,'Metrics'!$E$23) | T23: =INDEX(curve_y7,'Metrics'!$E$23) | U23: =INDEX(curve_y8,'Metrics'!$E$23) | V23: =IF(ISNUMBER('Metrics'!$B$23),MAX(0,MIN(1,IF('Metrics'!$B$23<='Metrics'!$F$23,'Metrics'!$N$23,IF('Metrics'!$B$23>='Metrics'!$M$23,'Metrics'!$U$23,IF('Metrics'!$B$23<='Metrics'!$G$23,IF('Metrics'!$G$23-'Metrics'!$F$23<=0,'Metrics'!$O$23,'Metrics'!$N$23+('Metrics'!$B$23-'Metrics'!$F$23)/('Metrics'!$G$23-'Metrics'!$F$23)*('Metrics'!$O$23-'Metrics'!$N$23)),IF('Metrics'!$B$23<='Metrics'!$H$23,IF('Metrics'!$H$23-'Metrics'!$G$23<=0,'Metrics'!$P$23,'Metrics'!$O$23+('Metrics'!$B$23-'Metrics'!$G$23)/('Metrics'!$H$23-'Metrics'!$G$23)*('Metrics'!$P$23-'Metrics'!$O$23)),IF('Metrics'!$B$23<='Metrics'!$I$23,IF('Metrics'!$I$23-'Metrics'!$H$23<=0,'Metrics'!$Q$23,'Metrics'!$P$23+('Metrics'!$B$23-'Metrics'!$H$23)/('Metrics'!$I$23-'Metrics'!$H$23)*('Metrics'!$Q$23-'Metrics'!$P$23)),IF('Metrics'!$B$23<='Metrics'!$J$23,IF('Metrics'!$J$23-'Metrics'!$I$23<=0,'Metrics'!$R$23,'Metrics'!$Q$23+('Metrics'!$B$23-'Metrics'!$I$23)/('Metrics'!$J$23-'Metrics'!$I$23)*('Metrics'!$R$23-'Metrics'!$Q$23)),IF('Metrics'!$B$23<='Metrics'!$K$23,IF('Metrics'!$K$23-'Metrics'!$J$23<=0,'Metrics'!$S$23,'Metrics'!$R$23+('Metrics'!$B$23-'Metrics'!$J$23)/('Metrics'!$K$23-'Metrics'!$J$23)*('Metrics'!$S$23-'Metrics'!$R$23)),IF('Metrics'!$B$23<='Metrics'!$L$23,IF('Metrics'!$L$23-'Metrics'!$K$23<=0,'Metrics'!$T$23,'Metrics'!$S$23+('Metrics'!$B$23-'Metrics'!$K$23)/('Metrics'!$L$23-'Metrics'!$K$23)*('Metrics'!$T$23-'Metrics'!$S$23)),IF('Metrics'!$M$23-'Metrics'!$L$23<=0,'Metrics'!$U$23,'Metrics'!$T$23+('Metrics'!$B$23-'Metrics'!$L$23)/('Metrics'!$M$23-'Metrics'!$L$23)*('Metrics'!$U$23-'Metrics'!$T$23)))))))))))),"")
