Workbook
Name anchor_good: 'Reference'!$B$6
Name score_good: 'Reference'!$C$6
Name anchor_fair: 'Reference'!$B$7
Name score_fair: 'Reference'!$C$7
Name anchor_poor: 'Reference'!$B$8
Name score_poor: 'Reference'!$C$8
Name curve_keys: 'Reference'!$A$90:$A$123
Name curve_x1: 'Reference'!$G$90:$G$123
Name curve_y1: 'Reference'!$H$90:$H$123
Name curve_x2: 'Reference'!$I$90:$I$123
Name curve_y2: 'Reference'!$J$90:$J$123
Name curve_x3: 'Reference'!$K$90:$K$123
Name curve_y3: 'Reference'!$L$90:$L$123
Name curve_x4: 'Reference'!$M$90:$M$123
Name curve_y4: 'Reference'!$N$90:$N$123
Name curve_x5: 'Reference'!$O$90:$O$123
Name curve_y5: 'Reference'!$P$90:$P$123
Name curve_x39: 'Reference'!$Q$90:$Q$123
Name curve_x69: 'Reference'!$R$90:$R$123
Name nutrient_regions: 'Reference'!$A$127:$A$135
Name nutrient_tn_gf: 'Reference'!$B$127:$B$135
Name nutrient_tn_fp: 'Reference'!$C$127:$C$135
Name nutrient_tp_gf: 'Reference'!$D$127:$D$135
Name nutrient_tp_fp: 'Reference'!$E$127:$E$135
Name attains_keys: 'Reference'!$A$139:$A$145
Name attains_ratings: 'Reference'!$B$139:$B$145
Name site_name: 'EASI Score'!$B$2
Name site_assessor: 'EASI Score'!$G$2
Name site_comid: 'EASI Score'!$K$2
Name site_coords: 'EASI Score'!$B$3
Name site_date: 'EASI Score'!$G$3
Name ctx_region: 'EASI Score'!$K$3
Name ctx_fcode: 'EASI Score'!$B$4
Name ctx_slope_override: 'EASI Score'!$G$4
Name calc_slope_class: 'EASI Score'!$K$4
Name in_impervious: 'EASI Score'!$J$8
Name in_agriculture: 'EASI Score'!$J$9
Name in_woodyWetland: 'EASI Score'!$J$10
Name in_herbaceousWetland: 'EASI Score'!$J$11
Name in_roadDensity: 'EASI Score'!$J$13
Name in_storage: 'EASI Score'!$J$14
Name in_runoff: 'EASI Score'!$J$15
Name in_flowCv: 'EASI Score'!$J$17
Name in_bhr: 'EASI Score'!$J$18
Name in_er: 'EASI Score'!$J$19
Name in_slope: 'EASI Score'!$J$20
Name in_sinuosity: 'EASI Score'!$J$22
Name ov_stageClass: 'EASI Score'!$J$25
Name ov_indicators: 'EASI Score'!$J$26
Name ov_erodingBankPct: 'EASI Score'!$J$28
Name ov_armoredBankPct: 'EASI Score'!$J$29
Name in_kFactor: 'EASI Score'!$J$31
Name in_woodyRiparian: 'EASI Score'!$J$34
Name in_forest: 'EASI Score'!$J$36
Name in_shrub: 'EASI Score'!$J$37
Name in_grassland: 'EASI Score'!$J$38
Name in_wetland: 'EASI Score'!$J$39
Name in_tn: 'EASI Score'!$J$41
Name in_tp: 'EASI Score'!$J$42
Name in_chemCatchment: 'EASI Score'!$J$43

Sheet Instructions
A1: Model Name | B1: Ecosystem Assessment Screening Index (EASI) | D1: Color Coding Key:
A2: Developers | B2: Leanne M. Stepchinski, Gabrielle C. David, Samantha R. Wiest, and Garrett T. Menichino | D2: User Input
B3: U.S. Army Engineer Research and Development Center, Environmental Laboratory | D3: Calculated
B4: Vicksburg, MS | D4: Linked to Another Cell
B5: Leanne.M.Stepchinski@usace.army.mil, Gabrielle.C.David@usace.army.mil, Samantha.R.Wiest@erdc.dren.mil, Garrett.T.Menichino@usace.army.mil
D6: Select an orange cell to read its guidance note.
A7: Model Version | B7: EASI calculator v1.1.0, scoring method b2e3033116e3 (Alternative 2: NARS-9 references) | D7: Sheets: EASI Score (entries and results), Metrics (every rule and route), Reference (bands, curves, weights), Metadata (method identity).
A8: Date of Last Update | B8: 46282
A10: Waiver | B10: This model is provided for free as part of the USACE Technical Report "Ecosystem Assessment Screening Index (EASI)" by Leanne M. Stepchinski, Gabrielle C. David, Samantha R. Wiest, and Garrett T. Menichino. It ships with the STAF web application, whose EASI report offers the same download.
B11: None of the authors nor the US Army Corps of Engineers accepts responsibility or liability for the model's use by third parties.
A13: Instructions
A14: 1) | B14: Add the site information into the orange cells at the top of the EASI Score worksheet: reach ID, coordinates, date, assessor, NHDPlus V2 COMID, the NARS-9 ecoregion (drop-down) and the NHD feature code.
A15: 2) | B15: Enter each desktop quantity once in the orange cells of the Metrics columns (column J). The Source column names the StreamCat field or the EASI report item each value comes from. Select a cell to read its guidance note.
A16: 3) | B16: Grey cells repeat an entry made higher in the table and cannot be edited. White cells in column J are computed from the entries above them.
A17: 4) | B17: Leave a cell blank when the evidence is unavailable. Never enter zero for unknown: a zero is evidence. A blank input leaves its function unrated, and unrated functions drop out of the sub-indices and the index.
A18: 5) | B18: Optional: enter the twelve EROM mean monthly flows in the helper block below the table and copy the computed variability into the Low flow row, and enter the observed channel class, indicators and bank percentages if you have field observations.
A19: 6) | B19: Ratings, function scores (0 to 15), the outcome sub-indices and the EASI index auto-populate (columns A to H). The scoring summary table, the legends and the charts to the right of the table also auto-populate.
A20: 7) | B20: Record other observations, sources or assumptions in the grey box at the bottom of the worksheet.
A22: Comments/Assumptions
A23: 1) | B23: The calculator implements the EASI scoring method of the web application exactly: the same bands, regional reference curves, lookups, weights and rounding, generated from the application's own scoring definitions. Same inputs give the same ratings, function scores, sub-indices and index. The Metadata sheet identifies the method.
A24: 2) | B24: The Metrics sheet shows every input, rule and route that produced a rating. The Reference sheet lists the bands, the reference curves, the regional nutrient thresholds, the lookups and the outcome weights.
A25: 3) | B25: Derived values (ratios, sums and products) are rounded to twelve decimals before banding, as in the application. Displayed indices are rounded to two decimals. When a sub-index lands exactly on a half-hundredth, Excel rounds away from zero and the application rounds to the even digit, so the displayed value can differ by 0.01 while the class is the same.
A26: 4) | B26: The calculator does not retrieve data, delineate a watershed or draw cross-sections. The observed channel and bank entries are the only expert-review inputs it supports. Entries outside the documented ranges are refused.
A27: 5) | B27: EASI is a screening-level desktop estimate, not a field-validated assessment. The reference curves express regional expectations derived from least-disturbed reaches, and several proxies remain unvalidated. The technical report states each metric's limitations.
A28: 6) | B28: All computed cells are locked and the sheets are protected without a secret password (it is 'easi'), so a mistaken edit is unlikely, not impossible.

Sheet EASI Score
A1: Ecosystem Assessment Screening Index (EASI) Worksheet
A2: Reach ID | F2: Assessor(s) | J2: COMID
A3: Lat/Long | F3: Date | J3: NARS-9 region
A4: NHD FCODE | F4: Slope class override | J4: Slope class used | K4: =IF('EASI Score'!$G$4<>"",'EASI Score'!$G$4,IF(NOT(ISNUMBER('EASI Score'!$J$20)),"national",IF('EASI Score'!$J$20<0,"national",IF('EASI Score'!$J$20<0.005,"lt_0.5",IF('EASI Score'!$J$20<0.02,"0.5_to_2","ge_2")))))
A5: EASI | B5: Outcomes | D5: Functional Categories | F5: Functions | I5: Metrics | O5: Scoring Summary | R5: Outcomes | V5: EASI Index Scoring | Y5: Function Scoring
A6: Index Score | B6: Name | C6: Sub-Index Score | D6: Name | E6: Functions Rated | F6: Name | G6: Rating | H6: Function Score | I6: Name | J6: Value | K6: Units | L6: Input Rating | M6: Source | O6: Functional Categories | P6: Functions | Q6: Score | R6: Physical | S6: Chemical | T6: Biological | V6: 1.00 | W6: Functioning | Y6: 15 | Z6: Functioning
A8: =IF('Results'!$E$30="","",'Results'!$E$30) | B8: Physical | C8: =IF('Results'!$E$27="","",'Results'!$E$27) | D8: Hydrology | E8: =COUNT('EASI Score'!$H$8:$H$16) | F8: Catchment hydrology | G8: ='Metrics'!$C$11 | H8: ='Metrics'!$B$12 | I8: Impervious cover of the watershed | K8: % | L8: ='Metrics'!$C$6 | M8: StreamCat pctimp2019ws | O8: Hydrology | P8: Catchment hydrology | Q8: =IF('EASI Score'!$H$8="","",'EASI Score'!$H$8) | R8: D | S8: i | T8: i | V8: 0.70 | Y8: 11
I9: Agricultural cover of the watershed (crop, hay and pasture) | K9: % | L9: ='Metrics'!$C$7 | M9: StreamCat pctcrop2019ws + pcthay2019ws | P9: Surface water storage | Q9: =IF('EASI Score'!$H$10="","",'EASI Score'!$H$10) | R9: D | S9: i | T9: i | W9: Functioning At-Risk | Y9: 10 | Z9: Functioning At-Risk
F10: Surface water storage | G10: ='Metrics'!$C$21 | H10: ='Metrics'!$B$22 | I10: Woody wetland cover of the watershed | K10: % | M10: StreamCat pctwdwet2019ws | P10: Reach inflow | Q10: =IF('EASI Score'!$H$13="","",'EASI Score'!$H$13) | R10: D | S10: i | T10: i
I11: Herbaceous wetland cover of the watershed | K11: % | M11: StreamCat pcthbwet2019ws | P11: Streamflow regime | Q11: =IF('EASI Score'!$H$14="","",'EASI Score'!$H$14) | R11: D | S11: i | T11: i | V11: 0.40 | Y11: 6
I12: Wetland extent (sum, capped at 100) | J12: =IF('Metrics'!$B$19="","",'Metrics'!$B$19) | K12: % | L12: ='Metrics'!$C$21 | M12: Computed from the entries above | O12: Hydraulics | P12: Low flow and baseflow dynamics | Q12: =IF('EASI Score'!$H$17="","",'EASI Score'!$H$17) | R12: D | S12: i | T12: i | W12: Non-Functioning | Y12: 5 | Z12: Non-Functioning
F13: Reach inflow | G13: ='Metrics'!$C$29 | H13: ='Metrics'!$B$30 | I13: Road density of the watershed | K13: km/km2 | L13: ='Metrics'!$C$29 | M13: StreamCat rddensws | P13: High flow dynamics | Q13: =IF('EASI Score'!$H$18="","",'EASI Score'!$H$18) | R13: D | S13: i | T13: i
F14: Streamflow regime | G14: ='Metrics'!$C$39 | H14: ='Metrics'!$B$40 | I14: Normalized dam storage upstream | K14: m3/km2 | M14: StreamCat damnrmstorws | P14: Floodplain connectivity | Q14: =IF('EASI Score'!$H$19="","",'EASI Score'!$H$19) | R14: D | S14: i | T14: i | V14: 0.00 | Y14: 0
I15: Mean annual runoff of the watershed | K15: mm | M15: StreamCat runoffws | P15: Hyporheic connectivity | Q15: =IF('EASI Score'!$H$21="","",'EASI Score'!$H$21) | R15: D | S15: i | T15: i
I16: Degree of regulation | J16: =IF('Metrics'!$B$37="","",'Metrics'!$B$37) | K16: % | L16: ='Metrics'!$C$39 | M16: Computed from the entries above | O16: Geomorphology | P16: Channel evolution | Q16: =IF('EASI Score'!$H$23="","",'EASI Score'!$H$23) | R16: D | S16: i | T16: i
D17: Hydraulics | E17: =COUNT('EASI Score'!$H$17:$H$22) | F17: Low flow and baseflow dynamics | G17: ='Metrics'!$C$50 | H17: ='Metrics'!$B$51 | I17: Monthly flow variability (CV of the twelve EROM monthly flows) | K17: ratio | L17: ='Metrics'!$C$50 | M17: NHDPlus V2 EROM QE_01 to QE_12, or the helper below | P17: Channel and floodplain dynamics | Q17: =IF('EASI Score'!$H$27="","",'EASI Score'!$H$27) | R17: D | S17: i | T17: i | V17: Rating to Function Score
F18: High flow dynamics | G18: ='Metrics'!$C$58 | H18: ='Metrics'!$B$59 | I18: Bank-height ratio (reach median) | K18: ratio | L18: ='Metrics'!$C$58 | M18: EASI report cross-section block or a field survey | P18: Sediment continuity | Q18: =IF('EASI Score'!$H$30="","",'EASI Score'!$H$30) | R18: D | S18: i | T18: i | V18: Rating | Y18: Score
F19: Floodplain connectivity | G19: ='Metrics'!$C$68 | H19: ='Metrics'!$B$69 | I19: Entrenchment ratio (reach median) | K19: ratio | L19: ='Metrics'!$C$68 | M19: EASI report cross-section block or a field survey | P19: Bed composition and large wood | Q19: =IF('EASI Score'!$H$33="","",'EASI Score'!$H$33) | R19: D | S19: i | T19: i | V19: Good (Functioning) | Y19: ='Reference'!$C$6
I20: Channel slope | K20: m/m | M20: NHDPlus V2 VAA slope | O20: Physicochemistry | P20: Light & thermal regime | Q20: =IF('EASI Score'!$H$34="","",'EASI Score'!$H$34) | S20: D | T20: i | V20: Fair (Functioning At-Risk) | Y20: ='Reference'!$C$7
F21: Hyporheic connectivity | G21: ='Metrics'!$C$79 | H21: ='Metrics'!$B$80 | I21: Channel slope | J21: =IF('EASI Score'!$J$20="","",'EASI Score'!$J$20) | K21: m/m | L21: ='Metrics'!$C$74 | M21: NHDPlus V2 VAA slope | P21: Carbon processing | Q21: =IF('EASI Score'!$H$36="","",'EASI Score'!$H$36) | S21: D | T21: i | V21: Poor (Non-Functioning) | Y21: ='Reference'!$C$8
I22: Reach sinuosity | K22: ratio | L22: ='Metrics'!$C$75 | M22: Reach geometry (channel length over straight-line length) | P22: Nutrient cycling | Q22: =IF('EASI Score'!$H$41="","",'EASI Score'!$H$41) | R22: i | S22: D | T22: i | V22: Not rated (blank input) | Y22: excluded from the rollup
D23: Geomorphology | E23: =COUNT('EASI Score'!$H$23:$H$33) | F23: Channel evolution | G23: ='Metrics'!$C$91 | H23: ='Metrics'!$B$92 | I23: Bank-height ratio (reach median) | J23: =IF('EASI Score'!$J$18="","",'EASI Score'!$J$18) | K23: ratio | L23: ='Metrics'!$C$85 | M23: EASI report cross-section block or a field survey | P23: Water & soil quality | Q23: =IF('EASI Score'!$H$45="","",'EASI Score'!$H$45) | R23: i | S23: D | T23: i
I24: Entrenchment ratio (reach median) | J24: =IF('EASI Score'!$J$19="","",'EASI Score'!$J$19) | K24: ratio | L24: ='Metrics'!$C$88 | M24: EASI report cross-section block or a field survey | O24: Biology | P24: Habitat provision | Q24: =IF('EASI Score'!$H$48="","",'EASI Score'!$H$48) | T24: D
I25: Observed channel-evolution class (optional) | M25: Field assessment or verified imagery | P25: Population support | Q25: =IF('EASI Score'!$H$49="","",'EASI Score'!$H$49) | R25: i | S25: i | T25: D
I26: Observed channel-evolution indicators (note) (optional) | M26: Field assessment or verified imagery | P26: Community dynamics | Q26: =IF('EASI Score'!$H$64="","",'EASI Score'!$H$64) | R26: i | S26: i | T26: D
F27: Channel and floodplain dynamics | G27: ='Metrics'!$C$101 | H27: ='Metrics'!$B$102 | I27: Bank-height ratio (reach median) | J27: =IF('EASI Score'!$J$18="","",'EASI Score'!$J$18) | K27: ratio | M27: EASI report cross-section block or a field survey | P27: Watershed connectivity | Q27: =IF('EASI Score'!$H$65="","",'EASI Score'!$H$65) | R27: i | T27: D
I28: Observed eroding bank (optional) | K28: % | L28: ='Metrics'!$C$98 | M28: Field assessment or verified imagery | O28: Sub-index Scores | R28: =IF('Results'!$E$27="","",'Results'!$E$27) | S28: =IF('Results'!$E$28="","",'Results'!$E$28) | T28: =IF('Results'!$E$29="","",'Results'!$E$29)
I29: Observed armored bank (optional) | K29: % | L29: ='Metrics'!$C$99 | M29: Field assessment or verified imagery | O29: EASI Index | R29: =IF('Results'!$E$30="","",'Results'!$E$30)
F30: Sediment continuity | G30: ='Metrics'!$C$113 | H30: ='Metrics'!$B$114 | I30: Agricultural cover of the watershed (crop, hay and pasture) | J30: =IF('EASI Score'!$J$9="","",'EASI Score'!$J$9) | K30: % | L30: ='Metrics'!$C$107 | M30: StreamCat pctcrop2019ws + pcthay2019ws | O30: Functions rated | R30: ='Results'!$B$33
I31: Soil erodibility (K factor) of the watershed | L31: ='Metrics'!$C$108 | M31: StreamCat kffactws | O31: Coverage | R31: ='Results'!$B$37
I32: Road density of the watershed | J32: =IF('EASI Score'!$J$13="","",'EASI Score'!$J$13) | K32: km/km2 | L32: ='Metrics'!$C$109 | M32: StreamCat rddensws | O32: Provisional result | R32: =IF('Results'!$B$36="yes","yes (coverage below 0.70)","no")
F33: Bed composition and large wood | G33: ='Metrics'!$C$121 | H33: ='Metrics'!$B$122 | I33: Agricultural cover of the watershed (crop, hay and pasture) | J33: =IF('EASI Score'!$J$9="","",'EASI Score'!$J$9) | K33: % | L33: ='Metrics'!$C$121 | M33: StreamCat pctcrop2019ws + pcthay2019ws
B34: Chemical | C34: =IF('Results'!$E$28="","",'Results'!$E$28) | D34: Physicochemistry | E34: =COUNT('EASI Score'!$H$34:$H$47) | F34: Light & thermal regime | G34: ='Metrics'!$C$134 | H34: ='Metrics'!$B$135 | I34: Woody riparian cover in the 100 m corridor | K34: % | L34: ='Metrics'!$C$129 | M34: StreamCat forest + shrub + woody wetland at wsrp100
I35: Impervious cover of the watershed | J35: =IF('EASI Score'!$J$8="","",'EASI Score'!$J$8) | K35: % | L35: ='Metrics'!$C$130 | M35: StreamCat pctimp2019ws
F36: Carbon processing | G36: ='Metrics'!$C$148 | H36: ='Metrics'!$B$149 | I36: Forest cover in the 100 m corridor | K36: % | M36: StreamCat pctconif + pctdecid + pctmxfst at wsrp100
I37: Shrub cover in the 100 m corridor | K37: % | M37: StreamCat pctshrb2019wsrp100
I38: Grassland cover in the 100 m corridor | K38: % | M38: StreamCat pctgrs2019wsrp100
I39: Wetland cover in the 100 m corridor (woody and herbaceous) | K39: % | M39: StreamCat pctwdwet + pcthbwet at wsrp100
I40: Natural corridor cover (sum, capped at 100) | J40: =IF('Metrics'!$B$144="","",'Metrics'!$B$144) | K40: % | L40: ='Metrics'!$C$148 | M40: Computed from the entries above
F41: Nutrient cycling | G41: ='Metrics'!$C$158 | H41: ='Metrics'!$B$159 | I41: Total nitrogen (median of station medians) | K41: mg/L | L41: ='Metrics'!$C$154 | M41: WQP total-fraction observations within 5 miles and 10 years
...

Sheet Metrics
A1: EASI calculator: metric scoring
A2: Read only. One block per function: the inputs it reads, the route that applied, the rating, the index anchor and the function score. Ratings follow the application's catalog exactly. The entries live on the EASI Score sheet.
A4: 1. Catchment hydrology | B4: Catchment hydrology (land-cover pressure) (catchment-land-cover-pressure, worst_index)
A5: Item | B5: Value | C5: Rating | D5: Index | E5: Note
A6: Watershed impervious cover | B6: =IF('EASI Score'!$J$8="","",'EASI Score'!$J$8) | C6: =IF(NOT(ISNUMBER('EASI Score'!$J$8)),"",IF('EASI Score'!$J$8<10,"Good",IF(AND('EASI Score'!$J$8>=10,'EASI Score'!$J$8<=25),"Fair",IF('EASI Score'!$J$8>25,"Poor","")))) | D6: =IF('Metrics'!$C$6="Good",'Reference'!$B$6,IF('Metrics'!$C$6="Fair",'Reference'!$B$7,IF('Metrics'!$C$6="Poor",'Reference'!$B$8,"")))
A7: Watershed agricultural cover | B7: =IF('EASI Score'!$J$9="","",'EASI Score'!$J$9) | C7: =IF(NOT(ISNUMBER('EASI Score'!$J$9)),"",IF('EASI Score'!$J$9<30,"Good",IF(AND('EASI Score'!$J$9>=30,'EASI Score'!$J$9<=50),"Fair",IF('EASI Score'!$J$9>50,"Poor","")))) | D7: =IF('Metrics'!$C$7="Good",'Reference'!$B$6,IF('Metrics'!$C$7="Fair",'Reference'!$B$7,IF('Metrics'!$C$7="Poor",'Reference'!$B$8,"")))
A8: Governing input | B8: =IF('Metrics'!$B$9="","",INDEX('Metrics'!$A$6:$A$7,MATCH('Metrics'!$B$9,'Metrics'!$D$6:$D$7,0)))
A9: Combined rating index (the more limiting input) | B9: =IF(COUNT('Metrics'!$D$6:$D$7)=0,"",MIN('Metrics'!$D$6:$D$7))
A10: Route that applied | B10: ="automatic method"
A11: Function rating | C11: =IF(NOT(ISNUMBER('Metrics'!$B$9)),"",IF('Metrics'!$B$9='Reference'!$B$6,"Good",IF('Metrics'!$B$9='Reference'!$B$7,"Fair",IF('Metrics'!$B$9='Reference'!$B$8,"Poor","")))) | D11: =IF('Metrics'!$C$11="Good",'Reference'!$B$6,IF('Metrics'!$C$11="Fair",'Reference'!$B$7,IF('Metrics'!$C$11="Poor",'Reference'!$B$8,""))) | E11: Partial rating allowed when one input is missing.
A12: Function score (0 to 15) | B12: =IF('Metrics'!$C$11="Good",'Reference'!$C$6,IF('Metrics'!$C$11="Fair",'Reference'!$C$7,IF('Metrics'!$C$11="Poor",'Reference'!$C$8,"")))
A13: Status | B13: =IF(COUNT('Metrics'!$D$6:$D$7)=0,"not rated",IF(COUNT('Metrics'!$D$6:$D$7)<2,"partial","complete"))
A15: 2. Surface water storage | B15: Wetland extent (watershed-wetland-extent, sum_capped)
A16: Item | B16: Value | C16: Rating | D16: Index | E16: Note
A17: Woody wetland cover | B17: =IF('EASI Score'!$J$10="","",'EASI Score'!$J$10)
A18: Herbaceous wetland cover | B18: =IF('EASI Score'!$J$11="","",'EASI Score'!$J$11)
A19: Combined value (sum capped at 100) | B19: =IF(AND(ISNUMBER('EASI Score'!$J$10),ISNUMBER('EASI Score'!$J$11)),ROUND(MIN('EASI Score'!$J$10+'EASI Score'!$J$11,100),12),"")
A20: Route that applied | B20: ="automatic method"
A21: Function rating | C21: =IF(NOT(ISNUMBER('Metrics'!$B$19)),"",IF('Metrics'!$B$19<1,"Poor",IF(AND('Metrics'!$B$19>=1,'Metrics'!$B$19<=5),"Fair",IF('Metrics'!$B$19>5,"Good","")))) | D21: =IF('Metrics'!$C$21="Good",'Reference'!$B$6,IF('Metrics'!$C$21="Fair",'Reference'!$B$7,IF('Metrics'!$C$21="Poor",'Reference'!$B$8,""))) | E21: All classes are required. A missing class is unknown, not zero.
A22: Function score (0 to 15) | B22: =IF('Metrics'!$C$21="Good",'Reference'!$C$6,IF('Metrics'!$C$21="Fair",'Reference'!$C$7,IF('Metrics'!$C$21="Poor",'Reference'!$C$8,"")))
A23: Status | B23: =IF('Metrics'!$C$21="","not rated","complete")
A25: 3. Reach inflow | B25: Road-density proxy for concentrated inflow pressure (road-density-inflow-pressure, threshold)
A26: Item | B26: Value | C26: Rating | D26: Index | E26: Note
A27: Watershed road density | B27: =IF('EASI Score'!$J$13="","",'EASI Score'!$J$13)
A28: Route that applied | B28: ="automatic method"
A29: Function rating | C29: =IF(NOT(ISNUMBER('EASI Score'!$J$13)),"",IF('EASI Score'!$J$13<1,"Good",IF(AND('EASI Score'!$J$13>=1,'EASI Score'!$J$13<3),"Fair",IF('EASI Score'!$J$13>=3,"Poor","")))) | D29: =IF('Metrics'!$C$29="Good",'Reference'!$B$6,IF('Metrics'!$C$29="Fair",'Reference'!$B$7,IF('Metrics'!$C$29="Poor",'Reference'!$B$8,"")))
A30: Function score (0 to 15) | B30: =IF('Metrics'!$C$29="Good",'Reference'!$C$6,IF('Metrics'!$C$29="Fair",'Reference'!$C$7,IF('Metrics'!$C$29="Poor",'Reference'!$C$8,"")))
A31: Status | B31: =IF('Metrics'!$C$29="","not rated","complete")
A33: 4. Streamflow regime | B33: Flow alteration (degree of regulation) (degree-of-regulation, ratio)
A34: Item | B34: Value | C34: Rating | D34: Index | E34: Note
A35: Upstream normalized storage | B35: =IF('EASI Score'!$J$14="","",'EASI Score'!$J$14)
A36: Annual runoff | B36: =IF('EASI Score'!$J$15="","",'EASI Score'!$J$15)
A37: Degree of regulation (%) | B37: =IF(AND(ISNUMBER('EASI Score'!$J$14),ISNUMBER('EASI Score'!$J$15),'EASI Score'!$J$15<>0,'EASI Score'!$J$15>0),ROUND((100*'EASI Score'!$J$14)/(1000*'EASI Score'!$J$15),12),"")
A38: Route that applied | B38: ="automatic method"
A39: Function rating | C39: =IF(NOT(ISNUMBER('Metrics'!$B$37)),"",IF('Metrics'!$B$37<2,"Good",IF(AND('Metrics'!$B$37>=2,'Metrics'!$B$37<=15),"Fair",IF('Metrics'!$B$37>15,"Poor","")))) | D39: =IF('Metrics'!$C$39="Good",'Reference'!$B$6,IF('Metrics'!$C$39="Fair",'Reference'!$B$7,IF('Metrics'!$C$39="Poor",'Reference'!$B$8,"")))
A40: Function score (0 to 15) | B40: =IF('Metrics'!$C$39="Good",'Reference'!$C$6,IF('Metrics'!$C$39="Fair",'Reference'!$C$7,IF('Metrics'!$C$39="Poor",'Reference'!$C$8,"")))
A41: Status | B41: =IF('Metrics'!$C$39="","not rated","complete")
A43: 5. Low flow and baseflow dynamics | B43: Low-flow condition (erom-flow-variability, threshold)
A44: Item | B44: Value | C44: Rating | D44: Index | E44: Note
A45: Monthly flow variability | B45: =IF('EASI Score'!$J$17="","",'EASI Score'!$J$17)
...

Sheet Results
A1: EASI calculator: results
A2: Engine sheet (hidden). Function scores, outcome sub-indices and the Ecosystem Condition Index, computed with the STAF rollup: unrated functions leave both the numerator and the denominator. The EASI Score sheet displays these cells.
A4: Function | B4: Discipline | C4: Metric | D4: Rating | E4: Score | F4: Class | G4: Physical | H4: Chemical | I4: Biological | J4: Score or 0 | K4: Rated | L4: Route
A5: Catchment hydrology | B5: Hydrology | C5: Watershed Land-Cover Pressure | D5: ='Metrics'!$C$11 | E5: ='Metrics'!$B$12 | F5: =IF(NOT(ISNUMBER('Results'!$E$5)),"Not assessed",IF('Results'!$E$5<=5,"Non-Functioning",IF('Results'!$E$5<=10,"Functioning-at-Risk","Functioning"))) | G5: 1 | H5: 0.1 | I5: 0.1 | J5: =IF(ISNUMBER('Results'!$E$5),'Results'!$E$5,0) | K5: =IF(ISNUMBER('Results'!$E$5),1,0) | L5: ='Metrics'!$B$10
A6: Surface water storage | B6: Hydrology | C6: Percent Wetlands in Watershed | D6: ='Metrics'!$C$21 | E6: ='Metrics'!$B$22 | F6: =IF(NOT(ISNUMBER('Results'!$E$6)),"Not assessed",IF('Results'!$E$6<=5,"Non-Functioning",IF('Results'!$E$6<=10,"Functioning-at-Risk","Functioning"))) | G6: 1 | H6: 0.1 | I6: 0.1 | J6: =IF(ISNUMBER('Results'!$E$6),'Results'!$E$6,0) | K6: =IF(ISNUMBER('Results'!$E$6),1,0) | L6: ='Metrics'!$B$20
A7: Reach inflow | B7: Hydrology | C7: Concentrated Runoff / Stormwater Inputs | D7: ='Metrics'!$C$29 | E7: ='Metrics'!$B$30 | F7: =IF(NOT(ISNUMBER('Results'!$E$7)),"Not assessed",IF('Results'!$E$7<=5,"Non-Functioning",IF('Results'!$E$7<=10,"Functioning-at-Risk","Functioning"))) | G7: 1 | H7: 0.1 | I7: 0.1 | J7: =IF(ISNUMBER('Results'!$E$7),'Results'!$E$7,0) | K7: =IF(ISNUMBER('Results'!$E$7),1,0) | L7: ='Metrics'!$B$28
A8: Streamflow regime | B8: Hydrology | C8: Flow Alteration (Regulation / Water Use) | D8: ='Metrics'!$C$39 | E8: ='Metrics'!$B$40 | F8: =IF(NOT(ISNUMBER('Results'!$E$8)),"Not assessed",IF('Results'!$E$8<=5,"Non-Functioning",IF('Results'!$E$8<=10,"Functioning-at-Risk","Functioning"))) | G8: 1 | H8: 0.1 | I8: 0.1 | J8: =IF(ISNUMBER('Results'!$E$8),'Results'!$E$8,0) | K8: =IF(ISNUMBER('Results'!$E$8),1,0) | L8: ='Metrics'!$B$38
A9: Low flow and baseflow dynamics | B9: Hydraulics | C9: Low-flow Wetted Connectivity | D9: ='Metrics'!$C$50 | E9: ='Metrics'!$B$51 | F9: =IF(NOT(ISNUMBER('Results'!$E$9)),"Not assessed",IF('Results'!$E$9<=5,"Non-Functioning",IF('Results'!$E$9<=10,"Functioning-at-Risk","Functioning"))) | G9: 1 | H9: 0.1 | I9: 0.1 | J9: =IF(ISNUMBER('Results'!$E$9),'Results'!$E$9,0) | K9: =IF(ISNUMBER('Results'!$E$9),1,0) | L9: ='Metrics'!$B$49
A10: High flow dynamics | B10: Hydraulics | C10: Floodplain Engagement Frequency (bankfull recurrence) | D10: ='Metrics'!$C$58 | E10: ='Metrics'!$B$59 | F10: =IF(NOT(ISNUMBER('Results'!$E$10)),"Not assessed",IF('Results'!$E$10<=5,"Non-Functioning",IF('Results'!$E$10<=10,"Functioning-at-Risk","Functioning"))) | G10: 1 | H10: 0.1 | I10: 0.1 | J10: =IF(ISNUMBER('Results'!$E$10),'Results'!$E$10,0) | K10: =IF(ISNUMBER('Results'!$E$10),1,0) | L10: ='Metrics'!$B$57
A11: Floodplain connectivity | B11: Hydraulics | C11: Floodplain Access / Entrenchment | D11: ='Metrics'!$C$68 | E11: ='Metrics'!$B$69 | F11: =IF(NOT(ISNUMBER('Results'!$E$11)),"Not assessed",IF('Results'!$E$11<=5,"Non-Functioning",IF('Results'!$E$11<=10,"Functioning-at-Risk","Functioning"))) | G11: 1 | H11: 0.1 | I11: 0.1 | J11: =IF(ISNUMBER('Results'!$E$11),'Results'!$E$11,0) | K11: =IF(ISNUMBER('Results'!$E$11),1,0) | L11: ='Metrics'!$B$67
A12: Hyporheic connectivity | B12: Hydraulics | C12: Hyporheic Exchange Indicators | D12: ='Metrics'!$C$79 | E12: ='Metrics'!$B$80 | F12: =IF(NOT(ISNUMBER('Results'!$E$12)),"Not assessed",IF('Results'!$E$12<=5,"Non-Functioning",IF('Results'!$E$12<=10,"Functioning-at-Risk","Functioning"))) | G12: 1 | H12: 0.1 | I12: 0.1 | J12: =IF(ISNUMBER('Results'!$E$12),'Results'!$E$12,0) | K12: =IF(ISNUMBER('Results'!$E$12),1,0) | L12: ='Metrics'!$B$78
A13: Channel evolution | B13: Geomorphology | C13: Channel Evolution Stage & Trends | D13: ='Metrics'!$C$91 | E13: ='Metrics'!$B$92 | F13: =IF(NOT(ISNUMBER('Results'!$E$13)),"Not assessed",IF('Results'!$E$13<=5,"Non-Functioning",IF('Results'!$E$13<=10,"Functioning-at-Risk","Functioning"))) | G13: 1 | H13: 0.1 | I13: 0.1 | J13: =IF(ISNUMBER('Results'!$E$13),'Results'!$E$13,0) | K13: =IF(ISNUMBER('Results'!$E$13),1,0) | L13: ='Metrics'!$B$90
A14: Channel and floodplain dynamics | B14: Geomorphology | C14: Bank Erosion & Armoring Condition | D14: ='Metrics'!$C$101 | E14: ='Metrics'!$B$102 | F14: =IF(NOT(ISNUMBER('Results'!$E$14)),"Not assessed",IF('Results'!$E$14<=5,"Non-Functioning",IF('Results'!$E$14<=10,"Functioning-at-Risk","Functioning"))) | G14: 1 | H14: 0.1 | I14: 0.1 | J14: =IF(ISNUMBER('Results'!$E$14),'Results'!$E$14,0) | K14: =IF(ISNUMBER('Results'!$E$14),1,0) | L14: ='Metrics'!$B$100
A15: Sediment continuity | B15: Geomorphology | C15: Sediment Supply Potential (watershed/banks) | D15: ='Metrics'!$C$113 | E15: ='Metrics'!$B$114 | F15: =IF(NOT(ISNUMBER('Results'!$E$15)),"Not assessed",IF('Results'!$E$15<=5,"Non-Functioning",IF('Results'!$E$15<=10,"Functioning-at-Risk","Functioning"))) | G15: 1 | H15: 0.1 | I15: 0.1 | J15: =IF(ISNUMBER('Results'!$E$15),'Results'!$E$15,0) | K15: =IF(ISNUMBER('Results'!$E$15),1,0) | L15: ='Metrics'!$B$112
A16: Bed composition and large wood | B16: Geomorphology | C16: Substrate Condition (grain size/embeddedness/fines/consolidation) | D16: ='Metrics'!$C$121 | E16: ='Metrics'!$B$122 | F16: =IF(NOT(ISNUMBER('Results'!$E$16)),"Not assessed",IF('Results'!$E$16<=5,"Non-Functioning",IF('Results'!$E$16<=10,"Functioning-at-Risk","Functioning"))) | G16: 1 | H16: 0.1 | I16: 0.1 | J16: =IF(ISNUMBER('Results'!$E$16),'Results'!$E$16,0) | K16: =IF(ISNUMBER('Results'!$E$16),1,0) | L16: ='Metrics'!$B$120
A17: Light & thermal regime | B17: Physicochemistry | C17: Stream Temperature | D17: ='Metrics'!$C$134 | E17: ='Metrics'!$B$135 | F17: =IF(NOT(ISNUMBER('Results'!$E$17)),"Not assessed",IF('Results'!$E$17<=5,"Non-Functioning",IF('Results'!$E$17<=10,"Functioning-at-Risk","Functioning"))) | G17: 0 | H17: 1 | I17: 0.1 | J17: =IF(ISNUMBER('Results'!$E$17),'Results'!$E$17,0) | K17: =IF(ISNUMBER('Results'!$E$17),1,0) | L17: ='Metrics'!$B$133
A18: Carbon processing | B18: Physicochemistry | C18: Detrital Processing (CPOM retention / shredders) | D18: ='Metrics'!$C$148 | E18: ='Metrics'!$B$149 | F18: =IF(NOT(ISNUMBER('Results'!$E$18)),"Not assessed",IF('Results'!$E$18<=5,"Non-Functioning",IF('Results'!$E$18<=10,"Functioning-at-Risk","Functioning"))) | G18: 0 | H18: 1 | I18: 0.1 | J18: =IF(ISNUMBER('Results'!$E$18),'Results'!$E$18,0) | K18: =IF(ISNUMBER('Results'!$E$18),1,0) | L18: ='Metrics'!$B$147
A19: Nutrient cycling | B19: Physicochemistry | C19: Nitrogen & Phosphorus Concentrations | D19: ='Metrics'!$C$158 | E19: ='Metrics'!$B$159 | F19: =IF(NOT(ISNUMBER('Results'!$E$19)),"Not assessed",IF('Results'!$E$19<=5,"Non-Functioning",IF('Results'!$E$19<=10,"Functioning-at-Risk","Functioning"))) | G19: 0.1 | H19: 1 | I19: 0.1 | J19: =IF(ISNUMBER('Results'!$E$19),'Results'!$E$19,0) | K19: =IF(ISNUMBER('Results'!$E$19),1,0) | L19: ='Metrics'!$B$157
A20: Water & soil quality | B20: Physicochemistry | C20: Regulatory Impairment Status (305b/303d/TMDL) | D20: ='Metrics'!$C$167 | E20: ='Metrics'!$B$168 | F20: =IF(NOT(ISNUMBER('Results'!$E$20)),"Not assessed",IF('Results'!$E$20<=5,"Non-Functioning",IF('Results'!$E$20<=10,"Functioning-at-Risk","Functioning"))) | G20: 0.1 | H20: 1 | I20: 0.1 | J20: =IF(ISNUMBER('Results'!$E$20),'Results'!$E$20,0) | K20: =IF(ISNUMBER('Results'!$E$20),1,0) | L20: ='Metrics'!$B$166
A21: Habitat provision | B21: Biology | C21: In-stream Habitat Complexity & Cover | D21: ='Metrics'!$C$178 | E21: ='Metrics'!$B$179 | F21: =IF(NOT(ISNUMBER('Results'!$E$21)),"Not assessed",IF('Results'!$E$21<=5,"Non-Functioning",IF('Results'!$E$21<=10,"Functioning-at-Risk","Functioning"))) | G21: 0 | H21: 0 | I21: 1 | J21: =IF(ISNUMBER('Results'!$E$21),'Results'!$E$21,0) | K21: =IF(ISNUMBER('Results'!$E$21),1,0) | L21: ='Metrics'!$B$177
A22: Population support | B22: Biology | C22: Biological Integrity (IBI / community condition) | D22: ='Metrics'!$C$189 | E22: ='Metrics'!$B$190 | F22: =IF(NOT(ISNUMBER('Results'!$E$22)),"Not assessed",IF('Results'!$E$22<=5,"Non-Functioning",IF('Results'!$E$22<=10,"Functioning-at-Risk","Functioning"))) | G22: 0.1 | H22: 0.1 | I22: 1 | J22: =IF(ISNUMBER('Results'!$E$22),'Results'!$E$22,0) | K22: =IF(ISNUMBER('Results'!$E$22),1,0) | L22: ='Metrics'!$B$188
A23: Community dynamics | B23: Biology | C23: Invasive / Non-native Species Presence | D23: ='Metrics'!$C$197 | E23: ='Metrics'!$B$198 | F23: =IF(NOT(ISNUMBER('Results'!$E$23)),"Not assessed",IF('Results'!$E$23<=5,"Non-Functioning",IF('Results'!$E$23<=10,"Functioning-at-Risk","Functioning"))) | G23: 0.1 | H23: 0.1 | I23: 1 | J23: =IF(ISNUMBER('Results'!$E$23),'Results'!$E$23,0) | K23: =IF(ISNUMBER('Results'!$E$23),1,0) | L23: ='Metrics'!$B$196
A24: Watershed connectivity | B24: Biology | C24: Fish Passage & Barrier Effects (longitudinal connectivity) | D24: ='Metrics'!$C$205 | E24: ='Metrics'!$B$206 | F24: =IF(NOT(ISNUMBER('Results'!$E$24)),"Not assessed",IF('Results'!$E$24<=5,"Non-Functioning",IF('Results'!$E$24<=10,"Functioning-at-Risk","Functioning"))) | G24: 0.1 | H24: 0 | I24: 1 | J24: =IF(ISNUMBER('Results'!$E$24),'Results'!$E$24,0) | K24: =IF(ISNUMBER('Results'!$E$24),1,0) | L24: ='Metrics'!$B$204
A26: Outcome | B26: Weighted score | C26: Weighted maximum | D26: Sub-index | E26: Displayed | F26: Class | G26: Coverage
A27: Physical | B27: =SUMPRODUCT('Results'!$J$5:$J$24,'Results'!$G$5:$G$24,'Results'!$K$5:$K$24) | C27: =SUMPRODUCT('Results'!$G$5:$G$24,'Results'!$K$5:$K$24)*15 | D27: =IF('Results'!$C$27=0,"",'Results'!$B$27/'Results'!$C$27) | E27: =IF('Results'!$D$27="","",ROUND('Results'!$D$27,2)) | F27: =IF('Results'!$E$27="","Not assessed",IF('Results'!$E$27<=0.39,"Non-Functioning",IF('Results'!$E$27<=0.69,"Functioning-at-Risk","Functioning"))) | G27: =IF(SUMPRODUCT('Results'!$G$5:$G$24)=0,"",SUMPRODUCT('Results'!$G$5:$G$24,'Results'!$K$5:$K$24)/SUMPRODUCT('Results'!$G$5:$G$24))
A28: Chemical | B28: =SUMPRODUCT('Results'!$J$5:$J$24,'Results'!$H$5:$H$24,'Results'!$K$5:$K$24) | C28: =SUMPRODUCT('Results'!$H$5:$H$24,'Results'!$K$5:$K$24)*15 | D28: =IF('Results'!$C$28=0,"",'Results'!$B$28/'Results'!$C$28) | E28: =IF('Results'!$D$28="","",ROUND('Results'!$D$28,2)) | F28: =IF('Results'!$E$28="","Not assessed",IF('Results'!$E$28<=0.39,"Non-Functioning",IF('Results'!$E$28<=0.69,"Functioning-at-Risk","Functioning"))) | G28: =IF(SUMPRODUCT('Results'!$H$5:$H$24)=0,"",SUMPRODUCT('Results'!$H$5:$H$24,'Results'!$K$5:$K$24)/SUMPRODUCT('Results'!$H$5:$H$24))
A29: Biological | B29: =SUMPRODUCT('Results'!$J$5:$J$24,'Results'!$I$5:$I$24,'Results'!$K$5:$K$24) | C29: =SUMPRODUCT('Results'!$I$5:$I$24,'Results'!$K$5:$K$24)*15 | D29: =IF('Results'!$C$29=0,"",'Results'!$B$29/'Results'!$C$29) | E29: =IF('Results'!$D$29="","",ROUND('Results'!$D$29,2)) | F29: =IF('Results'!$E$29="","Not assessed",IF('Results'!$E$29<=0.39,"Non-Functioning",IF('Results'!$E$29<=0.69,"Functioning-at-Risk","Functioning"))) | G29: =IF(SUMPRODUCT('Results'!$I$5:$I$24)=0,"",SUMPRODUCT('Results'!$I$5:$I$24,'Results'!$K$5:$K$24)/SUMPRODUCT('Results'!$I$5:$I$24))
A30: Ecosystem Condition Index | D30: =IF(COUNT('Results'!$D$27,'Results'!$D$28,'Results'!$D$29)=0,"",AVERAGE('Results'!$D$27,'Results'!$D$28,'Results'!$D$29)) | E30: =IF('Results'!$D$30="","",ROUND('Results'!$D$30,2)) | F30: =IF('Results'!$E$30="","Not assessed",IF('Results'!$E$30<=0.39,"Non-Functioning",IF('Results'!$E$30<=0.69,"Functioning-at-Risk","Functioning")))
A32: Coverage | B32: Value
A33: Functions rated | B33: =SUM('Results'!$K$5:$K$24)
A34: Functions selected | B34: 20
A35: Overall coverage | B35: ='Results'!$B$33/'Results'!$B$34
A36: Provisional (coverage below 0.70 overall or for an outcome) | B36: =IF(OR(AND(ISNUMBER('Results'!$B$35),'Results'!$B$35<0.7),AND(ISNUMBER('Results'!$G$27),'Results'!$G$27<0.7),AND(ISNUMBER('Results'!$G$28),'Results'!$G$28<0.7),AND(ISNUMBER('Results'!$G$29),'Results'!$G$29<0.7)),"yes","no")
A37: Status | B37: =IF('Results'!$B$35=1,"Complete screening coverage","Partial screening coverage")

Sheet Reference
A1: Reference tables generated from the EASI scoring definitions
A2: Read only. These values are the application's own catalog, reference curves, regional thresholds, lookups and weights. The Metrics sheet reads them by cell reference.
A4: Rating anchors and function scores
A5: Rating | B5: Index anchor | C5: Function score | D5: Score class
A6: Good | B6: 0.85 | C6: 13 | D6: Functioning
A7: Fair | B7: 0.545 | C7: 8 | D7: Functioning-at-Risk
A8: Poor | B8: 0.195 | C8: 3 | D8: Non-Functioning
A10: Condition classes
A11: Index at or below | B11: Class | C11: Function score at or below
A12: 0.39 | B12: Non-Functioning | C12: 5
A13: 0.69 | B13: Functioning-at-Risk | C13: 10
A14: 1 | B14: Functioning | C14: 15
A16: Fixed bands per input (informational; the Metrics formulas carry the same tests)
A17: Method | B17: Input | C17: Rating | D17: Min | E17: Min inclusive | F17: Max | G17: Max inclusive | H17: Label
A18: catchment-land-cover-pressure | B18: impervious | C18: Good | E18: FALSE | F18: 10 | G18: FALSE | H18: <10%
A19: catchment-land-cover-pressure | B19: impervious | C19: Fair | D19: 10 | E19: TRUE | F19: 25 | G19: TRUE | H19: 10-25%
A20: catchment-land-cover-pressure | B20: impervious | C20: Poor | D20: 25 | E20: FALSE | G20: FALSE | H20: >25%
A21: catchment-land-cover-pressure | B21: agriculture | C21: Good | E21: FALSE | F21: 30 | G21: FALSE | H21: <30%
A22: catchment-land-cover-pressure | B22: agriculture | C22: Fair | D22: 30 | E22: TRUE | F22: 50 | G22: TRUE | H22: 30-50%
A23: catchment-land-cover-pressure | B23: agriculture | C23: Poor | D23: 50 | E23: FALSE | G23: FALSE | H23: >50%
A24: watershed-wetland-extent | B24: (combined) | C24: Poor | E24: FALSE | F24: 1 | G24: FALSE | H24: <1%
A25: watershed-wetland-extent | B25: (combined) | C25: Fair | D25: 1 | E25: TRUE | F25: 5 | G25: TRUE | H25: 1-5%
A26: watershed-wetland-extent | B26: (combined) | C26: Good | D26: 5 | E26: FALSE | G26: FALSE | H26: >5%
A27: road-density-inflow-pressure | B27: (combined) | C27: Good | E27: FALSE | F27: 1 | G27: FALSE | H27: <1 km/km²
A28: road-density-inflow-pressure | B28: (combined) | C28: Fair | D28: 1 | E28: TRUE | F28: 3 | G28: FALSE | H28: 1-<3 km/km²
A29: road-density-inflow-pressure | B29: (combined) | C29: Poor | D29: 3 | E29: TRUE | G29: FALSE | H29: ≥3 km/km²
A30: degree-of-regulation | B30: (combined) | C30: Good | E30: FALSE | F30: 2 | G30: FALSE | H30: <2%
A31: degree-of-regulation | B31: (combined) | C31: Fair | D31: 2 | E31: TRUE | F31: 15 | G31: TRUE | H31: 2-15%
A32: degree-of-regulation | B32: (combined) | C32: Poor | D32: 15 | E32: FALSE | G32: FALSE | H32: >15%
A33: bank-height-ratio | B33: (combined) | C33: Good | E33: FALSE | F33: 1.3 | G33: TRUE | H33: ≤1.3
A34: bank-height-ratio | B34: (combined) | C34: Fair | D34: 1.3 | E34: FALSE | F34: 1.5 | G34: TRUE | H34: >1.3-≤1.5
A35: bank-height-ratio | B35: (combined) | C35: Poor | D35: 1.5 | E35: FALSE | G35: FALSE | H35: >1.5
A36: hyporheic-exchange-potential | B36: slope | C36: Poor | E36: FALSE | F36: 0.003 | G36: FALSE | H36: <0.003 m/m
A37: hyporheic-exchange-potential | B37: slope | C37: Fair | D37: 0.003 | E37: TRUE | F37: 0.006 | G37: FALSE | H37: 0.003-<0.006 m/m
A38: hyporheic-exchange-potential | B38: slope | C38: Good | D38: 0.006 | E38: TRUE | G38: FALSE | H38: ≥0.006 m/m
A39: hyporheic-exchange-potential | B39: sinuosity | C39: Poor | E39: FALSE | F39: 1.05 | G39: FALSE | H39: <1.05
A40: hyporheic-exchange-potential | B40: sinuosity | C40: Fair | D40: 1.05 | E40: TRUE | F40: 1.2 | G40: FALSE | H40: 1.05-<1.2
A41: hyporheic-exchange-potential | B41: sinuosity | C41: Good | D41: 1.2 | E41: TRUE | G41: FALSE | H41: ≥1.2
A42: channel-adjustment-susceptibility | B42: bhr | C42: Good | E42: FALSE | F42: 1.3 | G42: TRUE | H42: ≤1.3
A43: channel-adjustment-susceptibility | B43: bhr | C43: Fair | D43: 1.3 | E43: FALSE | F43: 1.5 | G43: TRUE | H43: >1.3-≤1.5
...

Sheet Metadata
A1: Metadata and version information
A2: Item | B2: Value
A3: Calculator version | B3: 1.1.0
A4: Calculator date | B4: 2026-09-17
A5: Scoring method digest | B5: b2e3033116e3
A6: Scoring identity | B6: alternative-2 (Alternative 2: NARS-9 references)
A7: Criteria set | B7: regional
A8: Reference curves | B8: 34 curves
A9: Catalog sha256 | B9: 78c1e2921198905ee6e53f18147e2aa33f9a6ffd87ff3e7a23844238b3fb73f3
A10: Curves sha256 | B10: a824e2c254dea1c22af62d2a6f5fd3d0862ff0574190111655aa5b34dbce4887
A11: NARS-9 geography sha256 | B11: f08b5be1ec4149da224f7fc5185c755f0d612d9115c53a172081c67009ab0300
A12: Rating anchors | B12: Good 0.85, Fair 0.545, Poor 0.195
A13: Function scores | B13: Good 13, Fair 8, Poor 3
... A22: Formula vocabulary | B22: IF AND OR NOT MIN MAX ROUND INDEX MATCH IFERROR ISNUMBER COUNT SUM SUMPRODUCT AVERAGE STDEV.P PRODUCT UPPER TRIM SUBSTITUTE LEN NA

Sheet ChartData
A1: Chart series (hidden). One column per class so each bar takes the class colour.
A2: Function | B2: Score | C2: Non-Functioning (0-5) | D2: Functioning At-Risk (6-10) | E2: Functioning (11-15)
A3: Catchment hydrology | B3: =IF('EASI Score'!$H$8="","",'EASI Score'!$H$8) | C3: =IF(ISNUMBER('ChartData'!$B$3),IF('ChartData'!$B$3<=5,'ChartData'!$B$3,NA()),NA()) | D3: =IF(ISNUMBER('ChartData'!$B$3),IF(AND('ChartData'!$B$3>5,'ChartData'!$B$3<=10),'ChartData'!$B$3,NA()),NA()) | E3: =IF(ISNUMBER('ChartData'!$B$3),IF('ChartData'!$B$3>10,'ChartData'!$B$3,NA()),NA())
A4: Surface water storage | B4: =IF('EASI Score'!$H$10="","",'EASI Score'!$H$10) | C4: =IF(ISNUMBER('ChartData'!$B$4),IF('ChartData'!$B$4<=5,'ChartData'!$B$4,NA()),NA()) | D4: =IF(ISNUMBER('ChartData'!$B$4),IF(AND('ChartData'!$B$4>5,'ChartData'!$B$4<=10),'ChartData'!$B$4,NA()),NA()) | E4: =IF(ISNUMBER('ChartData'!$B$4),IF('ChartData'!$B$4>10,'ChartData'!$B$4,NA()),NA())
A5: Reach inflow | B5: =IF('EASI Score'!$H$13="","",'EASI Score'!$H$13) | C5: =IF(ISNUMBER('ChartData'!$B$5),IF('ChartData'!$B$5<=5,'ChartData'!$B$5,NA()),NA()) | D5: =IF(ISNUMBER('ChartData'!$B$5),IF(AND('ChartData'!$B$5>5,'ChartData'!$B$5<=10),'ChartData'!$B$5,NA()),NA()) | E5: =IF(ISNUMBER('ChartData'!$B$5),IF('ChartData'!$B$5>10,'ChartData'!$B$5,NA()),NA())
A6: Streamflow regime | B6: =IF('EASI Score'!$H$14="","",'EASI Score'!$H$14) | C6: =IF(ISNUMBER('ChartData'!$B$6),IF('ChartData'!$B$6<=5,'ChartData'!$B$6,NA()),NA()) | D6: =IF(ISNUMBER('ChartData'!$B$6),IF(AND('ChartData'!$B$6>5,'ChartData'!$B$6<=10),'ChartData'!$B$6,NA()),NA()) | E6: =IF(ISNUMBER('ChartData'!$B$6),IF('ChartData'!$B$6>10,'ChartData'!$B$6,NA()),NA())
A7: Low flow and baseflow dynamics | B7: =IF('EASI Score'!$H$17="","",'EASI Score'!$H$17) | C7: =IF(ISNUMBER('ChartData'!$B$7),IF('ChartData'!$B$7<=5,'ChartData'!$B$7,NA()),NA()) | D7: =IF(ISNUMBER('ChartData'!$B$7),IF(AND('ChartData'!$B$7>5,'ChartData'!$B$7<=10),'ChartData'!$B$7,NA()),NA()) | E7: =IF(ISNUMBER('ChartData'!$B$7),IF('ChartData'!$B$7>10,'ChartData'!$B$7,NA()),NA())
A8: High flow dynamics | B8: =IF('EASI Score'!$H$18="","",'EASI Score'!$H$18) | C8: =IF(ISNUMBER('ChartData'!$B$8),IF('ChartData'!$B$8<=5,'ChartData'!$B$8,NA()),NA()) | D8: =IF(ISNUMBER('ChartData'!$B$8),IF(AND('ChartData'!$B$8>5,'ChartData'!$B$8<=10),'ChartData'!$B$8,NA()),NA()) | E8: =IF(ISNUMBER('ChartData'!$B$8),IF('ChartData'!$B$8>10,'ChartData'!$B$8,NA()),NA())
A9: Floodplain connectivity | B9: =IF('EASI Score'!$H$19="","",'EASI Score'!$H$19) | C9: =IF(ISNUMBER('ChartData'!$B$9),IF('ChartData'!$B$9<=5,'ChartData'!$B$9,NA()),NA()) | D9: =IF(ISNUMBER('ChartData'!$B$9),IF(AND('ChartData'!$B$9>5,'ChartData'!$B$9<=10),'ChartData'!$B$9,NA()),NA()) | E9: =IF(ISNUMBER('ChartData'!$B$9),IF('ChartData'!$B$9>10,'ChartData'!$B$9,NA()),NA())
A10: Hyporheic connectivity | B10: =IF('EASI Score'!$H$21="","",'EASI Score'!$H$21) | C10: =IF(ISNUMBER('ChartData'!$B$10),IF('ChartData'!$B$10<=5,'ChartData'!$B$10,NA()),NA()) | D10: =IF(ISNUMBER('ChartData'!$B$10),IF(AND('ChartData'!$B$10>5,'ChartData'!$B$10<=10),'ChartData'!$B$10,NA()),NA()) | E10: =IF(ISNUMBER('ChartData'!$B$10),IF('ChartData'!$B$10>10,'ChartData'!$B$10,NA()),NA())
A11: Channel evolution | B11: =IF('EASI Score'!$H$23="","",'EASI Score'!$H$23) | C11: =IF(ISNUMBER('ChartData'!$B$11),IF('ChartData'!$B$11<=5,'ChartData'!$B$11,NA()),NA()) | D11: =IF(ISNUMBER('ChartData'!$B$11),IF(AND('ChartData'!$B$11>5,'ChartData'!$B$11<=10),'ChartData'!$B$11,NA()),NA()) | E11: =IF(ISNUMBER('ChartData'!$B$11),IF('ChartData'!$B$11>10,'ChartData'!$B$11,NA()),NA())
A12: Channel and floodplain dynamics | B12: =IF('EASI Score'!$H$27="","",'EASI Score'!$H$27) | C12: =IF(ISNUMBER('ChartData'!$B$12),IF('ChartData'!$B$12<=5,'ChartData'!$B$12,NA()),NA()) | D12: =IF(ISNUMBER('ChartData'!$B$12),IF(AND('ChartData'!$B$12>5,'ChartData'!$B$12<=10),'ChartData'!$B$12,NA()),NA()) | E12: =IF(ISNUMBER('ChartData'!$B$12),IF('ChartData'!$B$12>10,'ChartData'!$B$12,NA()),NA())
A13: Sediment continuity | B13: =IF('EASI Score'!$H$30="","",'EASI Score'!$H$30) | C13: =IF(ISNUMBER('ChartData'!$B$13),IF('ChartData'!$B$13<=5,'ChartData'!$B$13,NA()),NA()) | D13: =IF(ISNUMBER('ChartData'!$B$13),IF(AND('ChartData'!$B$13>5,'ChartData'!$B$13<=10),'ChartData'!$B$13,NA()),NA()) | E13: =IF(ISNUMBER('ChartData'!$B$13),IF('ChartData'!$B$13>10,'ChartData'!$B$13,NA()),NA())
A14: Bed composition and large wood | B14: =IF('EASI Score'!$H$33="","",'EASI Score'!$H$33) | C14: =IF(ISNUMBER('ChartData'!$B$14),IF('ChartData'!$B$14<=5,'ChartData'!$B$14,NA()),NA()) | D14: =IF(ISNUMBER('ChartData'!$B$14),IF(AND('ChartData'!$B$14>5,'ChartData'!$B$14<=10),'ChartData'!$B$14,NA()),NA()) | E14: =IF(ISNUMBER('ChartData'!$B$14),IF('ChartData'!$B$14>10,'ChartData'!$B$14,NA()),NA())
A15: Light & thermal regime | B15: =IF('EASI Score'!$H$34="","",'EASI Score'!$H$34) | C15: =IF(ISNUMBER('ChartData'!$B$15),IF('ChartData'!$B$15<=5,'ChartData'!$B$15,NA()),NA()) | D15: =IF(ISNUMBER('ChartData'!$B$15),IF(AND('ChartData'!$B$15>5,'ChartData'!$B$15<=10),'ChartData'!$B$15,NA()),NA()) | E15: =IF(ISNUMBER('ChartData'!$B$15),IF('ChartData'!$B$15>10,'ChartData'!$B$15,NA()),NA())
A16: Carbon processing | B16: =IF('EASI Score'!$H$36="","",'EASI Score'!$H$36) | C16: =IF(ISNUMBER('ChartData'!$B$16),IF('ChartData'!$B$16<=5,'ChartData'!$B$16,NA()),NA()) | D16: =IF(ISNUMBER('ChartData'!$B$16),IF(AND('ChartData'!$B$16>5,'ChartData'!$B$16<=10),'ChartData'!$B$16,NA()),NA()) | E16: =IF(ISNUMBER('ChartData'!$B$16),IF('ChartData'!$B$16>10,'ChartData'!$B$16,NA()),NA())
A17: Nutrient cycling | B17: =IF('EASI Score'!$H$41="","",'EASI Score'!$H$41) | C17: =IF(ISNUMBER('ChartData'!$B$17),IF('ChartData'!$B$17<=5,'ChartData'!$B$17,NA()),NA()) | D17: =IF(ISNUMBER('ChartData'!$B$17),IF(AND('ChartData'!$B$17>5,'ChartData'!$B$17<=10),'ChartData'!$B$17,NA()),NA()) | E17: =IF(ISNUMBER('ChartData'!$B$17),IF('ChartData'!$B$17>10,'ChartData'!$B$17,NA()),NA())
A18: Water & soil quality | B18: =IF('EASI Score'!$H$45="","",'EASI Score'!$H$45) | C18: =IF(ISNUMBER('ChartData'!$B$18),IF('ChartData'!$B$18<=5,'ChartData'!$B$18,NA()),NA()) | D18: =IF(ISNUMBER('ChartData'!$B$18),IF(AND('ChartData'!$B$18>5,'ChartData'!$B$18<=10),'ChartData'!$B$18,NA()),NA()) | E18: =IF(ISNUMBER('ChartData'!$B$18),IF('ChartData'!$B$18>10,'ChartData'!$B$18,NA()),NA())
A19: Habitat provision | B19: =IF('EASI Score'!$H$48="","",'EASI Score'!$H$48) | C19: =IF(ISNUMBER('ChartData'!$B$19),IF('ChartData'!$B$19<=5,'ChartData'!$B$19,NA()),NA()) | D19: =IF(ISNUMBER('ChartData'!$B$19),IF(AND('ChartData'!$B$19>5,'ChartData'!$B$19<=10),'ChartData'!$B$19,NA()),NA()) | E19: =IF(ISNUMBER('ChartData'!$B$19),IF('ChartData'!$B$19>10,'ChartData'!$B$19,NA()),NA())
A20: Population support | B20: =IF('EASI Score'!$H$49="","",'EASI Score'!$H$49) | C20: =IF(ISNUMBER('ChartData'!$B$20),IF('ChartData'!$B$20<=5,'ChartData'!$B$20,NA()),NA()) | D20: =IF(ISNUMBER('ChartData'!$B$20),IF(AND('ChartData'!$B$20>5,'ChartData'!$B$20<=10),'ChartData'!$B$20,NA()),NA()) | E20: =IF(ISNUMBER('ChartData'!$B$20),IF('ChartData'!$B$20>10,'ChartData'!$B$20,NA()),NA())
A21: Community dynamics | B21: =IF('EASI Score'!$H$64="","",'EASI Score'!$H$64) | C21: =IF(ISNUMBER('ChartData'!$B$21),IF('ChartData'!$B$21<=5,'ChartData'!$B$21,NA()),NA()) | D21: =IF(ISNUMBER('ChartData'!$B$21),IF(AND('ChartData'!$B$21>5,'ChartData'!$B$21<=10),'ChartData'!$B$21,NA()),NA()) | E21: =IF(ISNUMBER('ChartData'!$B$21),IF('ChartData'!$B$21>10,'ChartData'!$B$21,NA()),NA())
A22: Watershed connectivity | B22: =IF('EASI Score'!$H$65="","",'EASI Score'!$H$65) | C22: =IF(ISNUMBER('ChartData'!$B$22),IF('ChartData'!$B$22<=5,'ChartData'!$B$22,NA()),NA()) | D22: =IF(ISNUMBER('ChartData'!$B$22),IF(AND('ChartData'!$B$22>5,'ChartData'!$B$22<=10),'ChartData'!$B$22,NA()),NA()) | E22: =IF(ISNUMBER('ChartData'!$B$22),IF('ChartData'!$B$22>10,'ChartData'!$B$22,NA()),NA())
A24: Outcome | B24: Score | C24: Non-Functioning (0.00-0.39) | D24: Functioning At-Risk (0.40-0.69) | E24: Functioning (0.70-1.00)
A25: Physical | B25: =IF('Results'!$E$27="","",'Results'!$E$27) | C25: =IF(ISNUMBER('ChartData'!$B$25),IF('ChartData'!$B$25<=0.39,'ChartData'!$B$25,NA()),NA()) | D25: =IF(ISNUMBER('ChartData'!$B$25),IF(AND('ChartData'!$B$25>0.39,'ChartData'!$B$25<=0.69),'ChartData'!$B$25,NA()),NA()) | E25: =IF(ISNUMBER('ChartData'!$B$25),IF('ChartData'!$B$25>0.69,'ChartData'!$B$25,NA()),NA())
A26: Chemical | B26: =IF('Results'!$E$28="","",'Results'!$E$28) | C26: =IF(ISNUMBER('ChartData'!$B$26),IF('ChartData'!$B$26<=0.39,'ChartData'!$B$26,NA()),NA()) | D26: =IF(ISNUMBER('ChartData'!$B$26),IF(AND('ChartData'!$B$26>0.39,'ChartData'!$B$26<=0.69),'ChartData'!$B$26,NA()),NA()) | E26: =IF(ISNUMBER('ChartData'!$B$26),IF('ChartData'!$B$26>0.69,'ChartData'!$B$26,NA()),NA())
A27: Biological | B27: =IF('Results'!$E$29="","",'Results'!$E$29) | C27: =IF(ISNUMBER('ChartData'!$B$27),IF('ChartData'!$B$27<=0.39,'ChartData'!$B$27,NA()),NA()) | D27: =IF(ISNUMBER('ChartData'!$B$27),IF(AND('ChartData'!$B$27>0.39,'ChartData'!$B$27<=0.69),'ChartData'!$B$27,NA()),NA()) | E27: =IF(ISNUMBER('ChartData'!$B$27),IF('ChartData'!$B$27>0.69,'ChartData'!$B$27,NA()),NA())
