Workbook
Name anchor_good: 'Reference'!$B$6
Name score_good: 'Reference'!$C$6
Name anchor_fair: 'Reference'!$B$7
Name score_fair: 'Reference'!$C$7
Name anchor_poor: 'Reference'!$B$8
Name score_poor: 'Reference'!$C$8
Name curve_keys: 'Reference'!$A$90:$A$123
Name curve_x1: 'Reference'!$G$90:$G$123
Name curve_y1: 'Reference'!$H$90:$H$123
Name curve_x2: 'Reference'!$I$90:$I$123
Name curve_y2: 'Reference'!$J$90:$J$123
Name curve_x3: 'Reference'!$K$90:$K$123
Name curve_y3: 'Reference'!$L$90:$L$123
Name curve_x4: 'Reference'!$M$90:$M$123
Name curve_y4: 'Reference'!$N$90:$N$123
Name curve_x5: 'Reference'!$O$90:$O$123
Name curve_y5: 'Reference'!$P$90:$P$123
Name curve_x39: 'Reference'!$Q$90:$Q$123
Name curve_x69: 'Reference'!$R$90:$R$123
Name nutrient_regions: 'Reference'!$A$127:$A$135
Name nutrient_tn_gf: 'Reference'!$B$127:$B$135
Name nutrient_tn_fp: 'Reference'!$C$127:$C$135
Name nutrient_tp_gf: 'Reference'!$D$127:$D$135
Name nutrient_tp_fp: 'Reference'!$E$127:$E$135
Name attains_keys: 'Reference'!$A$139:$A$145
Name attains_ratings: 'Reference'!$B$139:$B$145
Name site_name: 'Inputs'!$C$5
Name site_assessor: 'Inputs'!$C$6
Name site_date: 'Inputs'!$C$7
Name site_comid: 'Inputs'!$C$8
Name site_coords: 'Inputs'!$C$9
Name site_notes: 'Inputs'!$C$10
Name ctx_region: 'Inputs'!$C$14
Name ctx_fcode: 'Inputs'!$C$15
Name ctx_slope_override: 'Inputs'!$C$16
Name calc_slope_class: 'Inputs'!$C$17
Name in_impervious: 'Inputs'!$C$22
Name in_agriculture: 'Inputs'!$C$23
Name in_woodyWetland: 'Inputs'!$C$24
Name in_herbaceousWetland: 'Inputs'!$C$25
Name in_roadDensity: 'Inputs'!$C$26
Name in_kFactor: 'Inputs'!$C$27
Name in_storage: 'Inputs'!$C$29
Name in_runoff: 'Inputs'!$C$30
Name in_flowCv: 'Inputs'!$C$31
Name in_woodyRiparian: 'Inputs'!$C$33
Name in_forest: 'Inputs'!$C$34
Name in_shrub: 'Inputs'!$C$35
Name in_grassland: 'Inputs'!$C$36
Name in_wetland: 'Inputs'!$C$37
Name in_bhr: 'Inputs'!$C$39
Name in_er: 'Inputs'!$C$40
Name in_slope: 'Inputs'!$C$41
Name in_sinuosity: 'Inputs'!$C$42
Name in_tn: 'Inputs'!$C$44
Name in_tp: 'Inputs'!$C$45
Name in_category: 'Inputs'!$C$46
Name in_chemCatchment: 'Inputs'!$C$48
Name in_chemWatershed: 'Inputs'!$C$49
Name in_prGBmmi: 'Inputs'!$C$50

Sheet Instructions
A1: EASI calculator
A2: Ecosystem Assessment Screening Index (EASI), Stream Tiered Assessment Framework (STAF)
A3: Calculator version 1.0.0 (2026-09-16). Scoring method digest b2e3033116e3 (Alternative 2: NARS-9 references). See the Metadata sheet.
A5: What it is
A6: An offline implementation of the EASI screening methodology. The web application retrieves the desktop evidence for a stream reach and scores it; this workbook scores the same evidence when you enter it by hand. Same inputs give the same ratings, function scores, sub-indices and Ecosystem Condition Index, because every threshold, curve, lookup and weight here is generated from the application's own scoring definitions.
A8: How to use it
A9: 1. On the Inputs sheet, fill the site block, then the context: the NARS-9 ecoregion code of the site, the NHD feature code and, if needed, a slope class override.
A10: 2. Enter each desktop quantity once (yellow cells). The Source column names the StreamCat field or the EASI report item each value comes from. Leave a cell blank when the evidence is unavailable. Never enter zero for unknown: a zero is evidence.
A11: 3. Optional: enter the twelve EROM monthly flows to compute the monthly flow variability, and the observed channel class and bank percentages if you have field observations.
A12: 4. Read the Metrics sheet for each function's route, rating and score, and the Results sheet for the sub-indices, the ECI and the coverage.
A14: Colour key
A15: Yellow: required entry. Blue: optional context or override. Grey: computed. All computed cells are locked; the sheets are protected without a secret password (it is 'easi') so that a mistaken edit is unlikely, not impossible.
... A24: EASI is a screening-level desktop estimate, not a field-validated assessment. The reference curves express regional expectations derived from least-disturbed reaches and several proxies remain unvalidated; the technical report states each metric's limitations.

Sheet Inputs
A1: EASI calculator: inputs
A2: Yellow cells are required entries, blue cells are optional context or overrides, grey cells are computed. Enter each quantity once; the Metrics sheet reuses it wherever the method needs it. Leave a cell blank when the evidence is unavailable. Never enter zero for unknown.
A4: Site
A5: Site name
A6: Assessor
A7: Date
A8: NHDPlus V2 COMID
A9: Latitude, longitude
A10: Notes
A12: Context
A13: Setting | B13: Key | C13: Value | F13: Note
A14: NARS-9 aggregate ecoregion of the site | B14: ctx_region | F14: Code of the EPA NARS nine-region ecoregion containing the site (CPL, NAP, NPL, SAP, SPL, TPL, UMW, WMT, XER). It selects the regional reference curves and the nutrient thresholds. Leave blank if unknown: the national curves apply and nutrients fall back to the CHEM index.
A15: NHD feature code (FCODE) of the reach | B15: ctx_fcode | F15: From NHDPlus V2. Codes 33600, 33601 and 33603 are canals and ditches, which rate Channel evolution Poor.
A16: Slope class override | B16: ctx_slope_override | F16: Normally derived from the channel slope below. Set only to force a class (lt_0.5, 0.5_to_2, ge_2 or national).
A17: Slope class used for the entrenchment curves (derived) | B17: calc_slope_class | C17: =IF('Inputs'!$C$16<>"",'Inputs'!$C$16,IF(NOT(ISNUMBER('Inputs'!$C$41)),"national",IF('Inputs'!$C$41<0,"national",IF('Inputs'!$C$41<0.005,"lt_0.5",IF('Inputs'!$C$41<0.02,"0.5_to_2","ge_2"))))) | F17: lt_0.5 below 0.005 m/m, 0.5_to_2 to below 0.02, ge_2 at or above 0.02, national when the slope is blank or negative. The override above wins when set.
A19: Desktop quantities
A20: Quantity | B20: Key | C20: Value | D20: Units | E20: Source | F20: Note
A21: Watershed land cover (StreamCat, watershed area of interest)
A22: Impervious cover of the watershed | B22: impervious | D22: % | E22: StreamCat pctimp2019ws | F22: Used by Catchment hydrology and Light and thermal regime.
A23: Agricultural cover of the watershed (crop plus hay and pasture) | B23: agriculture | D23: % | E23: StreamCat pctcrop2019ws + pcthay2019ws (the application rounds the sum to two decimals) | F23: Used by Catchment hydrology, Sediment continuity and Bed composition.
A24: Woody wetland cover of the watershed | B24: woodyWetland | D24: % | E24: StreamCat pctwdwet2019ws
A25: Herbaceous wetland cover of the watershed | B25: herbaceousWetland | D25: % | E25: StreamCat pcthbwet2019ws
A26: Road density of the watershed | B26: roadDensity | D26: km/km2 | E26: StreamCat rddensws | F26: Used by Reach inflow and Sediment continuity.
A27: Soil erodibility K factor of the watershed | B27: kFactor | E27: StreamCat kffactws
A28: Flow regulation and flow variability
A29: Normalized dam storage upstream | B29: storage | D29: m3/km2 | E29: StreamCat damnrmstorws | F29: A true zero is valid evidence. Leave blank when unknown.
A30: Mean annual runoff of the watershed | B30: runoff | D30: mm | E30: StreamCat runoffws | F30: Must be positive for the degree of regulation.
A31: Monthly flow variability (coefficient of variation of the twelve EROM mean monthly flows) | B31: flowCv | D31: ratio | E31: NHDPlus V2 EROM QE_01 to QE_12: population standard deviation over the mean, rounded to six decimals | F31: Enter the value from the EASI report, or compute it below from the twelve monthly flows.
A32: Riparian corridor (StreamCat, 100 m watershed corridor)
A33: Woody riparian cover in the 100 m corridor (forest, shrub and woody wetland) | B33: woodyRiparian | D33: % | E33: StreamCat conifer + deciduous + mixed forest + shrub + woody wetland at wsrp100 (rounded to one decimal) | F33: Used by Light and thermal regime and Habitat provision.
A34: Forest cover in the corridor | B34: forest | D34: % | E34: StreamCat pctconif + pctdecid + pctmxfst at wsrp100
A35: Shrub cover in the corridor | B35: shrub | D35: % | E35: StreamCat pctshrb2019wsrp100
A36: Grassland cover in the corridor | B36: grassland | D36: % | E36: StreamCat pctgrs2019wsrp100
A37: Wetland cover in the corridor (woody and herbaceous) | B37: wetland | D37: % | E37: StreamCat pctwdwet + pcthbwet at wsrp100
A38: Channel geometry (3DEP cross-sections and NHDPlus attributes)
A39: Bank-height ratio (low-bank height over maximum bankfull depth), reach median | B39: bhr | D39: ratio | E39: EASI report cross-section block or a field survey | F39: Used by High flow dynamics, Channel evolution and Channel and floodplain dynamics.
A40: Entrenchment ratio (flood-prone width over bankfull width), reach median | B40: er | D40: ratio | E40: EASI report cross-section block or a field survey | F40: Used by Floodplain connectivity and Channel evolution.
A41: Channel slope | B41: slope | D41: m/m | E41: NHDPlus V2 VAA slope | F41: Used by Hyporheic connectivity and to pick the entrenchment slope class.
A42: Reach sinuosity | B42: sinuosity | D42: ratio | E42: reach geometry (channel length over straight-line length)
A43: Water quality (Water Quality Portal and ATTAINS)
...

Sheet Metrics
A1: EASI calculator: metric scoring
A2: Read only. One block per function: the inputs it reads, the route that applied, the rating, the index anchor and the function score. Ratings follow the application's catalog exactly.
A4: 1. Catchment hydrology | B4: Catchment hydrology (land-cover pressure) (catchment-land-cover-pressure, worst_index)
A5: Item | B5: Value | C5: Rating | D5: Index | E5: Note
A6: Watershed impervious cover | B6: =IF('Inputs'!$C$22="","",'Inputs'!$C$22) | C6: =IF(NOT(ISNUMBER('Inputs'!$C$22)),"",IF('Inputs'!$C$22<10,"Good",IF(AND('Inputs'!$C$22>=10,'Inputs'!$C$22<=25),"Fair",IF('Inputs'!$C$22>25,"Poor","")))) | D6: =IF('Metrics'!$C$6="Good",'Reference'!$B$6,IF('Metrics'!$C$6="Fair",'Reference'!$B$7,IF('Metrics'!$C$6="Poor",'Reference'!$B$8,"")))
A7: Watershed agricultural cover | B7: =IF('Inputs'!$C$23="","",'Inputs'!$C$23) | C7: =IF(NOT(ISNUMBER('Inputs'!$C$23)),"",IF('Inputs'!$C$23<30,"Good",IF(AND('Inputs'!$C$23>=30,'Inputs'!$C$23<=50),"Fair",IF('Inputs'!$C$23>50,"Poor","")))) | D7: =IF('Metrics'!$C$7="Good",'Reference'!$B$6,IF('Metrics'!$C$7="Fair",'Reference'!$B$7,IF('Metrics'!$C$7="Poor",'Reference'!$B$8,"")))
A8: Governing input | B8: =IF('Metrics'!$B$9="","",INDEX('Metrics'!$A$6:$A$7,MATCH('Metrics'!$B$9,'Metrics'!$D$6:$D$7,0)))
A9: Combined rating index (the more limiting input) | B9: =IF(COUNT('Metrics'!$D$6:$D$7)=0,"",MIN('Metrics'!$D$6:$D$7))
A10: Route that applied | B10: ="automatic method"
A11: Function rating | C11: =IF(NOT(ISNUMBER('Metrics'!$B$9)),"",IF('Metrics'!$B$9='Reference'!$B$6,"Good",IF('Metrics'!$B$9='Reference'!$B$7,"Fair",IF('Metrics'!$B$9='Reference'!$B$8,"Poor","")))) | D11: =IF('Metrics'!$C$11="Good",'Reference'!$B$6,IF('Metrics'!$C$11="Fair",'Reference'!$B$7,IF('Metrics'!$C$11="Poor",'Reference'!$B$8,""))) | E11: Partial rating allowed when one input is missing.
A12: Function score (0 to 15) | B12: =IF('Metrics'!$C$11="Good",'Reference'!$C$6,IF('Metrics'!$C$11="Fair",'Reference'!$C$7,IF('Metrics'!$C$11="Poor",'Reference'!$C$8,"")))
A13: Status | B13: =IF(COUNT('Metrics'!$D$6:$D$7)=0,"not rated",IF(COUNT('Metrics'!$D$6:$D$7)<2,"partial","complete"))
A15: 2. Surface water storage | B15: Wetland extent (watershed-wetland-extent, sum_capped)
A16: Item | B16: Value | C16: Rating | D16: Index | E16: Note
A17: Woody wetland cover | B17: =IF('Inputs'!$C$24="","",'Inputs'!$C$24)
A18: Herbaceous wetland cover | B18: =IF('Inputs'!$C$25="","",'Inputs'!$C$25)
A19: Combined value (sum capped at 100) | B19: =IF(AND(ISNUMBER('Inputs'!$C$24),ISNUMBER('Inputs'!$C$25)),ROUND(MIN('Inputs'!$C$24+'Inputs'!$C$25,100),12),"")
A20: Route that applied | B20: ="automatic method"
A21: Function rating | C21: =IF(NOT(ISNUMBER('Metrics'!$B$19)),"",IF('Metrics'!$B$19<1,"Poor",IF(AND('Metrics'!$B$19>=1,'Metrics'!$B$19<=5),"Fair",IF('Metrics'!$B$19>5,"Good","")))) | D21: =IF('Metrics'!$C$21="Good",'Reference'!$B$6,IF('Metrics'!$C$21="Fair",'Reference'!$B$7,IF('Metrics'!$C$21="Poor",'Reference'!$B$8,""))) | E21: All classes are required. A missing class is unknown, not zero.
A22: Function score (0 to 15) | B22: =IF('Metrics'!$C$21="Good",'Reference'!$C$6,IF('Metrics'!$C$21="Fair",'Reference'!$C$7,IF('Metrics'!$C$21="Poor",'Reference'!$C$8,"")))
A23: Status | B23: =IF('Metrics'!$C$21="","not rated","complete")
A25: 3. Reach inflow | B25: Road-density proxy for concentrated inflow pressure (road-density-inflow-pressure, threshold)
A26: Item | B26: Value | C26: Rating | D26: Index | E26: Note
A27: Watershed road density | B27: =IF('Inputs'!$C$26="","",'Inputs'!$C$26)
A28: Route that applied | B28: ="automatic method"
A29: Function rating | C29: =IF(NOT(ISNUMBER('Inputs'!$C$26)),"",IF('Inputs'!$C$26<1,"Good",IF(AND('Inputs'!$C$26>=1,'Inputs'!$C$26<3),"Fair",IF('Inputs'!$C$26>=3,"Poor","")))) | D29: =IF('Metrics'!$C$29="Good",'Reference'!$B$6,IF('Metrics'!$C$29="Fair",'Reference'!$B$7,IF('Metrics'!$C$29="Poor",'Reference'!$B$8,"")))
A30: Function score (0 to 15) | B30: =IF('Metrics'!$C$29="Good",'Reference'!$C$6,IF('Metrics'!$C$29="Fair",'Reference'!$C$7,IF('Metrics'!$C$29="Poor",'Reference'!$C$8,"")))
A31: Status | B31: =IF('Metrics'!$C$29="","not rated","complete")
A33: 4. Streamflow regime | B33: Flow alteration (degree of regulation) (degree-of-regulation, ratio)
A34: Item | B34: Value | C34: Rating | D34: Index | E34: Note
A35: Upstream normalized storage | B35: =IF('Inputs'!$C$29="","",'Inputs'!$C$29)
A36: Annual runoff | B36: =IF('Inputs'!$C$30="","",'Inputs'!$C$30)
A37: Degree of regulation (%) | B37: =IF(AND(ISNUMBER('Inputs'!$C$29),ISNUMBER('Inputs'!$C$30),'Inputs'!$C$30<>0,'Inputs'!$C$30>0),ROUND((100*'Inputs'!$C$29)/(1000*'Inputs'!$C$30),12),"")
A38: Route that applied | B38: ="automatic method"
A39: Function rating | C39: =IF(NOT(ISNUMBER('Metrics'!$B$37)),"",IF('Metrics'!$B$37<2,"Good",IF(AND('Metrics'!$B$37>=2,'Metrics'!$B$37<=15),"Fair",IF('Metrics'!$B$37>15,"Poor","")))) | D39: =IF('Metrics'!$C$39="Good",'Reference'!$B$6,IF('Metrics'!$C$39="Fair",'Reference'!$B$7,IF('Metrics'!$C$39="Poor",'Reference'!$B$8,"")))
A40: Function score (0 to 15) | B40: =IF('Metrics'!$C$39="Good",'Reference'!$C$6,IF('Metrics'!$C$39="Fair",'Reference'!$C$7,IF('Metrics'!$C$39="Poor",'Reference'!$C$8,"")))
A41: Status | B41: =IF('Metrics'!$C$39="","not rated","complete")
A43: 5. Low flow and baseflow dynamics | B43: Low-flow condition (erom-flow-variability, threshold)
A44: Item | B44: Value | C44: Rating | D44: Index | E44: Note
A45: Monthly flow variability | B45: =IF('Inputs'!$C$31="","",'Inputs'!$C$31)
...

Sheet Results
A1: EASI calculator: results
A2: Read only. Function scores, outcome sub-indices and the Ecosystem Condition Index, computed with the STAF rollup: unrated functions leave both the numerator and the denominator.
A4: Function | B4: Discipline | C4: Metric | D4: Rating | E4: Score | F4: Class | G4: Physical | H4: Chemical | I4: Biological | J4: Score or 0 | K4: Rated | L4: Route
A5: Catchment hydrology | B5: Hydrology | C5: Watershed Land-Cover Pressure | D5: ='Metrics'!$C$11 | E5: ='Metrics'!$B$12 | F5: =IF(NOT(ISNUMBER('Results'!$E$5)),"Not assessed",IF('Results'!$E$5<=5,"Non-Functioning",IF('Results'!$E$5<=10,"Functioning-at-Risk","Functioning"))) | G5: 1 | H5: 0.1 | I5: 0.1 | J5: =IF(ISNUMBER('Results'!$E$5),'Results'!$E$5,0) | K5: =IF(ISNUMBER('Results'!$E$5),1,0) | L5: ='Metrics'!$B$10
A6: Surface water storage | B6: Hydrology | C6: Percent Wetlands in Watershed | D6: ='Metrics'!$C$21 | E6: ='Metrics'!$B$22 | F6: =IF(NOT(ISNUMBER('Results'!$E$6)),"Not assessed",IF('Results'!$E$6<=5,"Non-Functioning",IF('Results'!$E$6<=10,"Functioning-at-Risk","Functioning"))) | G6: 1 | H6: 0.1 | I6: 0.1 | J6: =IF(ISNUMBER('Results'!$E$6),'Results'!$E$6,0) | K6: =IF(ISNUMBER('Results'!$E$6),1,0) | L6: ='Metrics'!$B$20
A7: Reach inflow | B7: Hydrology | C7: Concentrated Runoff / Stormwater Inputs | D7: ='Metrics'!$C$29 | E7: ='Metrics'!$B$30 | F7: =IF(NOT(ISNUMBER('Results'!$E$7)),"Not assessed",IF('Results'!$E$7<=5,"Non-Functioning",IF('Results'!$E$7<=10,"Functioning-at-Risk","Functioning"))) | G7: 1 | H7: 0.1 | I7: 0.1 | J7: =IF(ISNUMBER('Results'!$E$7),'Results'!$E$7,0) | K7: =IF(ISNUMBER('Results'!$E$7),1,0) | L7: ='Metrics'!$B$28
A8: Streamflow regime | B8: Hydrology | C8: Flow Alteration (Regulation / Water Use) | D8: ='Metrics'!$C$39 | E8: ='Metrics'!$B$40 | F8: =IF(NOT(ISNUMBER('Results'!$E$8)),"Not assessed",IF('Results'!$E$8<=5,"Non-Functioning",IF('Results'!$E$8<=10,"Functioning-at-Risk","Functioning"))) | G8: 1 | H8: 0.1 | I8: 0.1 | J8: =IF(ISNUMBER('Results'!$E$8),'Results'!$E$8,0) | K8: =IF(ISNUMBER('Results'!$E$8),1,0) | L8: ='Metrics'!$B$38
A9: Low flow and baseflow dynamics | B9: Hydraulics | C9: Low-flow Wetted Connectivity | D9: ='Metrics'!$C$50 | E9: ='Metrics'!$B$51 | F9: =IF(NOT(ISNUMBER('Results'!$E$9)),"Not assessed",IF('Results'!$E$9<=5,"Non-Functioning",IF('Results'!$E$9<=10,"Functioning-at-Risk","Functioning"))) | G9: 1 | H9: 0.1 | I9: 0.1 | J9: =IF(ISNUMBER('Results'!$E$9),'Results'!$E$9,0) | K9: =IF(ISNUMBER('Results'!$E$9),1,0) | L9: ='Metrics'!$B$49
A10: High flow dynamics | B10: Hydraulics | C10: Floodplain Engagement Frequency (bankfull recurrence) | D10: ='Metrics'!$C$58 | E10: ='Metrics'!$B$59 | F10: =IF(NOT(ISNUMBER('Results'!$E$10)),"Not assessed",IF('Results'!$E$10<=5,"Non-Functioning",IF('Results'!$E$10<=10,"Functioning-at-Risk","Functioning"))) | G10: 1 | H10: 0.1 | I10: 0.1 | J10: =IF(ISNUMBER('Results'!$E$10),'Results'!$E$10,0) | K10: =IF(ISNUMBER('Results'!$E$10),1,0) | L10: ='Metrics'!$B$57
A11: Floodplain connectivity | B11: Hydraulics | C11: Floodplain Access / Entrenchment | D11: ='Metrics'!$C$68 | E11: ='Metrics'!$B$69 | F11: =IF(NOT(ISNUMBER('Results'!$E$11)),"Not assessed",IF('Results'!$E$11<=5,"Non-Functioning",IF('Results'!$E$11<=10,"Functioning-at-Risk","Functioning"))) | G11: 1 | H11: 0.1 | I11: 0.1 | J11: =IF(ISNUMBER('Results'!$E$11),'Results'!$E$11,0) | K11: =IF(ISNUMBER('Results'!$E$11),1,0) | L11: ='Metrics'!$B$67
A12: Hyporheic connectivity | B12: Hydraulics | C12: Hyporheic Exchange Indicators | D12: ='Metrics'!$C$79 | E12: ='Metrics'!$B$80 | F12: =IF(NOT(ISNUMBER('Results'!$E$12)),"Not assessed",IF('Results'!$E$12<=5,"Non-Functioning",IF('Results'!$E$12<=10,"Functioning-at-Risk","Functioning"))) | G12: 1 | H12: 0.1 | I12: 0.1 | J12: =IF(ISNUMBER('Results'!$E$12),'Results'!$E$12,0) | K12: =IF(ISNUMBER('Results'!$E$12),1,0) | L12: ='Metrics'!$B$78
A13: Channel evolution | B13: Geomorphology | C13: Channel Evolution Stage & Trends | D13: ='Metrics'!$C$91 | E13: ='Metrics'!$B$92 | F13: =IF(NOT(ISNUMBER('Results'!$E$13)),"Not assessed",IF('Results'!$E$13<=5,"Non-Functioning",IF('Results'!$E$13<=10,"Functioning-at-Risk","Functioning"))) | G13: 1 | H13: 0.1 | I13: 0.1 | J13: =IF(ISNUMBER('Results'!$E$13),'Results'!$E$13,0) | K13: =IF(ISNUMBER('Results'!$E$13),1,0) | L13: ='Metrics'!$B$90
A14: Channel and floodplain dynamics | B14: Geomorphology | C14: Bank Erosion & Armoring Condition | D14: ='Metrics'!$C$101 | E14: ='Metrics'!$B$102 | F14: =IF(NOT(ISNUMBER('Results'!$E$14)),"Not assessed",IF('Results'!$E$14<=5,"Non-Functioning",IF('Results'!$E$14<=10,"Functioning-at-Risk","Functioning"))) | G14: 1 | H14: 0.1 | I14: 0.1 | J14: =IF(ISNUMBER('Results'!$E$14),'Results'!$E$14,0) | K14: =IF(ISNUMBER('Results'!$E$14),1,0) | L14: ='Metrics'!$B$100
A15: Sediment continuity | B15: Geomorphology | C15: Sediment Supply Potential (watershed/banks) | D15: ='Metrics'!$C$113 | E15: ='Metrics'!$B$114 | F15: =IF(NOT(ISNUMBER('Results'!$E$15)),"Not assessed",IF('Results'!$E$15<=5,"Non-Functioning",IF('Results'!$E$15<=10,"Functioning-at-Risk","Functioning"))) | G15: 1 | H15: 0.1 | I15: 0.1 | J15: =IF(ISNUMBER('Results'!$E$15),'Results'!$E$15,0) | K15: =IF(ISNUMBER('Results'!$E$15),1,0) | L15: ='Metrics'!$B$112
A16: Bed composition and large wood | B16: Geomorphology | C16: Substrate Condition (grain size/embeddedness/fines/consolidation) | D16: ='Metrics'!$C$121 | E16: ='Metrics'!$B$122 | F16: =IF(NOT(ISNUMBER('Results'!$E$16)),"Not assessed",IF('Results'!$E$16<=5,"Non-Functioning",IF('Results'!$E$16<=10,"Functioning-at-Risk","Functioning"))) | G16: 1 | H16: 0.1 | I16: 0.1 | J16: =IF(ISNUMBER('Results'!$E$16),'Results'!$E$16,0) | K16: =IF(ISNUMBER('Results'!$E$16),1,0) | L16: ='Metrics'!$B$120
A17: Light & thermal regime | B17: Physicochemistry | C17: Stream Temperature | D17: ='Metrics'!$C$134 | E17: ='Metrics'!$B$135 | F17: =IF(NOT(ISNUMBER('Results'!$E$17)),"Not assessed",IF('Results'!$E$17<=5,"Non-Functioning",IF('Results'!$E$17<=10,"Functioning-at-Risk","Functioning"))) | G17: 0 | H17: 1 | I17: 0.1 | J17: =IF(ISNUMBER('Results'!$E$17),'Results'!$E$17,0) | K17: =IF(ISNUMBER('Results'!$E$17),1,0) | L17: ='Metrics'!$B$133
A18: Carbon processing | B18: Physicochemistry | C18: Detrital Processing (CPOM retention / shredders) | D18: ='Metrics'!$C$148 | E18: ='Metrics'!$B$149 | F18: =IF(NOT(ISNUMBER('Results'!$E$18)),"Not assessed",IF('Results'!$E$18<=5,"Non-Functioning",IF('Results'!$E$18<=10,"Functioning-at-Risk","Functioning"))) | G18: 0 | H18: 1 | I18: 0.1 | J18: =IF(ISNUMBER('Results'!$E$18),'Results'!$E$18,0) | K18: =IF(ISNUMBER('Results'!$E$18),1,0) | L18: ='Metrics'!$B$147
A19: Nutrient cycling | B19: Physicochemistry | C19: Nitrogen & Phosphorus Concentrations | D19: ='Metrics'!$C$158 | E19: ='Metrics'!$B$159 | F19: =IF(NOT(ISNUMBER('Results'!$E$19)),"Not assessed",IF('Results'!$E$19<=5,"Non-Functioning",IF('Results'!$E$19<=10,"Functioning-at-Risk","Functioning"))) | G19: 0.1 | H19: 1 | I19: 0.1 | J19: =IF(ISNUMBER('Results'!$E$19),'Results'!$E$19,0) | K19: =IF(ISNUMBER('Results'!$E$19),1,0) | L19: ='Metrics'!$B$157
A20: Water & soil quality | B20: Physicochemistry | C20: Regulatory Impairment Status (305b/303d/TMDL) | D20: ='Metrics'!$C$167 | E20: ='Metrics'!$B$168 | F20: =IF(NOT(ISNUMBER('Results'!$E$20)),"Not assessed",IF('Results'!$E$20<=5,"Non-Functioning",IF('Results'!$E$20<=10,"Functioning-at-Risk","Functioning"))) | G20: 0.1 | H20: 1 | I20: 0.1 | J20: =IF(ISNUMBER('Results'!$E$20),'Results'!$E$20,0) | K20: =IF(ISNUMBER('Results'!$E$20),1,0) | L20: ='Metrics'!$B$166
A21: Habitat provision | B21: Biology | C21: In-stream Habitat Complexity & Cover | D21: ='Metrics'!$C$178 | E21: ='Metrics'!$B$179 | F21: =IF(NOT(ISNUMBER('Results'!$E$21)),"Not assessed",IF('Results'!$E$21<=5,"Non-Functioning",IF('Results'!$E$21<=10,"Functioning-at-Risk","Functioning"))) | G21: 0 | H21: 0 | I21: 1 | J21: =IF(ISNUMBER('Results'!$E$21),'Results'!$E$21,0) | K21: =IF(ISNUMBER('Results'!$E$21),1,0) | L21: ='Metrics'!$B$177
A22: Population support | B22: Biology | C22: Biological Integrity (IBI / community condition) | D22: ='Metrics'!$C$189 | E22: ='Metrics'!$B$190 | F22: =IF(NOT(ISNUMBER('Results'!$E$22)),"Not assessed",IF('Results'!$E$22<=5,"Non-Functioning",IF('Results'!$E$22<=10,"Functioning-at-Risk","Functioning"))) | G22: 0.1 | H22: 0.1 | I22: 1 | J22: =IF(ISNUMBER('Results'!$E$22),'Results'!$E$22,0) | K22: =IF(ISNUMBER('Results'!$E$22),1,0) | L22: ='Metrics'!$B$188
A23: Community dynamics | B23: Biology | C23: Invasive / Non-native Species Presence | D23: ='Metrics'!$C$197 | E23: ='Metrics'!$B$198 | F23: =IF(NOT(ISNUMBER('Results'!$E$23)),"Not assessed",IF('Results'!$E$23<=5,"Non-Functioning",IF('Results'!$E$23<=10,"Functioning-at-Risk","Functioning"))) | G23: 0.1 | H23: 0.1 | I23: 1 | J23: =IF(ISNUMBER('Results'!$E$23),'Results'!$E$23,0) | K23: =IF(ISNUMBER('Results'!$E$23),1,0) | L23: ='Metrics'!$B$196
A24: Watershed connectivity | B24: Biology | C24: Fish Passage & Barrier Effects (longitudinal connectivity) | D24: ='Metrics'!$C$205 | E24: ='Metrics'!$B$206 | F24: =IF(NOT(ISNUMBER('Results'!$E$24)),"Not assessed",IF('Results'!$E$24<=5,"Non-Functioning",IF('Results'!$E$24<=10,"Functioning-at-Risk","Functioning"))) | G24: 0.1 | H24: 0 | I24: 1 | J24: =IF(ISNUMBER('Results'!$E$24),'Results'!$E$24,0) | K24: =IF(ISNUMBER('Results'!$E$24),1,0) | L24: ='Metrics'!$B$204
A26: Outcome | B26: Weighted score | C26: Weighted maximum | D26: Sub-index | E26: Displayed | F26: Class | G26: Coverage
A27: Physical | B27: =SUMPRODUCT('Results'!$J$5:$J$24,'Results'!$G$5:$G$24,'Results'!$K$5:$K$24) | C27: =SUMPRODUCT('Results'!$G$5:$G$24,'Results'!$K$5:$K$24)*15 | D27: =IF('Results'!$C$27=0,"",'Results'!$B$27/'Results'!$C$27) | E27: =IF('Results'!$D$27="","",ROUND('Results'!$D$27,2)) | F27: =IF('Results'!$E$27="","Not assessed",IF('Results'!$E$27<=0.39,"Non-Functioning",IF('Results'!$E$27<=0.69,"Functioning-at-Risk","Functioning"))) | G27: =IF(SUMPRODUCT('Results'!$G$5:$G$24)=0,"",SUMPRODUCT('Results'!$G$5:$G$24,'Results'!$K$5:$K$24)/SUMPRODUCT('Results'!$G$5:$G$24))
A28: Chemical | B28: =SUMPRODUCT('Results'!$J$5:$J$24,'Results'!$H$5:$H$24,'Results'!$K$5:$K$24) | C28: =SUMPRODUCT('Results'!$H$5:$H$24,'Results'!$K$5:$K$24)*15 | D28: =IF('Results'!$C$28=0,"",'Results'!$B$28/'Results'!$C$28) | E28: =IF('Results'!$D$28="","",ROUND('Results'!$D$28,2)) | F28: =IF('Results'!$E$28="","Not assessed",IF('Results'!$E$28<=0.39,"Non-Functioning",IF('Results'!$E$28<=0.69,"Functioning-at-Risk","Functioning"))) | G28: =IF(SUMPRODUCT('Results'!$H$5:$H$24)=0,"",SUMPRODUCT('Results'!$H$5:$H$24,'Results'!$K$5:$K$24)/SUMPRODUCT('Results'!$H$5:$H$24))
A29: Biological | B29: =SUMPRODUCT('Results'!$J$5:$J$24,'Results'!$I$5:$I$24,'Results'!$K$5:$K$24) | C29: =SUMPRODUCT('Results'!$I$5:$I$24,'Results'!$K$5:$K$24)*15 | D29: =IF('Results'!$C$29=0,"",'Results'!$B$29/'Results'!$C$29) | E29: =IF('Results'!$D$29="","",ROUND('Results'!$D$29,2)) | F29: =IF('Results'!$E$29="","Not assessed",IF('Results'!$E$29<=0.39,"Non-Functioning",IF('Results'!$E$29<=0.69,"Functioning-at-Risk","Functioning"))) | G29: =IF(SUMPRODUCT('Results'!$I$5:$I$24)=0,"",SUMPRODUCT('Results'!$I$5:$I$24,'Results'!$K$5:$K$24)/SUMPRODUCT('Results'!$I$5:$I$24))
A30: Ecosystem Condition Index | D30: =IF(COUNT('Results'!$D$27,'Results'!$D$28,'Results'!$D$29)=0,"",AVERAGE('Results'!$D$27,'Results'!$D$28,'Results'!$D$29)) | E30: =IF('Results'!$D$30="","",ROUND('Results'!$D$30,2)) | F30: =IF('Results'!$E$30="","Not assessed",IF('Results'!$E$30<=0.39,"Non-Functioning",IF('Results'!$E$30<=0.69,"Functioning-at-Risk","Functioning")))
A32: Coverage | B32: Value
A33: Functions rated | B33: =SUM('Results'!$K$5:$K$24)
A34: Functions selected | B34: 20
A35: Overall coverage | B35: ='Results'!$B$33/'Results'!$B$34
A36: Provisional (coverage below 0.70 overall or for an outcome) | B36: =IF(OR(AND(ISNUMBER('Results'!$B$35),'Results'!$B$35<0.7),AND(ISNUMBER('Results'!$G$27),'Results'!$G$27<0.7),AND(ISNUMBER('Results'!$G$28),'Results'!$G$28<0.7),AND(ISNUMBER('Results'!$G$29),'Results'!$G$29<0.7)),"yes","no")
A37: Status | B37: =IF('Results'!$B$35=1,"Complete screening coverage","Partial screening coverage")

Sheet Reference
A1: Reference tables generated from the EASI scoring definitions
A2: Read only. These values are the application's own catalog, reference curves, regional thresholds, lookups and weights. The Metrics sheet reads them by cell reference.
A4: Rating anchors and function scores
A5: Rating | B5: Index anchor | C5: Function score | D5: Score class
A6: Good | B6: 0.85 | C6: 13 | D6: Functioning
A7: Fair | B7: 0.545 | C7: 8 | D7: Functioning-at-Risk
A8: Poor | B8: 0.195 | C8: 3 | D8: Non-Functioning
A10: Condition classes
A11: Index at or below | B11: Class | C11: Function score at or below
A12: 0.39 | B12: Non-Functioning | C12: 5
A13: 0.69 | B13: Functioning-at-Risk | C13: 10
A14: 1 | B14: Functioning | C14: 15
A16: Fixed bands per input (informational; the Metrics formulas carry the same tests)
A17: Method | B17: Input | C17: Rating | D17: Min | E17: Min inclusive | F17: Max | G17: Max inclusive | H17: Label
A18: catchment-land-cover-pressure | B18: impervious | C18: Good | E18: FALSE | F18: 10 | G18: FALSE | H18: <10%
A19: catchment-land-cover-pressure | B19: impervious | C19: Fair | D19: 10 | E19: TRUE | F19: 25 | G19: TRUE | H19: 10-25%
A20: catchment-land-cover-pressure | B20: impervious | C20: Poor | D20: 25 | E20: FALSE | G20: FALSE | H20: >25%
A21: catchment-land-cover-pressure | B21: agriculture | C21: Good | E21: FALSE | F21: 30 | G21: FALSE | H21: <30%
A22: catchment-land-cover-pressure | B22: agriculture | C22: Fair | D22: 30 | E22: TRUE | F22: 50 | G22: TRUE | H22: 30-50%
A23: catchment-land-cover-pressure | B23: agriculture | C23: Poor | D23: 50 | E23: FALSE | G23: FALSE | H23: >50%
A24: watershed-wetland-extent | B24: (combined) | C24: Poor | E24: FALSE | F24: 1 | G24: FALSE | H24: <1%
A25: watershed-wetland-extent | B25: (combined) | C25: Fair | D25: 1 | E25: TRUE | F25: 5 | G25: TRUE | H25: 1-5%
A26: watershed-wetland-extent | B26: (combined) | C26: Good | D26: 5 | E26: FALSE | G26: FALSE | H26: >5%
A27: road-density-inflow-pressure | B27: (combined) | C27: Good | E27: FALSE | F27: 1 | G27: FALSE | H27: <1 km/km²
A28: road-density-inflow-pressure | B28: (combined) | C28: Fair | D28: 1 | E28: TRUE | F28: 3 | G28: FALSE | H28: 1-<3 km/km²
A29: road-density-inflow-pressure | B29: (combined) | C29: Poor | D29: 3 | E29: TRUE | G29: FALSE | H29: ≥3 km/km²
A30: degree-of-regulation | B30: (combined) | C30: Good | E30: FALSE | F30: 2 | G30: FALSE | H30: <2%
A31: degree-of-regulation | B31: (combined) | C31: Fair | D31: 2 | E31: TRUE | F31: 15 | G31: TRUE | H31: 2-15%
A32: degree-of-regulation | B32: (combined) | C32: Poor | D32: 15 | E32: FALSE | G32: FALSE | H32: >15%
A33: bank-height-ratio | B33: (combined) | C33: Good | E33: FALSE | F33: 1.3 | G33: TRUE | H33: ≤1.3
A34: bank-height-ratio | B34: (combined) | C34: Fair | D34: 1.3 | E34: FALSE | F34: 1.5 | G34: TRUE | H34: >1.3-≤1.5
A35: bank-height-ratio | B35: (combined) | C35: Poor | D35: 1.5 | E35: FALSE | G35: FALSE | H35: >1.5
A36: hyporheic-exchange-potential | B36: slope | C36: Poor | E36: FALSE | F36: 0.003 | G36: FALSE | H36: <0.003 m/m
A37: hyporheic-exchange-potential | B37: slope | C37: Fair | D37: 0.003 | E37: TRUE | F37: 0.006 | G37: FALSE | H37: 0.003-<0.006 m/m
A38: hyporheic-exchange-potential | B38: slope | C38: Good | D38: 0.006 | E38: TRUE | G38: FALSE | H38: ≥0.006 m/m
A39: hyporheic-exchange-potential | B39: sinuosity | C39: Poor | E39: FALSE | F39: 1.05 | G39: FALSE | H39: <1.05
A40: hyporheic-exchange-potential | B40: sinuosity | C40: Fair | D40: 1.05 | E40: TRUE | F40: 1.2 | G40: FALSE | H40: 1.05-<1.2
A41: hyporheic-exchange-potential | B41: sinuosity | C41: Good | D41: 1.2 | E41: TRUE | G41: FALSE | H41: ≥1.2
A42: channel-adjustment-susceptibility | B42: bhr | C42: Good | E42: FALSE | F42: 1.3 | G42: TRUE | H42: ≤1.3
A43: channel-adjustment-susceptibility | B43: bhr | C43: Fair | D43: 1.3 | E43: FALSE | F43: 1.5 | G43: TRUE | H43: >1.3-≤1.5
...

Sheet Metadata
A1: Metadata and version information
A2: Item | B2: Value
A3: Calculator version | B3: 1.0.0
A4: Calculator date | B4: 2026-09-16
A5: Scoring method digest | B5: b2e3033116e3
A6: Scoring identity | B6: alternative-2 (Alternative 2: NARS-9 references)
A7: Criteria set | B7: regional
A8: Reference curves | B8: 34 curves
A9: Catalog sha256 | B9: 78c1e2921198905ee6e53f18147e2aa33f9a6ffd87ff3e7a23844238b3fb73f3
A10: Curves sha256 | B10: a824e2c254dea1c22af62d2a6f5fd3d0862ff0574190111655aa5b34dbce4887
A11: NARS-9 geography sha256 | B11: f08b5be1ec4149da224f7fc5185c755f0d612d9115c53a172081c67009ab0300
A12: Rating anchors | B12: Good 0.85, Fair 0.545, Poor 0.195
A13: Function scores | B13: Good 13, Fair 8, Poor 3
... A21: Formula vocabulary | B21: IF AND OR NOT MIN MAX ROUND INDEX MATCH IFERROR ISNUMBER COUNT SUM SUMPRODUCT AVERAGE STDEV.P PRODUCT UPPER TRIM SUBSTITUTE LEN
