Workbook

Sheet Instructions
A1: Model Name | B1: Stream Functions Assessment and Rapid Index (SFARI) | I1: Color Coding Key:
A2: Developers | B2: Leanne Stepchinski, Gabrielle David, Samantha Wiest, and Garrett Menichino | I2: User Input | L2: **DO NOT INPUT VALUES HERE**
B3: U.S. Army Engineer Research and Development Center, Environmental Laboratory | I3: Calculated | L3: Function | M3: Value | N3: Red (0-5) | O3: Yellow (6-10) | P3: Blue (11-15)
B4: Vicksburg, MS | I4: Linked to Another Sheet | L4: ='Existing Conditions'!F8 -> Catchment Hydrology | M4: ='Existing Conditions'!H8 -> 0 | N4: =IF(M4/15<=0.39, M4, IF(M4/15<=0.69, NA(), NA())) -> 0 | O4: =IF(M4/15<=0.39, NA(), IF(M4/15<=0.69, M4,NA())) -> #N/A | P4: =IF(M4/15<=0.39, NA(), IF(M4/15<=0.69, NA(), M4)) -> #N/A
B5: Leanne.M.Stepchinski@usace.army.mil, Gabrielle.C.David@usace.army.mil, Samantha.R.Wiest@erdc.dren.mil, Garrett.T.Menichino@usace.army.mil | L5: ='Existing Conditions'!F12 -> Surface Water Storage | M5: ='Existing Conditions'!H12 -> 0 | N5: =IF(M5/15<=0.39, M5, IF(M5/15<=0.69, NA(), NA())) -> 0 | O5: =IF(M5/15<=0.39, NA(), IF(M5/15<=0.69, M5,NA())) -> #N/A | P5: =IF(M5/15<=0.39, NA(), IF(M5/15<=0.69, NA(), M5)) -> #N/A
I6: Protect/unprotect password: | L6: ='Existing Conditions'!F16 -> Reach Inflow | M6: ='Existing Conditions'!H16 -> 0 | N6: =IF(M6/15<=0.39, M6, IF(M6/15<=0.69, NA(), NA())) -> 0 | O6: =IF(M6/15<=0.39, NA(), IF(M6/15<=0.69, M6,NA())) -> #N/A | P6: =IF(M6/15<=0.39, NA(), IF(M6/15<=0.69, NA(), M6)) -> #N/A
A7: Model Version | B7: SFARI v1.1 | I7: sfari | L7: ='Existing Conditions'!F20 -> Streamflow Regime | M7: ='Existing Conditions'!H20 -> 0 | N7: =IF(M7/15<=0.39, M7, IF(M7/15<=0.69, NA(), NA())) -> 0 | O7: =IF(M7/15<=0.39, NA(), IF(M7/15<=0.69, M7,NA())) -> #N/A | P7: =IF(M7/15<=0.39, NA(), IF(M7/15<=0.69, NA(), M7)) -> #N/A
A8: Date of Last Update | B8: 46294 | L8: ='Existing Conditions'!F24 -> Low Flow and Baseflow Dynamics | M8: ='Existing Conditions'!H24 -> 0 | N8: =IF(M8/15<=0.39, M8, IF(M8/15<=0.69, NA(), NA())) -> 0 | O8: =IF(M8/15<=0.39, NA(), IF(M8/15<=0.69, M8,NA())) -> #N/A | P8: =IF(M8/15<=0.39, NA(), IF(M8/15<=0.69, NA(), M8)) -> #N/A
L9: ='Existing Conditions'!F28 -> High Flow Dynamics | M9: ='Existing Conditions'!H28 -> 0 | N9: =IF(M9/15<=0.39, M9, IF(M9/15<=0.69, NA(), NA())) -> 0 | O9: =IF(M9/15<=0.39, NA(), IF(M9/15<=0.69, M9,NA())) -> #N/A | P9: =IF(M9/15<=0.39, NA(), IF(M9/15<=0.69, NA(), M9)) -> #N/A
A10: Waiver | B10: This model is provided for free as part of the USACE Technical Report "Stream Functions Assessment and Rapid Index" by Leanne Stepchinski, Gabrielle David, Samantha R. Wiest, and Garrett T. Menichino | L10: ='Existing Conditions'!F32 -> Floodplain Connectivity | M10: ='Existing Conditions'!H32 -> 0 | N10: =IF(M10/15<=0.39, M10, IF(M10/15<=0.69, NA(), NA())) -> 0 | O10: =IF(M10/15<=0.39, NA(), IF(M10/15<=0.69, M10,NA())) -> #N/A | P10: =IF(M10/15<=0.39, NA(), IF(M10/15<=0.69, NA(), M10)) -> #N/A
B11: None of the authors nor the US Army Corps of Engineers accepts responsibility or liability for the model's use by third parties. | L11: ='Existing Conditions'!F36 -> Hyporheic Connectivity | M11: ='Existing Conditions'!H36 -> 0 | N11: =IF(M11/15<=0.39, M11, IF(M11/15<=0.69, NA(), NA())) -> 0 | O11: =IF(M11/15<=0.39, NA(), IF(M11/15<=0.69, M11,NA())) -> #N/A | P11: =IF(M11/15<=0.39, NA(), IF(M11/15<=0.69, NA(), M11)) -> #N/A
L12: ='Existing Conditions'!F40 -> Channel Evolution | M12: ='Existing Conditions'!H40 -> 0 | N12: =IF(M12/15<=0.39, M12, IF(M12/15<=0.69, NA(), NA())) -> 0 | O12: =IF(M12/15<=0.39, NA(), IF(M12/15<=0.69, M12,NA())) -> #N/A | P12: =IF(M12/15<=0.39, NA(), IF(M12/15<=0.69, NA(), M12)) -> #N/A
L13: ='Existing Conditions'!F44 -> Channel and Floodplain Dynamics | M13: ='Existing Conditions'!H44 -> 0 | N13: =IF(M13/15<=0.39, M13, IF(M13/15<=0.69, NA(), NA())) -> 0 | O13: =IF(M13/15<=0.39, NA(), IF(M13/15<=0.69, M13,NA())) -> #N/A | P13: =IF(M13/15<=0.39, NA(), IF(M13/15<=0.69, NA(), M13)) -> #N/A
L14: ='Existing Conditions'!F48 -> Sediment Continuity | M14: ='Existing Conditions'!H48 -> 0 | N14: =IF(M14/15<=0.39, M14, IF(M14/15<=0.69, NA(), NA())) -> 0 | O14: =IF(M14/15<=0.39, NA(), IF(M14/15<=0.69, M14,NA())) -> #N/A | P14: =IF(M14/15<=0.39, NA(), IF(M14/15<=0.69, NA(), M14)) -> #N/A
A15: Instructions | L15: ='Existing Conditions'!F52 -> Bed Composition and Bedform Dynamics | M15: ='Existing Conditions'!H52 -> 0 | N15: =IF(M15/15<=0.39, M15, IF(M15/15<=0.69, NA(), NA())) -> 0 | O15: =IF(M15/15<=0.39, NA(), IF(M15/15<=0.69, M15,NA())) -> #N/A | P15: =IF(M15/15<=0.39, NA(), IF(M15/15<=0.69, NA(), M15)) -> #N/A
A16: 1) | B16: Add the field site information into the orange cells at the top of the Existing Conditions worksheet. | L16: ='Existing Conditions'!F56 -> Light and Thermal Regime | M16: ='Existing Conditions'!H56 -> 0 | N16: =IF(M16/15<=0.39, M16, IF(M16/15<=0.69, NA(), NA())) -> 0 | O16: =IF(M16/15<=0.39, NA(), IF(M16/15<=0.69, M16,NA())) -> #N/A | P16: =IF(M16/15<=0.39, NA(), IF(M16/15<=0.69, NA(), M16)) -> #N/A
A17: 2) | B17: Record the metric scores using the Likert scale drop-down menu (column J). | L17: ='Existing Conditions'!F60 -> Carbon Processing | M17: ='Existing Conditions'!H60 -> 0 | N17: =IF(M17/15<=0.39, M17, IF(M17/15<=0.69, NA(), NA())) -> 0 | O17: =IF(M17/15<=0.39, NA(), IF(M17/15<=0.69, M17,NA())) -> #N/A | P17: =IF(M17/15<=0.39, NA(), IF(M17/15<=0.69, NA(), M17)) -> #N/A
A18: 3) | B18: Record the function scores by entering a quantitative value between 0-15 (column H). | L18: ='Existing Conditions'!F64 -> Nutrient Cycling | M18: ='Existing Conditions'!H64 -> 0 | N18: =IF(M18/15<=0.39, M18, IF(M18/15<=0.69, NA(), NA())) -> 0 | O18: =IF(M18/15<=0.39, NA(), IF(M18/15<=0.69, M18,NA())) -> #N/A | P18: =IF(M18/15<=0.39, NA(), IF(M18/15<=0.69, NA(), M18)) -> #N/A
A19: 4) | B19: Once the metric and function scores are recorded, the Functional Categories, Outcomes, and overall SFARI Index scores will auto-populate (column A). The scoring summary table and the bar charts to the right of the table will also auto-populate. | L19: ='Existing Conditions'!F68 -> Water and Soil Quality | M19: ='Existing Conditions'!H68 -> 0 | N19: =IF(M19/15<=0.39, M19, IF(M19/15<=0.69, NA(), NA())) -> 0 | O19: =IF(M19/15<=0.39, NA(), IF(M19/15<=0.69, M19,NA())) -> #N/A | P19: =IF(M19/15<=0.39, NA(), IF(M19/15<=0.69, NA(), M19)) -> #N/A
A20: 5) | B20: Record other metrics, notes, or regional outliers in the grey box at the bottom of the worksheet. | L20: ='Existing Conditions'!F72 -> Habitat Provision | M20: ='Existing Conditions'!H72 -> 0 | N20: =IF(M20/15<=0.39, M20, IF(M20/15<=0.69, NA(), NA())) -> 0 | O20: =IF(M20/15<=0.39, NA(), IF(M20/15<=0.69, M20,NA())) -> #N/A | P20: =IF(M20/15<=0.39, NA(), IF(M20/15<=0.69, NA(), M20)) -> #N/A
L21: ='Existing Conditions'!F76 -> Population Support | M21: ='Existing Conditions'!H76 -> 0 | N21: =IF(M21/15<=0.39, M21, IF(M21/15<=0.69, NA(), NA())) -> 0 | O21: =IF(M21/15<=0.39, NA(), IF(M21/15<=0.69, M21,NA())) -> #N/A | P21: =IF(M21/15<=0.39, NA(), IF(M21/15<=0.69, NA(), M21)) -> #N/A
A22: Comments/Assumptions | L22: ='Existing Conditions'!F80 -> Community Dynamics | M22: ='Existing Conditions'!H80 -> 0 | N22: =IF(M22/15<=0.39, M22, IF(M22/15<=0.69, NA(), NA())) -> 0 | O22: =IF(M22/15<=0.39, NA(), IF(M22/15<=0.69, M22,NA())) -> #N/A | P22: =IF(M22/15<=0.39, NA(), IF(M22/15<=0.69, NA(), M22)) -> #N/A
A23: 1) | B23: For the manual scoring approach, the user determines a function score based on a scale of 0-15. For optional automatic scoring, column G provides a "Function Score Check" based on the Likert Scale Scoring in column J. | L23: ='Existing Conditions'!F84 -> Watershed Connectivity | M23: ='Existing Conditions'!H84 -> 0 | N23: =IF(M23/15<=0.39, M23, IF(M23/15<=0.69, NA(), NA())) -> 0 | O23: =IF(M23/15<=0.39, NA(), IF(M23/15<=0.69, M23,NA())) -> #N/A | P23: =IF(M23/15<=0.39, NA(), IF(M23/15<=0.69, NA(), M23)) -> #N/A
L25: ='Existing Conditions'!B8 -> Physical | M25: ='Existing Conditions'!C8 -> 0 | N25: =IF(M25<=0.395, M25, IF(M25<=0.695, NA(), NA())) -> 0 | O25: =IF(M25<=0.395, NA(), IF(M25<=0.695, M25,NA())) -> #N/A | P25: =IF(M25<=0.395, NA(), IF(M25<=0.695, NA(), M25)) -> #N/A
L26: ='Existing Conditions'!B56 -> Chemical | M26: ='Existing Conditions'!C56 -> 0 | N26: =IF(M26<=0.395, M26, IF(M26<=0.695, NA(), NA())) -> 0 | O26: =IF(M26<=0.395, NA(), IF(M26<=0.695, M26,NA())) -> #N/A | P26: =IF(M26<=0.395, NA(), IF(M26<=0.695, NA(), M26)) -> #N/A
L27: ='Existing Conditions'!B72 -> Biological | M27: ='Existing Conditions'!C72 -> 0 | N27: =IF(M27<=0.395, M27, IF(M27<=0.695, NA(), NA())) -> 0 | O27: =IF(M27<=0.395, NA(), IF(M27<=0.695, M27,NA())) -> #N/A | P27: =IF(M27<=0.395, NA(), IF(M27<=0.695, NA(), M27)) -> #N/A

Sheet Summary
A1: SFARI assessment summary
A4: Reach name
A5: Assessment tier | B5: Rapid
A6: Reach length
A7: Drainage area
A8: Stream order (Strahler)
A9: NARS-9 region
A10: EPA Level I ecoregion
A11: EPA Level II ecoregion
A12: EPA Level III ecoregion
A13: Scores
B14: Existing Conditions
A15: Index
A16: ECI | B16: =IF(ISNUMBER('Existing Conditions'!$A$8),'Existing Conditions'!$A$8,"")
A17: Physical | B17: =IF(ISNUMBER('Existing Conditions'!$C$8),'Existing Conditions'!$C$8,"")
A18: Chemical | B18: =IF(ISNUMBER('Existing Conditions'!$C$56),'Existing Conditions'!$C$56,"")
A19: Biological | B19: =IF(ISNUMBER('Existing Conditions'!$C$72),'Existing Conditions'!$C$72,"")
A20: Hydrology
A21: Catchment hydrology | B21: =IF(ISNUMBER('Existing Conditions'!$H$8),'Existing Conditions'!$H$8,"")
A22: Surface water storage | B22: =IF(ISNUMBER('Existing Conditions'!$H$12),'Existing Conditions'!$H$12,"")
A23: Reach inflow | B23: =IF(ISNUMBER('Existing Conditions'!$H$16),'Existing Conditions'!$H$16,"")
A24: Streamflow regime | B24: =IF(ISNUMBER('Existing Conditions'!$H$20),'Existing Conditions'!$H$20,"")
A25: Hydraulics
A26: Low flow and baseflow dynamics | B26: =IF(ISNUMBER('Existing Conditions'!$H$24),'Existing Conditions'!$H$24,"")
A27: High flow dynamics | B27: =IF(ISNUMBER('Existing Conditions'!$H$28),'Existing Conditions'!$H$28,"")
A28: Floodplain connectivity | B28: =IF(ISNUMBER('Existing Conditions'!$H$32),'Existing Conditions'!$H$32,"")
A29: Hyporheic connectivity | B29: =IF(ISNUMBER('Existing Conditions'!$H$36),'Existing Conditions'!$H$36,"")
A30: Geomorphology
A31: Channel evolution | B31: =IF(ISNUMBER('Existing Conditions'!$H$40),'Existing Conditions'!$H$40,"")
A32: Channel and floodplain dynamics | B32: =IF(ISNUMBER('Existing Conditions'!$H$44),'Existing Conditions'!$H$44,"")
A33: Sediment continuity | B33: =IF(ISNUMBER('Existing Conditions'!$H$48),'Existing Conditions'!$H$48,"")
A34: Bed composition and bedform dynamics | B34: =IF(ISNUMBER('Existing Conditions'!$H$52),'Existing Conditions'!$H$52,"")
A35: Physicochemistry
A36: Light and thermal regime | B36: =IF(ISNUMBER('Existing Conditions'!$H$56),'Existing Conditions'!$H$56,"")
A37: Carbon processing | B37: =IF(ISNUMBER('Existing Conditions'!$H$60),'Existing Conditions'!$H$60,"")
A38: Nutrient cycling | B38: =IF(ISNUMBER('Existing Conditions'!$H$64),'Existing Conditions'!$H$64,"")
A39: Water and soil quality | B39: =IF(ISNUMBER('Existing Conditions'!$H$68),'Existing Conditions'!$H$68,"")
A40: Biology
A41: Habitat provision | B41: =IF(ISNUMBER('Existing Conditions'!$H$72),'Existing Conditions'!$H$72,"")
A42: Population support | B42: =IF(ISNUMBER('Existing Conditions'!$H$76),'Existing Conditions'!$H$76,"")
...

Sheet Existing Conditions
A1: Stream Function Assessment and Rapid Index (SFARI) Worksheet | R1: Strongly Agree | S1: 14
A2: Reach ID | F2: Reach Length (ft) | R2: Agree | S2: 11
A3: Lat/Long | F3: Assessor(s) | R3: Neutral | S3: 8
A4: Date | R4: Disagree | S4: 5
A5: SFARI | B5: Outcomes | D5: Functional Categories | F5: Functions | I5: Metrics | R5: Strongly Disagree | S5: 2 | Z5: Outcomes | AH5: Weighted Scores
A6: Index Score | B6: Name | C6: Sub-Index Score | D6: Name | E6: Sub-Index Score | F6: Name | G6: Function Score Check | H6: Manual Score | I6: Name | J6: Likert Scale Score | P6: Indicator | R6: NA | W6: Functional Categories | X6: Functions | Y6: Score | Z6: Physical | AA6: Chemical | AB6: Biological | AE6: Physical weight | AF6: Chemical weight | AG6: Biological weight | AH6: Physical | AI6: Chemical | AJ6: Biological
AO7: D | AP7: i
A8: =AVERAGE(C8:C87) -> 0 | B8: Physical | C8: =Z28 -> 0 | D8: Hydrology | E8: =IF(AVERAGE(H8:H23)/15<0.4, "Non-Functioning", IF(AVERAGE(H8:H23)/15<0.7, "Functioning At-Risk", "Functioning")) -> #DIV/0! | F8: Catchment Hydrology | G8: =AVERAGEIF(P8:P11,"<>#N/A") -> #DIV/0! | I8: Impervious surface area | P8: {=VLOOKUP($J8:$J8,$R$1:$S$5,2,FALSE)} -> #N/A | W8: Hydrology | X8: Catchment hydrology | Y8: =H8 -> 0 | Z8: D | AA8: i | AB8: i | AE8: =IF('Existing Conditions'!Z8="D",'Existing Conditions'!$AO$8,IF('Existing Conditions'!Z8="I",'Existing Conditions'!$AP$8,0)) -> 1 | AF8: =IF('Existing Conditions'!AA8="D",'Existing Conditions'!$AO$8,IF('Existing Conditions'!AA8="I",'Existing Conditions'!$AP$8,0)) -> 0.1 | AG8: =IF('Existing Conditions'!AB8="D",'Existing Conditions'!$AO$8,IF('Existing Conditions'!AB8="I",'Existing Conditions'!$AP$8,0)) -> 0.1 | AH8: =IF(OR(ISBLANK('Existing Conditions'!Z8),ISBLANK('Existing Conditions'!Y8)),NA(),'Existing Conditions'!$Y8)*AE8 -> 0 | AI8: =IF(OR(ISBLANK('Existing Conditions'!AA8),ISBLANK('Existing Conditions'!Y8)),NA(),'Existing Conditions'!$Y8)*AF8 -> 0 | AJ8: =IF(OR(ISBLANK('Existing Conditions'!AB8),ISBLANK('Existing Conditions'!Y8)),NA(),'Existing Conditions'!$Y8)*AG8 -> 0 | AK8: =IF(ISBLANK('Existing Conditions'!$Y$8), 0, AE8*15) -> 15 | AL8: =IF(ISBLANK('Existing Conditions'!$Y$8), 0, AF8*15) -> 1.5 | AM8: =IF(ISBLANK('Existing Conditions'!$Y$8), 0, AG8*15) -> 1.5 | AO8: 1 | AP8: 0.1
I9: Road density | P9: {=VLOOKUP($J9:$J9,$R$1:$S$5,2,FALSE)} -> #N/A | X9: Surface water storage | Y9: =H12 -> 0 | Z9: D | AA9: i | AB9: i | AE9: =IF('Existing Conditions'!Z9="D",'Existing Conditions'!$AO$8,IF('Existing Conditions'!Z9="I",'Existing Conditions'!$AP$8,0)) -> 1 | AF9: =IF('Existing Conditions'!AA9="D",'Existing Conditions'!$AO$8,IF('Existing Conditions'!AA9="I",'Existing Conditions'!$AP$8,0)) -> 0.1 | AG9: =IF('Existing Conditions'!AB9="D",'Existing Conditions'!$AO$8,IF('Existing Conditions'!AB9="I",'Existing Conditions'!$AP$8,0)) -> 0.1 | AH9: =IF(OR(ISBLANK('Existing Conditions'!Z9),ISBLANK('Existing Conditions'!Y9)),NA(),'Existing Conditions'!$Y9)*AE9 -> 0 | AI9: =IF(OR(ISBLANK('Existing Conditions'!AA9),ISBLANK('Existing Conditions'!Y9)),NA(),'Existing Conditions'!$Y9)*AF9 -> 0 | AJ9: =IF(OR(ISBLANK('Existing Conditions'!AB9),ISBLANK('Existing Conditions'!Y9)),NA(),'Existing Conditions'!$Y9)*AG9 -> 0 | AK9: =IF(ISBLANK('Existing Conditions'!$Y$9), 0, AE9*15) -> 15 | AL9: =IF(ISBLANK('Existing Conditions'!$Y$9), 0, AF9*15) -> 1.5 | AM9: =IF(ISBLANK('Existing Conditions'!$Y$9), 0, AG9*15) -> 1.5
I10: Land Use Change | P10: {=VLOOKUP($J10:$J10,$R$1:$S$5,2,FALSE)} -> #N/A | X10: Reach inflow | Y10: =H16 -> 0 | Z10: D | AA10: i | AE10: =IF('Existing Conditions'!Z10="D",'Existing Conditions'!$AO$8,IF('Existing Conditions'!Z10="I",'Existing Conditions'!$AP$8,0)) -> 1 | AF10: =IF('Existing Conditions'!AA10="D",'Existing Conditions'!$AO$8,IF('Existing Conditions'!AA10="I",'Existing Conditions'!$AP$8,0)) -> 0.1 | AG10: =IF('Existing Conditions'!AB10="D",'Existing Conditions'!$AO$8,IF('Existing Conditions'!AB10="I",'Existing Conditions'!$AP$8,0)) -> 0 | AH10: =IF(OR(ISBLANK('Existing Conditions'!Z10),ISBLANK('Existing Conditions'!Y10)),NA(),'Existing Conditions'!$Y10)*AE10 -> 0 | AI10: =IF(OR(ISBLANK('Existing Conditions'!AA10),ISBLANK('Existing Conditions'!Y10)),NA(),'Existing Conditions'!$Y10)*AF10 -> 0 | AJ10: =IF(OR(ISBLANK('Existing Conditions'!AB10),ISBLANK('Existing Conditions'!Y10)),NA(),'Existing Conditions'!$Y10)*AG10 -> #N/A | AK10: =IF(ISBLANK('Existing Conditions'!$Y$10), 0, AE10*15) -> 15 | AL10: =IF(ISBLANK('Existing Conditions'!$Y$10), 0, AF10*15) -> 1.5 | AM10: =IF(ISBLANK('Existing Conditions'!$Y$10), 0, AG10*15) -> 0
I11: Impoundments | P11: {=VLOOKUP($J11:$J11,$R$1:$S$5,2,FALSE)} -> #N/A | X11: Streamflow Regime | Y11: =H20 -> 0 | Z11: D | AA11: i | AB11: i | AE11: =IF('Existing Conditions'!Z11="D",'Existing Conditions'!$AO$8,IF('Existing Conditions'!Z11="I",'Existing Conditions'!$AP$8,0)) -> 1 | AF11: =IF('Existing Conditions'!AA11="D",'Existing Conditions'!$AO$8,IF('Existing Conditions'!AA11="I",'Existing Conditions'!$AP$8,0)) -> 0.1 | AG11: =IF('Existing Conditions'!AB11="D",'Existing Conditions'!$AO$8,IF('Existing Conditions'!AB11="I",'Existing Conditions'!$AP$8,0)) -> 0.1 | AH11: =IF(OR(ISBLANK('Existing Conditions'!Z11),ISBLANK('Existing Conditions'!Y11)),NA(),'Existing Conditions'!$Y11)*AE11 -> 0 | AI11: =IF(OR(ISBLANK('Existing Conditions'!AA11),ISBLANK('Existing Conditions'!Y11)),NA(),'Existing Conditions'!$Y11)*AF11 -> 0 | AJ11: =IF(OR(ISBLANK('Existing Conditions'!AB11),ISBLANK('Existing Conditions'!Y11)),NA(),'Existing Conditions'!$Y11)*AG11 -> 0 | AK11: =IF(ISBLANK('Existing Conditions'!$Y$11), 0, AE11*15) -> 15 | AL11: =IF(ISBLANK('Existing Conditions'!$Y$11), 0, AF11*15) -> 1.5 | AM11: =IF(ISBLANK('Existing Conditions'!$Y$11), 0, AG11*15) -> 1.5
F12: Surface Water Storage | G12: =AVERAGEIF(P12:P15,"<>#N/A") -> #DIV/0! | I12: Wetland coverage | P12: {=VLOOKUP($J12:$J12,$R$1:$S$5,2,FALSE)} -> #N/A | W12: Hydraulics | X12: Low flow and baseflow | Y12: =H24 -> 0 | Z12: D | AA12: i | AB12: i | AE12: =IF('Existing Conditions'!Z12="D",'Existing Conditions'!$AO$8,IF('Existing Conditions'!Z12="I",'Existing Conditions'!$AP$8,0)) -> 1 | AF12: =IF('Existing Conditions'!AA12="D",'Existing Conditions'!$AO$8,IF('Existing Conditions'!AA12="I",'Existing Conditions'!$AP$8,0)) -> 0.1 | AG12: =IF('Existing Conditions'!AB12="D",'Existing Conditions'!$AO$8,IF('Existing Conditions'!AB12="I",'Existing Conditions'!$AP$8,0)) -> 0.1 | AH12: =IF(OR(ISBLANK('Existing Conditions'!Z12),ISBLANK('Existing Conditions'!Y12)),NA(),'Existing Conditions'!$Y12)*AE12 -> 0 | AI12: =IF(OR(ISBLANK('Existing Conditions'!AA12),ISBLANK('Existing Conditions'!Y12)),NA(),'Existing Conditions'!$Y12)*AF12 -> 0 | AJ12: =IF(OR(ISBLANK('Existing Conditions'!AB12),ISBLANK('Existing Conditions'!Y12)),NA(),'Existing Conditions'!$Y12)*AG12 -> 0 | AK12: =IF(ISBLANK('Existing Conditions'!$Y$12), 0, AE12*15) -> 15 | AL12: =IF(ISBLANK('Existing Conditions'!$Y$12), 0, AF12*15) -> 1.5 | AM12: =IF(ISBLANK('Existing Conditions'!$Y$12), 0, AG12*15) -> 1.5
I13: Floodplain water retention | P13: {=VLOOKUP($J13:$J13,$R$1:$S$5,2,FALSE)} -> #N/A | X13: High flow dynamics | Y13: =H28 -> 0 | Z13: D | AA13: i | AB13: i | AE13: =IF('Existing Conditions'!Z13="D",'Existing Conditions'!$AO$8,IF('Existing Conditions'!Z13="I",'Existing Conditions'!$AP$8,0)) -> 1 | AF13: =IF('Existing Conditions'!AA13="D",'Existing Conditions'!$AO$8,IF('Existing Conditions'!AA13="I",'Existing Conditions'!$AP$8,0)) -> 0.1 | AG13: =IF('Existing Conditions'!AB13="D",'Existing Conditions'!$AO$8,IF('Existing Conditions'!AB13="I",'Existing Conditions'!$AP$8,0)) -> 0.1 | AH13: =IF(OR(ISBLANK('Existing Conditions'!Z13),ISBLANK('Existing Conditions'!Y13)),NA(),'Existing Conditions'!$Y13)*AE13 -> 0 | AI13: =IF(OR(ISBLANK('Existing Conditions'!AA13),ISBLANK('Existing Conditions'!Y13)),NA(),'Existing Conditions'!$Y13)*AF13 -> 0 | AJ13: =IF(OR(ISBLANK('Existing Conditions'!AB13),ISBLANK('Existing Conditions'!Y13)),NA(),'Existing Conditions'!$Y13)*AG13 -> 0 | AK13: =IF(ISBLANK('Existing Conditions'!$Y$13), 0, AE13*15) -> 15 | AL13: =IF(ISBLANK('Existing Conditions'!$Y$13), 0, AF13*15) -> 1.5 | AM13: =IF(ISBLANK('Existing Conditions'!$Y$13), 0, AG13*15) -> 1.5
I14: In-channel ponding/beaver | P14: {=VLOOKUP($J14:$J14,$R$1:$S$5,2,FALSE)} -> #N/A | X14: Floodplain connectivity | Y14: =H32 -> 0 | Z14: i | AA14: i | AB14: i | AE14: =IF('Existing Conditions'!Z14="D",'Existing Conditions'!$AO$8,IF('Existing Conditions'!Z14="I",'Existing Conditions'!$AP$8,0)) -> 0.1 | AF14: =IF('Existing Conditions'!AA14="D",'Existing Conditions'!$AO$8,IF('Existing Conditions'!AA14="I",'Existing Conditions'!$AP$8,0)) -> 0.1 | AG14: =IF('Existing Conditions'!AB14="D",'Existing Conditions'!$AO$8,IF('Existing Conditions'!AB14="I",'Existing Conditions'!$AP$8,0)) -> 0.1 | AH14: =IF(OR(ISBLANK('Existing Conditions'!Z14),ISBLANK('Existing Conditions'!Y14)),NA(),'Existing Conditions'!$Y14)*AE14 -> 0 | AI14: =IF(OR(ISBLANK('Existing Conditions'!AA14),ISBLANK('Existing Conditions'!Y14)),NA(),'Existing Conditions'!$Y14)*AF14 -> 0 | AJ14: =IF(OR(ISBLANK('Existing Conditions'!AB14),ISBLANK('Existing Conditions'!Y14)),NA(),'Existing Conditions'!$Y14)*AG14 -> 0 | AK14: =IF(ISBLANK('Existing Conditions'!$Y$14), 0, AE14*15) -> 1.5 | AL14: =IF(ISBLANK('Existing Conditions'!$Y$14), 0, AF14*15) -> 1.5 | AM14: =IF(ISBLANK('Existing Conditions'!$Y$14), 0, AG14*15) -> 1.5
I15: Off-channel storage | P15: {=VLOOKUP($J15:$J15,$R$1:$S$5,2,FALSE)} -> #N/A | X15: Hyporheic connectivity | Y15: =H36 -> 0 | Z15: i | AA15: i | AB15: i | AE15: =IF('Existing Conditions'!Z15="D",'Existing Conditions'!$AO$8,IF('Existing Conditions'!Z15="I",'Existing Conditions'!$AP$8,0)) -> 0.1 | AF15: =IF('Existing Conditions'!AA15="D",'Existing Conditions'!$AO$8,IF('Existing Conditions'!AA15="I",'Existing Conditions'!$AP$8,0)) -> 0.1 | AG15: =IF('Existing Conditions'!AB15="D",'Existing Conditions'!$AO$8,IF('Existing Conditions'!AB15="I",'Existing Conditions'!$AP$8,0)) -> 0.1 | AH15: =IF(OR(ISBLANK('Existing Conditions'!Z15),ISBLANK('Existing Conditions'!Y15)),NA(),'Existing Conditions'!$Y15)*AE15 -> 0 | AI15: =IF(OR(ISBLANK('Existing Conditions'!AA15),ISBLANK('Existing Conditions'!Y15)),NA(),'Existing Conditions'!$Y15)*AF15 -> 0 | AJ15: =IF(OR(ISBLANK('Existing Conditions'!AB15),ISBLANK('Existing Conditions'!Y15)),NA(),'Existing Conditions'!$Y15)*AG15 -> 0 | AK15: =IF(ISBLANK('Existing Conditions'!$Y$15), 0, AE15*15) -> 1.5 | AL15: =IF(ISBLANK('Existing Conditions'!$Y$15), 0, AF15*15) -> 1.5 | AM15: =IF(ISBLANK('Existing Conditions'!$Y$15), 0, AG15*15) -> 1.5
F16: Reach Inflow | G16: =AVERAGEIF(P16:P19,"<>#N/A") -> #DIV/0! | I16: Concentrated flow inputs | P16: {=VLOOKUP($J16:$J16,$R$1:$S$5,2,FALSE)} -> #N/A | W16: Geomorphology | X16: Channel evolution | Y16: =H40 -> 0 | Z16: D | AA16: i | AB16: i | AE16: =IF('Existing Conditions'!Z16="D",'Existing Conditions'!$AO$8,IF('Existing Conditions'!Z16="I",'Existing Conditions'!$AP$8,0)) -> 1 | AF16: =IF('Existing Conditions'!AA16="D",'Existing Conditions'!$AO$8,IF('Existing Conditions'!AA16="I",'Existing Conditions'!$AP$8,0)) -> 0.1 | AG16: =IF('Existing Conditions'!AB16="D",'Existing Conditions'!$AO$8,IF('Existing Conditions'!AB16="I",'Existing Conditions'!$AP$8,0)) -> 0.1 | AH16: =IF(OR(ISBLANK('Existing Conditions'!Z16),ISBLANK('Existing Conditions'!Y16)),NA(),'Existing Conditions'!$Y16)*AE16 -> 0 | AI16: =IF(OR(ISBLANK('Existing Conditions'!AA16),ISBLANK('Existing Conditions'!Y16)),NA(),'Existing Conditions'!$Y16)*AF16 -> 0 | AJ16: =IF(OR(ISBLANK('Existing Conditions'!AB16),ISBLANK('Existing Conditions'!Y16)),NA(),'Existing Conditions'!$Y16)*AG16 -> 0 | AK16: =IF(ISBLANK('Existing Conditions'!$Y$16), 0, AE16*15) -> 15 | AL16: =IF(ISBLANK('Existing Conditions'!$Y$16), 0, AF16*15) -> 1.5 | AM16: =IF(ISBLANK('Existing Conditions'!$Y$16), 0, AG16*15) -> 1.5
I17: Tributary Condition and Impact | P17: {=VLOOKUP($J17:$J17,$R$1:$S$5,2,FALSE)} -> #N/A | X17: Channel and floodplain dynamics | Y17: =H44 -> 0 | Z17: D | AA17: i | AB17: i | AE17: =IF('Existing Conditions'!Z17="D",'Existing Conditions'!$AO$8,IF('Existing Conditions'!Z17="I",'Existing Conditions'!$AP$8,0)) -> 1 | AF17: =IF('Existing Conditions'!AA17="D",'Existing Conditions'!$AO$8,IF('Existing Conditions'!AA17="I",'Existing Conditions'!$AP$8,0)) -> 0.1 | AG17: =IF('Existing Conditions'!AB17="D",'Existing Conditions'!$AO$8,IF('Existing Conditions'!AB17="I",'Existing Conditions'!$AP$8,0)) -> 0.1 | AH17: =IF(OR(ISBLANK('Existing Conditions'!Z17),ISBLANK('Existing Conditions'!Y17)),NA(),'Existing Conditions'!$Y17)*AE17 -> 0 | AI17: =IF(OR(ISBLANK('Existing Conditions'!AA17),ISBLANK('Existing Conditions'!Y17)),NA(),'Existing Conditions'!$Y17)*AF17 -> 0 | AJ17: =IF(OR(ISBLANK('Existing Conditions'!AB17),ISBLANK('Existing Conditions'!Y17)),NA(),'Existing Conditions'!$Y17)*AG17 -> 0 | AK17: =IF(ISBLANK('Existing Conditions'!$Y$17), 0, AE17*15) -> 15 | AL17: =IF(ISBLANK('Existing Conditions'!$Y$17), 0, AF17*15) -> 1.5 | AM17: =IF(ISBLANK('Existing Conditions'!$Y$17), 0, AG17*15) -> 1.5
I18: Local runoff diversions | P18: {=VLOOKUP($J18:$J18,$R$1:$S$5,2,FALSE)} -> #N/A | X18: Sediment continuity | Y18: =H48 -> 0 | Z18: D | AA18: i | AB18: i | AE18: =IF('Existing Conditions'!Z18="D",'Existing Conditions'!$AO$8,IF('Existing Conditions'!Z18="I",'Existing Conditions'!$AP$8,0)) -> 1 | AF18: =IF('Existing Conditions'!AA18="D",'Existing Conditions'!$AO$8,IF('Existing Conditions'!AA18="I",'Existing Conditions'!$AP$8,0)) -> 0.1 | AG18: =IF('Existing Conditions'!AB18="D",'Existing Conditions'!$AO$8,IF('Existing Conditions'!AB18="I",'Existing Conditions'!$AP$8,0)) -> 0.1 | AH18: =IF(OR(ISBLANK('Existing Conditions'!Z18),ISBLANK('Existing Conditions'!Y18)),NA(),'Existing Conditions'!$Y18)*AE18 -> 0 | AI18: =IF(OR(ISBLANK('Existing Conditions'!AA18),ISBLANK('Existing Conditions'!Y18)),NA(),'Existing Conditions'!$Y18)*AF18 -> 0 | AJ18: =IF(OR(ISBLANK('Existing Conditions'!AB18),ISBLANK('Existing Conditions'!Y18)),NA(),'Existing Conditions'!$Y18)*AG18 -> 0 | AK18: =IF(ISBLANK('Existing Conditions'!$Y$18), 0, AE18*15) -> 15 | AL18: =IF(ISBLANK('Existing Conditions'!$Y$18), 0, AF18*15) -> 1.5 | AM18: =IF(ISBLANK('Existing Conditions'!$Y$18), 0, AG18*15) -> 1.5
I19: Road/highway drainage | P19: {=VLOOKUP($J19:$J19,$R$1:$S$5,2,FALSE)} -> #N/A | X19: Bed composition and bedform dynamics | Y19: =H52 -> 0 | Z19: D | AA19: i | AB19: i | AE19: =IF('Existing Conditions'!Z19="D",'Existing Conditions'!$AO$8,IF('Existing Conditions'!Z19="I",'Existing Conditions'!$AP$8,0)) -> 1 | AF19: =IF('Existing Conditions'!AA19="D",'Existing Conditions'!$AO$8,IF('Existing Conditions'!AA19="I",'Existing Conditions'!$AP$8,0)) -> 0.1 | AG19: =IF('Existing Conditions'!AB19="D",'Existing Conditions'!$AO$8,IF('Existing Conditions'!AB19="I",'Existing Conditions'!$AP$8,0)) -> 0.1 | AH19: =IF(OR(ISBLANK('Existing Conditions'!Z19),ISBLANK('Existing Conditions'!Y19)),NA(),'Existing Conditions'!$Y19)*AE19 -> 0 | AI19: =IF(OR(ISBLANK('Existing Conditions'!AA19),ISBLANK('Existing Conditions'!Y19)),NA(),'Existing Conditions'!$Y19)*AF19 -> 0 | AJ19: =IF(OR(ISBLANK('Existing Conditions'!AB19),ISBLANK('Existing Conditions'!Y19)),NA(),'Existing Conditions'!$Y19)*AG19 -> 0 | AK19: =IF(ISBLANK('Existing Conditions'!$Y$19), 0, AE19*15) -> 15 | AL19: =IF(ISBLANK('Existing Conditions'!$Y$19), 0, AF19*15) -> 1.5 | AM19: =IF(ISBLANK('Existing Conditions'!$Y$19), 0, AG19*15) -> 1.5
F20: Streamflow Regime | G20: =AVERAGEIF(P20:P23,"<>#N/A") -> #DIV/0! | I20: Flow Permanence | P20: {=VLOOKUP($J20:$J20,$R$1:$S$5,2,FALSE)} -> #N/A | W20: Physicochemistry | X20: Light and thermal regime | Y20: =H56 -> 0 | AA20: D | AB20: i | AE20: =IF('Existing Conditions'!Z20="D",'Existing Conditions'!$AO$8,IF('Existing Conditions'!Z20="I",'Existing Conditions'!$AP$8,0)) -> 0 | AF20: =IF('Existing Conditions'!AA20="D",'Existing Conditions'!$AO$8,IF('Existing Conditions'!AA20="I",'Existing Conditions'!$AP$8,0)) -> 1 | AG20: =IF('Existing Conditions'!AB20="D",'Existing Conditions'!$AO$8,IF('Existing Conditions'!AB20="I",'Existing Conditions'!$AP$8,0)) -> 0.1 | AH20: =IF(OR(ISBLANK('Existing Conditions'!Z20),ISBLANK('Existing Conditions'!Y20)),NA(),'Existing Conditions'!$Y20)*AE20 -> #N/A | AI20: =IF(OR(ISBLANK('Existing Conditions'!AA20),ISBLANK('Existing Conditions'!Y20)),NA(),'Existing Conditions'!$Y20)*AF20 -> 0 | AJ20: =IF(OR(ISBLANK('Existing Conditions'!AB20),ISBLANK('Existing Conditions'!Y20)),NA(),'Existing Conditions'!$Y20)*AG20 -> 0 | AK20: =IF(ISBLANK('Existing Conditions'!$Y$20), 0, AE20*15) -> 0 | AL20: =IF(ISBLANK('Existing Conditions'!$Y$20), 0, AF20*15) -> 15 | AM20: =IF(ISBLANK('Existing Conditions'!$Y$20), 0, AG20*15) -> 1.5
I21: Flow Statistics | P21: {=VLOOKUP($J21:$J21,$R$1:$S$5,2,FALSE)} -> #N/A | X21: Carbon processing | Y21: =H60 -> 0 | AA21: i | AB21: i | AE21: =IF('Existing Conditions'!Z21="D",'Existing Conditions'!$AO$8,IF('Existing Conditions'!Z21="I",'Existing Conditions'!$AP$8,0)) -> 0 | AF21: =IF('Existing Conditions'!AA21="D",'Existing Conditions'!$AO$8,IF('Existing Conditions'!AA21="I",'Existing Conditions'!$AP$8,0)) -> 0.1 | AG21: =IF('Existing Conditions'!AB21="D",'Existing Conditions'!$AO$8,IF('Existing Conditions'!AB21="I",'Existing Conditions'!$AP$8,0)) -> 0.1 | AH21: =IF(OR(ISBLANK('Existing Conditions'!Z21),ISBLANK('Existing Conditions'!Y21)),NA(),'Existing Conditions'!$Y21)*AE21 -> #N/A | AI21: =IF(OR(ISBLANK('Existing Conditions'!AA21),ISBLANK('Existing Conditions'!Y21)),NA(),'Existing Conditions'!$Y21)*AF21 -> 0 | AJ21: =IF(OR(ISBLANK('Existing Conditions'!AB21),ISBLANK('Existing Conditions'!Y21)),NA(),'Existing Conditions'!$Y21)*AG21 -> 0 | AK21: =IF(ISBLANK('Existing Conditions'!$Y$21), 0, AE21*15) -> 0 | AL21: =IF(ISBLANK('Existing Conditions'!$Y$21), 0, AF21*15) -> 1.5 | AM21: =IF(ISBLANK('Existing Conditions'!$Y$21), 0, AG21*15) -> 1.5
I22: Channel natural flow regime | P22: {=VLOOKUP($J22:$J22,$R$1:$S$5,2,FALSE)} -> #N/A | X22: Nutrient cycling | Y22: =H64 -> 0 | Z22: i | AA22: D | AB22: i | AE22: =IF('Existing Conditions'!Z22="D",'Existing Conditions'!$AO$8,IF('Existing Conditions'!Z22="I",'Existing Conditions'!$AP$8,0)) -> 0.1 | AF22: =IF('Existing Conditions'!AA22="D",'Existing Conditions'!$AO$8,IF('Existing Conditions'!AA22="I",'Existing Conditions'!$AP$8,0)) -> 1 | AG22: =IF('Existing Conditions'!AB22="D",'Existing Conditions'!$AO$8,IF('Existing Conditions'!AB22="I",'Existing Conditions'!$AP$8,0)) -> 0.1 | AH22: =IF(OR(ISBLANK('Existing Conditions'!Z22),ISBLANK('Existing Conditions'!Y22)),NA(),'Existing Conditions'!$Y22)*AE22 -> 0 | AI22: =IF(OR(ISBLANK('Existing Conditions'!AA22),ISBLANK('Existing Conditions'!Y22)),NA(),'Existing Conditions'!$Y22)*AF22 -> 0 | AJ22: =IF(OR(ISBLANK('Existing Conditions'!AB22),ISBLANK('Existing Conditions'!Y22)),NA(),'Existing Conditions'!$Y22)*AG22 -> 0 | AK22: =IF(ISBLANK('Existing Conditions'!$Y$22), 0, AE22*15) -> 1.5 | AL22: =IF(ISBLANK('Existing Conditions'!$Y$22), 0, AF22*15) -> 15 | AM22: =IF(ISBLANK('Existing Conditions'!$Y$22), 0, AG22*15) -> 1.5
I23: Artificial structures and inputs | P23: {=VLOOKUP($J23:$J23,$R$1:$S$5,2,FALSE)} -> #N/A | X23: Water and soil quality | Y23: =H68 -> 0 | Z23: i | AA23: D | AB23: i | AE23: =IF('Existing Conditions'!Z23="D",'Existing Conditions'!$AO$8,IF('Existing Conditions'!Z23="I",'Existing Conditions'!$AP$8,0)) -> 0.1 | AF23: =IF('Existing Conditions'!AA23="D",'Existing Conditions'!$AO$8,IF('Existing Conditions'!AA23="I",'Existing Conditions'!$AP$8,0)) -> 1 | AG23: =IF('Existing Conditions'!AB23="D",'Existing Conditions'!$AO$8,IF('Existing Conditions'!AB23="I",'Existing Conditions'!$AP$8,0)) -> 0.1 | AH23: =IF(OR(ISBLANK('Existing Conditions'!Z23),ISBLANK('Existing Conditions'!Y23)),NA(),'Existing Conditions'!$Y23)*AE23 -> 0 | AI23: =IF(OR(ISBLANK('Existing Conditions'!AA23),ISBLANK('Existing Conditions'!Y23)),NA(),'Existing Conditions'!$Y23)*AF23 -> 0 | AJ23: =IF(OR(ISBLANK('Existing Conditions'!AB23),ISBLANK('Existing Conditions'!Y23)),NA(),'Existing Conditions'!$Y23)*AG23 -> 0 | AK23: =IF(ISBLANK('Existing Conditions'!$Y$23), 0, AE23*15) -> 1.5 | AL23: =IF(ISBLANK('Existing Conditions'!$Y$23), 0, AF23*15) -> 15 | AM23: =IF(ISBLANK('Existing Conditions'!$Y$23), 0, AG23*15) -> 1.5
D24: Hydraulics | E24: =IF(AVERAGE(H24:H39)/15<0.4, "Non-Functioning", IF(AVERAGE(H24:H39)/15<0.7, "Functioning At-Risk", "Functioning")) -> #DIV/0! | F24: Low Flow and Baseflow Dynamics | G24: =AVERAGEIF(P24:P27,"<>#N/A") -> #DIV/0! | I24: Low flow velocity | P24: {=VLOOKUP($J24:$J24,$R$1:$S$5,2,FALSE)} -> #N/A | W24: Biology | X24: Habitat provision | Y24: =H72 -> 0 | AB24: D | AE24: =IF('Existing Conditions'!Z24="D",'Existing Conditions'!$AO$8,IF('Existing Conditions'!Z24="I",'Existing Conditions'!$AP$8,0)) -> 0 | AF24: =IF('Existing Conditions'!AA24="D",'Existing Conditions'!$AO$8,IF('Existing Conditions'!AA24="I",'Existing Conditions'!$AP$8,0)) -> 0 | AG24: =IF('Existing Conditions'!AB24="D",'Existing Conditions'!$AO$8,IF('Existing Conditions'!AB24="I",'Existing Conditions'!$AP$8,0)) -> 1 | AH24: =IF(OR(ISBLANK('Existing Conditions'!Z24),ISBLANK('Existing Conditions'!Y24)),NA(),'Existing Conditions'!$Y24)*AE24 -> #N/A | AI24: =IF(OR(ISBLANK('Existing Conditions'!AA24),ISBLANK('Existing Conditions'!Y24)),NA(),'Existing Conditions'!$Y24)*AF24 -> #N/A | AJ24: =IF(OR(ISBLANK('Existing Conditions'!AB24),ISBLANK('Existing Conditions'!Y24)),NA(),'Existing Conditions'!$Y24)*AG24 -> 0 | AK24: =IF(ISBLANK('Existing Conditions'!$Y$24), 0, AE24*15) -> 0 | AL24: =IF(ISBLANK('Existing Conditions'!$Y$24), 0, AF24*15) -> 0 | AM24: =IF(ISBLANK('Existing Conditions'!$Y$24), 0, AG24*15) -> 15
I25: Low flow depth | P25: {=VLOOKUP($J25:$J25,$R$1:$S$5,2,FALSE)} -> #N/A | X25: Population support | Y25: =H76 -> 0 | Z25: i | AA25: i | AB25: D | AE25: =IF('Existing Conditions'!Z25="D",'Existing Conditions'!$AO$8,IF('Existing Conditions'!Z25="I",'Existing Conditions'!$AP$8,0)) -> 0.1 | AF25: =IF('Existing Conditions'!AA25="D",'Existing Conditions'!$AO$8,IF('Existing Conditions'!AA25="I",'Existing Conditions'!$AP$8,0)) -> 0.1 | AG25: =IF('Existing Conditions'!AB25="D",'Existing Conditions'!$AO$8,IF('Existing Conditions'!AB25="I",'Existing Conditions'!$AP$8,0)) -> 1 | AH25: =IF(OR(ISBLANK('Existing Conditions'!Z25),ISBLANK('Existing Conditions'!Y25)),NA(),'Existing Conditions'!$Y25)*AE25 -> 0 | AI25: =IF(OR(ISBLANK('Existing Conditions'!AA25),ISBLANK('Existing Conditions'!Y25)),NA(),'Existing Conditions'!$Y25)*AF25 -> 0 | AJ25: =IF(OR(ISBLANK('Existing Conditions'!AB25),ISBLANK('Existing Conditions'!Y25)),NA(),'Existing Conditions'!$Y25)*AG25 -> 0 | AK25: =IF(ISBLANK('Existing Conditions'!$Y$25), 0, AE25*15) -> 1.5 | AL25: =IF(ISBLANK('Existing Conditions'!$Y$25), 0, AF25*15) -> 1.5 | AM25: =IF(ISBLANK('Existing Conditions'!$Y$25), 0, AG25*15) -> 15
I26: Longitudinal connectivity | P26: {=VLOOKUP($J26:$J26,$R$1:$S$5,2,FALSE)} -> #N/A | X26: Community dynamics | Y26: =H80 -> 0 | Z26: i | AA26: i | AB26: D | AE26: =IF('Existing Conditions'!Z26="D",'Existing Conditions'!$AO$8,IF('Existing Conditions'!Z26="I",'Existing Conditions'!$AP$8,0)) -> 0.1 | AF26: =IF('Existing Conditions'!AA26="D",'Existing Conditions'!$AO$8,IF('Existing Conditions'!AA26="I",'Existing Conditions'!$AP$8,0)) -> 0.1 | AG26: =IF('Existing Conditions'!AB26="D",'Existing Conditions'!$AO$8,IF('Existing Conditions'!AB26="I",'Existing Conditions'!$AP$8,0)) -> 1 | AH26: =IF(OR(ISBLANK('Existing Conditions'!Z26),ISBLANK('Existing Conditions'!Y26)),NA(),'Existing Conditions'!$Y26)*AE26 -> 0 | AI26: =IF(OR(ISBLANK('Existing Conditions'!AA26),ISBLANK('Existing Conditions'!Y26)),NA(),'Existing Conditions'!$Y26)*AF26 -> 0 | AJ26: =IF(OR(ISBLANK('Existing Conditions'!AB26),ISBLANK('Existing Conditions'!Y26)),NA(),'Existing Conditions'!$Y26)*AG26 -> 0 | AK26: =IF(ISBLANK('Existing Conditions'!$Y$26), 0, AE26*15) -> 1.5 | AL26: =IF(ISBLANK('Existing Conditions'!$Y$26), 0, AF26*15) -> 1.5 | AM26: =IF(ISBLANK('Existing Conditions'!$Y$26), 0, AG26*15) -> 15
I27: Lateral connectivity | P27: {=VLOOKUP($J27:$J27,$R$1:$S$5,2,FALSE)} -> #N/A | X27: Watershed connectivity | Y27: =H84 -> 0 | Z27: i | AB27: D | AE27: =IF('Existing Conditions'!Z27="D",'Existing Conditions'!$AO$8,IF('Existing Conditions'!Z27="I",'Existing Conditions'!$AP$8,0)) -> 0.1 | AF27: =IF('Existing Conditions'!AA27="D",'Existing Conditions'!$AO$8,IF('Existing Conditions'!AA27="I",'Existing Conditions'!$AP$8,0)) -> 0 | AG27: =IF('Existing Conditions'!AB27="D",'Existing Conditions'!$AO$8,IF('Existing Conditions'!AB27="I",'Existing Conditions'!$AP$8,0)) -> 1 | AH27: =IF(OR(ISBLANK('Existing Conditions'!Z27),ISBLANK('Existing Conditions'!Y27)),NA(),'Existing Conditions'!$Y27)*AE27 -> 0 | AI27: =IF(OR(ISBLANK('Existing Conditions'!AA27),ISBLANK('Existing Conditions'!Y27)),NA(),'Existing Conditions'!$Y27)*AF27 -> #N/A | AJ27: =IF(OR(ISBLANK('Existing Conditions'!AB27),ISBLANK('Existing Conditions'!Y27)),NA(),'Existing Conditions'!$Y27)*AG27 -> 0 | AK27: =IF(ISBLANK('Existing Conditions'!$Y$27), 0, AE27*15) -> 1.5 | AL27: =IF(ISBLANK('Existing Conditions'!$Y$27), 0, AF27*15) -> 0 | AM27: =IF(ISBLANK('Existing Conditions'!$Y$27), 0, AG27*15) -> 15
F28: High Flow Dynamics | G28: =AVERAGEIF(P28:P31,"<>#N/A") -> #DIV/0! | I28: Overbank Flow Frequency | P28: {=VLOOKUP($J28:$J28,$R$1:$S$5,2,FALSE)} -> #N/A | W28: Sub-index Scores | Z28: ='Existing Conditions'!AH28 -> 0 | AA28: ='Existing Conditions'!AI28 -> 0 | AB28: ='Existing Conditions'!AJ28 -> 0 | AE28: =SUM(AE8:AE27) -> 10.7 | AF28: =SUM(AF8:AF27) -> 4.5 | AG28: =SUM(AG8:AG27) -> 5.5 | AH28: =SUMIF(AH8:AH27,"<>#N/A")/AK28 -> 0 | AI28: =SUMIF(AI8:AI27,"<>#N/A")/AL28 -> 0 | AJ28: =SUMIF(AJ8:AJ27,"<>#N/A")/AM28 -> 0 | AK28: =SUM(AK8:AK27) -> 160.5 | AL28: =SUM(AL8:AL27) -> 67.5 | AM28: =SUM(AM8:AM27) -> 82.5
I29: Peak Flow Capacity (Morphological) | P29: {=VLOOKUP($J29:$J29,$R$1:$S$5,2,FALSE)} -> #N/A | W29: SFARI Index | Z29: =AVERAGE(Z28:AB28) -> 0
I30: Peak Flow Capacity (Velocity/Shear) | P30: {=VLOOKUP($J30:$J30,$R$1:$S$5,2,FALSE)} -> #N/A
I31: Bed Mobilization Frequency | P31: {=VLOOKUP($J31:$J31,$R$1:$S$5,2,FALSE)} -> #N/A
F32: Floodplain Connectivity | G32: =AVERAGEIF(P32:P35,"<>#N/A") -> #DIV/0! | I32: Floodplain Complexity | P32: {=VLOOKUP($J32:$J32,$R$1:$S$5,2,FALSE)} -> #N/A
I33: Entrenchment Ratio (ER) | P33: {=VLOOKUP($J33:$J33,$R$1:$S$5,2,FALSE)} -> #N/A
I34: Channel Condition | P34: {=VLOOKUP($J34:$J34,$R$1:$S$5,2,FALSE)} -> #N/A
I35: Lateral Floodplain inundation | P35: {=VLOOKUP($J35:$J35,$R$1:$S$5,2,FALSE)} -> #N/A
F36: Hyporheic Connectivity | G36: =AVERAGEIF(P36:P39,"<>#N/A") -> #DIV/0! | I36: Channel Complexity for Exchange | P36: {=VLOOKUP($J36:$J36,$R$1:$S$5,2,FALSE)} -> #N/A
I37: Floodplain Permeability | P37: {=VLOOKUP($J37:$J37,$R$1:$S$5,2,FALSE)} -> #N/A
I38: Bed Surface Grain Size | P38: {=VLOOKUP($J38:$J38,$R$1:$S$5,2,FALSE)} -> #N/A
I39: Visible Hyporheic Metrics | P39: {=VLOOKUP($J39:$J39,$R$1:$S$5,2,FALSE)} -> #N/A
D40: Geomorphology | E40: =IF(AVERAGE(H40:H55)/15<0.4, "Non-Functioning", IF(AVERAGE(H40:H55)/15<0.7, "Functioning At-Risk", "Functioning")) -> #DIV/0! | F40: Channel Evolution | G40: =AVERAGEIF(P40:P43,"<>#N/A") -> #DIV/0! | I40: Channel Evolution | P40: {=VLOOKUP($J40:$J40,$R$1:$S$5,2,FALSE)} -> #N/A
...

Sheet ReferenceCurves
A1: Reference curves
A2: SFARI rates metrics on a Likert scale; these are its criteria.
A4: Likert scores
A5: Likert | B5: Score
A6: Strongly Agree | B6: 14
A7: Agree | B7: 11
A8: Neutral | B8: 8
A9: Disagree | B9: 5
A10: Strongly Disagree | B10: 2
A11: Not Applicable | B11: Not counted
A14: Scoring criteria
A15: Function | B15: Metric | C15: Strongly Agree | D15: Agree | E15: Neutral | F15: Disagree | G15: Strongly Disagree
A16: Catchment hydrology | B16: Impervious surface area | C16: < 5% impervious | D16: ~5–10% impervious | F16: 10–20% impervious | G16: >20% impervious
A17: Catchment hydrology | B17: Road density | C17: <0.5 km roads/km² | D17: ~0.5–1.0 km/km² | F17: 1–2 km/km² | G17: >2 km/km²
A18: Catchment hydrology | B18: Land use change | C18: <5% area converted (e.g., 2001–2019) | D18: 5–15% converted | F18: ~15–30% converted | G18: ≥30% converted
A19: Catchment hydrology | B19: Impoundments | C19: None or negligible influence | D19: 1–2 small dams, partial influence | F19: Multiple moderate dams affecting peaks/baseflow | G19: Heavily regulated system
A20: Surface water storage | B20: Wetland Coverage | C20: High (>5% of floodplain area) | D20: Moderate (~2–5%) | F20: Low (~1–2%) | G20: Very low (<1%)
A21: Surface water storage | B21: Floodplain Water Retention | C21: Floodplain engages at ~1–2 yr or 2–5 yr events | D21: Overbanking requires slightly larger than bankfull but not rare | F21: Overbanking mainly at ~5–10 yr events. Partial disconnection | G21: Rarely or never overbanking below ~10-yr events. Incision or levees present
A22: Surface water storage | B22: In-channel Ponding / Beaver | C22: Present where expected. Enhance baseflow and habitat. Minimal fragmentation | D22: One to two small obstructions. Minor impacts | F22: Multiple ponds that moderately disrupt longitudinal connectivity | G22: Widespread channel fragmentation or overabundant ponding
A23: Surface water storage | B23: Off-channel Storage | C23: Multiple features connect during moderate (~bankfull) floods | D23: Partial connection or few off-channel areas | F23: Only large floods (>5–10 yr) access these areas | G23: Off-channel features mostly gone or permanently cut off
A24: Reach inflow | B24: Concentrated flow inputs | C24: 0–1 | D24: 2–3 | F24: 4–5 | G24: >5
A25: Reach inflow | B25: Tributary condition and impact | C25: Mostly natural tributaries with stable flows and typical sediment loads | D25: One or two moderately altered tributaries with occasional elevated turbidity | F25: Multiple majorly altered tributaries with frequent sediment plumes | G25: Widespread severely altered tributaries or severe pollution at many confluences
A26: Reach inflow | B26: Local runoff diversions | C26: No notable withdrawals or returns | D26: Minor ditches or returns with limited effect | F26: Moderate diversions or large returns that cause seasonal stress | G26: Large or chronic diversions or major returns that alter the flow regime
A27: Reach inflow | B27: Road/highway drainage | C27: 0–1 | D27: 2–3 | F27: 4–5 | G27: ≥5 or a major highway outfall
... A95: Watershed connectivity | B95: Dewatered or Intermittent Segments | C95: No artificial dryness. Natural connectivity is maintained. | D95: Minor dryness in small segments. | F95: Notable dryness or disconnection in key reaches. | G95: Chronic or large-scale dewatering. Major fragmentation.
A98: Suggested ratings from desktop values
A99: Metric | B99: Direction | C99: Strongly Agree | D99: Agree | E99: Disagree | F99: Strongly Disagree
A100: Impervious surface area | B100: Lower is better | C100: below 5 | D100: below 10 | E100: below 20 | F100: otherwise
A101: catchment-hydrology-agricultural-cover | B101: Lower is better | C101: below 15 | D101: below 25 | E101: below 50 | F101: otherwise
A102: Road density | B102: Lower is better | C102: below 0.5 | D102: below 1 | E102: below 2 | F102: otherwise
A103: Wetland Coverage | B103: Higher is better | C103: at least 5 | D103: at least 2 | E103: at least 1 | F103: otherwise
A104: Riparian Canopy Cover | B104: Higher is better | C104: at least 75 | D104: at least 50 | E104: at least 25 | F104: otherwise
A105: Riparian Corridor Width and Quality | B105: Higher is better | C105: at least 60 | D105: at least 40 | E105: at least 20 | F105: otherwise
A106: Vegetated Riparian Corridor Width | B106: Higher is better | C106: at least 60 | D106: at least 40 | E106: at least 20 | F106: otherwise
A107: Riparian communities | B107: Higher is better | C107: at least 60 | D107: at least 40 | E107: at least 20 | F107: otherwise
A108: Suggestions only: the assessor's Likert rating is what scores.

Sheet Sheet1
G19: Condition Index | H19: Variable Scoring
D20: Functioning | G20: 1 | H20: 15
H21: 14
H22: 13
H23: 12
G24: 0.7 | H24: 11
D25: Functioning At-Risk | H25: 10
H26: 9
H27: 8
H28: 7
G29: 0.4 | H29: 6
D30: Non-Functioning | H30: 5
H31: 4
H32: 3
H33: 2
H34: 1
G35: 0 | H35: 0

Sheet REFI Multiple Score
A14: Riparian Zone Ecological Function Index (REFI) Worksheet | N14: Optional Automated Scoring | Q14: Strongly Agree | S14: Both | T14: 2
A15: Reach | I15: Columns for Multiple Score Reach | N15: Strongly Agree | O15: 14 | Q15: Somewhat Agree | S15: Left | T15: 1
A16: Lat/Long | H16: Score ID | N16: Somewhat Agree | O16: 11 | Q16: Neutral | S16: Right | T16: 1
A17: Date | H17: River Bank (Both / Left / Right) | N17: Neutral | O17: 8 | Q17: Somewhat Disagree
A18: Assessor | H18: Score Length | N18: Somewhat Disagree | O18: 5 | Q18: Strongly Disagree | S18: Length | T18: =IFERROR(SUMIF(_xlfn.ANCHORARRAY(R20),"<>#N/A"),NA()) -> 0
A19: Overall | B19: Outcomes | D19: Categories | F19: Variable | H19: Indicators | N19: Strongly Disagree | O19: 2 | Q19: NA
A20: Index Score | B20: Name | C20: Index Score | D20: Name | E20: Index Score | F20: Name | G20: Score | H20: Name | I20: Likert Scale Score | J20: Likert Scale Score | K20: Likert Scale Score | L20: Likert Scale Score | N20: Variable Score | O20: Indicator | R20: {=IF(NOT($I$18:$L$18=0),$I$18:$L$18*(VLOOKUP($I$17:$L$17,$S$14:$T$16,2,FALSE)),NA())} -> #N/A | S20: #N/A | T20: #N/A | U20: #N/A
Q21: Subtotal
A22: =AVERAGE(C22:C56) -> #DIV/0! | B22: Instream functions | C22: =AVERAGE(E22:E40) -> #DIV/0! | D22: Physical Processes | E22: =AVERAGE(G22:G33) -> #DIV/0! | F22: Upland Runoff | H22: Direct Runoff | N22: =AVERAGEIF(O22:O25,"<>#N/A") -> #DIV/0! | O22: =IF($Q22>=1,$Q22,NA()) -> #N/A | Q22: =IFERROR(SUMIF(_xlfn.ANCHORARRAY(R22),"<>#N/A"),NA()) -> 0 | R22: {=VLOOKUP($I22:$L22,$N$15:$O$19,2,FALSE)*(_xlfn.ANCHORARRAY($R$20)/$T$18)} -> #N/A | S22: #N/A | T22: #N/A | U22: #N/A
H23: Bypassing Flows | O23: =IF($Q23>=1,$Q23,NA()) -> #N/A | Q23: =IFERROR(SUMIF(_xlfn.ANCHORARRAY(R23),"<>#N/A"),NA()) -> 0 | R23: {=VLOOKUP($I23:$L23,$N$15:$O$19,2,FALSE)*(_xlfn.ANCHORARRAY($R$20)/$T$18)} -> #N/A | S23: #N/A | T23: #N/A | U23: #N/A
H24: Floodplain Slope
H25: Runoff Pollution | O25: =IF($Q25>=1,$Q25,NA()) -> #N/A | Q25: =IFERROR(SUMIF(_xlfn.ANCHORARRAY(R25),"<>#N/A"),NA()) -> 0 | R25: {=VLOOKUP($I25:$L25,$N$15:$O$19,2,FALSE)*(_xlfn.ANCHORARRAY($R$20)/$T$18)} -> #N/A | S25: #N/A | T25: #N/A | U25: #N/A
F26: Hydrologic Connection | H26: Floodplain Connectivity | N26: =AVERAGEIF(O26:O29,"<>#N/A") -> #DIV/0! | O26: =IF($Q26>=1,$Q26,NA()) -> #N/A | Q26: =IFERROR(SUMIF(_xlfn.ANCHORARRAY(R26),"<>#N/A"),NA()) -> 0 | R26: {=VLOOKUP($I26:$L26,$N$15:$O$19,2,FALSE)*(_xlfn.ANCHORARRAY($R$20)/$T$18)} -> #N/A | S26: #N/A | T26: #N/A | U26: #N/A
H27: Floodplain Roughness | O27: =IF($Q27>=1,$Q27,NA()) -> #N/A | Q27: =IFERROR(SUMIF(_xlfn.ANCHORARRAY(R27),"<>#N/A"),NA()) -> 0 | R27: {=VLOOKUP($I27:$L27,$N$15:$O$19,2,FALSE)*(_xlfn.ANCHORARRAY($R$20)/$T$18)} -> #N/A | S27: #N/A | T27: #N/A | U27: #N/A
H28: Flood Storage
H29: Instream Hydrology | O29: =IF($Q29>=1,$Q29,NA()) -> #N/A | Q29: =IFERROR(SUMIF(_xlfn.ANCHORARRAY(R29),"<>#N/A"),NA()) -> 0 | R29: {=VLOOKUP($I29:$L29,$N$15:$O$19,2,FALSE)*(_xlfn.ANCHORARRAY($R$20)/$T$18)} -> #N/A | S29: #N/A | T29: #N/A | U29: #N/A
F30: Streamflow Processes | H30: Erosion Potential | N30: =AVERAGEIF(O30:O33,"<>#N/A") -> #DIV/0! | O30: =IF($Q30>=1,$Q30,NA()) -> #N/A | Q30: =IFERROR(SUMIF(_xlfn.ANCHORARRAY(R30),"<>#N/A"),NA()) -> 0 | R30: {=VLOOKUP($I30:$L30,$N$15:$O$19,2,FALSE)*(_xlfn.ANCHORARRAY($R$20)/$T$18)} -> #N/A | S30: #N/A | T30: #N/A | U30: #N/A
H31: Reach Erosion | O31: =IF($Q31>=1,$Q31,NA()) -> #N/A | Q31: =IFERROR(SUMIF(_xlfn.ANCHORARRAY(R31),"<>#N/A"),NA()) -> 0 | R31: {=VLOOKUP($I31:$L31,$N$15:$O$19,2,FALSE)*(_xlfn.ANCHORARRAY($R$20)/$T$18)} -> #N/A | S31: #N/A | T31: #N/A | U31: #N/A
H32: Channel Evolution
H33: Sediment Supply | O33: =IF($Q33>=1,$Q33,NA()) -> #N/A | Q33: =IFERROR(SUMIF(_xlfn.ANCHORARRAY(R33),"<>#N/A"),NA()) -> 0 | R33: {=VLOOKUP($I33:$L33,$N$15:$O$19,2,FALSE)*(_xlfn.ANCHORARRAY($R$20)/$T$18)} -> #N/A | S33: #N/A | T33: #N/A | U33: #N/A
D34: Biogeochemical Processes | E34: =AVERAGE(G34:G40) -> #DIV/0! | F34: Energy Sources and Biogeochemical Processes | H34: Carbon Sources | N34: =AVERAGEIF(O34:O37,"<>#N/A") -> #DIV/0! | O34: =IF($Q34>=1,$Q34,NA()) -> #N/A | Q34: =IFERROR(SUMIF(_xlfn.ANCHORARRAY(R34),"<>#N/A"),NA()) -> 0 | R34: {=VLOOKUP($I34:$L34,$N$15:$O$19,2,FALSE)*(_xlfn.ANCHORARRAY($R$20)/$T$18)} -> #N/A | S34: #N/A | T34: #N/A | U34: #N/A
H35: Root Zone | O35: =IF($Q35>=1,$Q35,NA()) -> #N/A | Q35: =IFERROR(SUMIF(_xlfn.ANCHORARRAY(R35),"<>#N/A"),NA()) -> 0 | R35: {=VLOOKUP($I35:$L35,$N$15:$O$19,2,FALSE)*(_xlfn.ANCHORARRAY($R$20)/$T$18)} -> #N/A | S35: #N/A | T35: #N/A | U35: #N/A
H36: Soil Suitability
H37: Mobilizing Flows | O37: =IF($Q37>=1,$Q37,NA()) -> #N/A | Q37: =IFERROR(SUMIF(_xlfn.ANCHORARRAY(R37),"<>#N/A"),NA()) -> 0 | R37: {=VLOOKUP($I37:$L37,$N$15:$O$19,2,FALSE)*(_xlfn.ANCHORARRAY($R$20)/$T$18)} -> #N/A | S37: #N/A | T37: #N/A | U37: #N/A
F38: Riparian Filtering | H38: Buffer Width | N38: =AVERAGEIF(O38:O40,"<>#N/A") -> #DIV/0! | O38: =IF($Q38>=1,$Q38,NA()) -> #N/A | Q38: =IFERROR(SUMIF(_xlfn.ANCHORARRAY(R38),"<>#N/A"),NA()) -> 0 | R38: {=VLOOKUP($I38:$L38,$N$15:$O$19,2,FALSE)*(_xlfn.ANCHORARRAY($R$20)/$T$18)} -> #N/A | S38: #N/A | T38: #N/A | U38: #N/A
H39: Buffer Density | O39: =IF($Q39>=1,$Q39,NA()) -> #N/A | Q39: =IFERROR(SUMIF(_xlfn.ANCHORARRAY(R39),"<>#N/A"),NA()) -> 0 | R39: {=VLOOKUP($I39:$L39,$N$15:$O$19,2,FALSE)*(_xlfn.ANCHORARRAY($R$20)/$T$18)} -> #N/A | S39: #N/A | T39: #N/A | U39: #N/A
H40: Ground Cover | O40: =IF($Q40>=1,$Q40,NA()) -> #N/A | Q40: =IFERROR(SUMIF(_xlfn.ANCHORARRAY(R40),"<>#N/A"),NA()) -> 0 | R40: {=VLOOKUP($I40:$L40,$N$15:$O$19,2,FALSE)*(_xlfn.ANCHORARRAY($R$20)/$T$18)} -> #N/A | S40: #N/A | T40: #N/A | U40: #N/A
B41: Ecological Connectivity | C41: =AVERAGE(E41:E45) -> #DIV/0! | D41: Lateral | E41: =AVERAGE(G41:G43) -> #DIV/0! | F41: Lateral Disturbance | H41: Adjacent Land Use | N41: =AVERAGEIF(O41:O43,"<>#N/A") -> #DIV/0! | O41: =IF($Q41>=1,$Q41,NA()) -> #N/A | Q41: =IFERROR(SUMIF(_xlfn.ANCHORARRAY(R41),"<>#N/A"),NA()) -> 0 | R41: {=VLOOKUP($I41:$L41,$N$15:$O$19,2,FALSE)*(_xlfn.ANCHORARRAY($R$20)/$T$18)} -> #N/A | S41: #N/A | T41: #N/A | U41: #N/A
H42: Average Buffer Width | O42: =IF($Q42>=1,$Q42,NA()) -> #N/A | Q42: =IFERROR(SUMIF(_xlfn.ANCHORARRAY(R42),"<>#N/A"),NA()) -> 0 | R42: {=VLOOKUP($I42:$L42,$N$15:$O$19,2,FALSE)*(_xlfn.ANCHORARRAY($R$20)/$T$18)} -> #N/A | S42: #N/A | T42: #N/A | U42: #N/A
H43: Distance from Buffer | O43: =IF($Q43>=1,$Q43,NA()) -> #N/A | Q43: =IFERROR(SUMIF(_xlfn.ANCHORARRAY(R43),"<>#N/A"),NA()) -> 0 | R43: {=VLOOKUP($I43:$L43,$N$15:$O$19,2,FALSE)*(_xlfn.ANCHORARRAY($R$20)/$T$18)} -> #N/A | S43: #N/A | T43: #N/A | U43: #N/A
D44: Longitudinal | E44: =AVERAGE(G44:G45) -> #DIV/0! | F44: Longitudinal Movement and Habitat | H44: Corridor Movement | N44: =AVERAGEIF(O44:O45,"<>#N/A") -> #DIV/0! | O44: =IF($Q44>=1,$Q44,NA()) -> #N/A | Q44: =IFERROR(SUMIF(_xlfn.ANCHORARRAY(R44),"<>#N/A"),NA()) -> 0 | R44: {=VLOOKUP($I44:$L44,$N$15:$O$19,2,FALSE)*(_xlfn.ANCHORARRAY($R$20)/$T$18)} -> #N/A | S44: #N/A | T44: #N/A | U44: #N/A
H45: Habitat Interspersion | O45: =IF($Q45>=1,$Q45,NA()) -> #N/A | Q45: =IFERROR(SUMIF(_xlfn.ANCHORARRAY(R45),"<>#N/A"),NA()) -> 0 | R45: {=VLOOKUP($I45:$L45,$N$15:$O$19,2,FALSE)*(_xlfn.ANCHORARRAY($R$20)/$T$18)} -> #N/A | S45: #N/A | T45: #N/A | U45: #N/A
B46: Unique and Important Habitats | C46: =(E46*0.75)+(E54*0.25) -> 3.5 | D46: Terrestrial | E46: =AVERAGEIF(G46:G53,"<>#N/A")/15 -> 0.33333333 | F46: Plant Community | G46: 5 | H46: Riparian Extent Vegetation | N46: =AVERAGEIF(O46:O47,"<>#N/A") -> #DIV/0! | O46: =IF($Q46>=1,$Q46,NA()) -> #N/A | Q46: =IFERROR(SUMIF(_xlfn.ANCHORARRAY(R46),"<>#N/A"),NA()) -> 0 | R46: {=VLOOKUP($I46:$L46,$N$15:$O$19,2,FALSE)*(_xlfn.ANCHORARRAY($R$20)/$T$18)} -> #N/A | S46: #N/A | T46: #N/A | U46: #N/A
H47: Invasive/Non-Native Species | O47: =IF($Q47>=1,$Q47,NA()) -> #N/A | Q47: =IFERROR(SUMIF(_xlfn.ANCHORARRAY(R47),"<>#N/A"),NA()) -> 0 | R47: {=VLOOKUP($I47:$L47,$N$15:$O$19,2,FALSE)*(_xlfn.ANCHORARRAY($R$20)/$T$18)} -> #N/A | S47: #N/A | T47: #N/A | U47: #N/A
F48: Canopy Habitat | G48: =NA() -> #N/A | H48: Vertical Structural Diversity | N48: =AVERAGEIF(O48:O49,"<>#N/A") -> #DIV/0! | O48: =IF($Q48>=1,$Q48,NA()) -> #N/A | Q48: =IFERROR(SUMIF(_xlfn.ANCHORARRAY(R48),"<>#N/A"),NA()) -> 0 | R48: {=VLOOKUP($I48:$L48,$N$15:$O$19,2,FALSE)*(_xlfn.ANCHORARRAY($R$20)/$T$18)} -> #N/A | S48: #N/A | T48: #N/A | U48: #N/A
H49: Horizontal Structural Diversity | O49: =IF($Q49>=1,$Q49,NA()) -> #N/A | Q49: =IFERROR(SUMIF(_xlfn.ANCHORARRAY(R49),"<>#N/A"),NA()) -> 0 | R49: {=VLOOKUP($I49:$L49,$N$15:$O$19,2,FALSE)*(_xlfn.ANCHORARRAY($R$20)/$T$18)} -> #N/A | S49: #N/A | T49: #N/A | U49: #N/A
F50: Understory Habitat | G50: =NA() -> #N/A | H50: Tree Size Class Diversity | N50: =AVERAGEIF(O50:O51,"<>#N/A") -> #DIV/0! | O50: =IF($Q50>=1,$Q50,NA()) -> #N/A | Q50: =IFERROR(SUMIF(_xlfn.ANCHORARRAY(R50),"<>#N/A"),NA()) -> 0 | R50: {=VLOOKUP($I50:$L50,$N$15:$O$19,2,FALSE)*(_xlfn.ANCHORARRAY($R$20)/$T$18)} -> #N/A | S50: #N/A | T50: #N/A | U50: #N/A
H51: Snag Density | O51: =IF($Q51>=1,$Q51,NA()) -> #N/A | Q51: =IFERROR(SUMIF(_xlfn.ANCHORARRAY(R51),"<>#N/A"),NA()) -> 0 | R51: {=VLOOKUP($I51:$L51,$N$15:$O$19,2,FALSE)*(_xlfn.ANCHORARRAY($R$20)/$T$18)} -> #N/A | S51: #N/A | T51: #N/A | U51: #N/A
F52: Forest Floor Habitat | G52: 5 | H52: Detritus Cover | N52: =AVERAGEIF(O52:O53,"<>#N/A") -> #DIV/0! | O52: =IF($Q52>=1,$Q52,NA()) -> #N/A | Q52: =IFERROR(SUMIF(_xlfn.ANCHORARRAY(R52),"<>#N/A"),NA()) -> 0 | R52: {=VLOOKUP($I52:$L52,$N$15:$O$19,2,FALSE)*(_xlfn.ANCHORARRAY($R$20)/$T$18)} -> #N/A | S52: #N/A | T52: #N/A | U52: #N/A
H53: Terrestrial Vegetation Contribution | O53: =IF($Q53>=1,$Q53,NA()) -> #N/A | Q53: =IFERROR(SUMIF(_xlfn.ANCHORARRAY(R53),"<>#N/A"),NA()) -> 0 | R53: {=VLOOKUP($I53:$L53,$N$15:$O$19,2,FALSE)*(_xlfn.ANCHORARRAY($R$20)/$T$18)} -> #N/A | S53: #N/A | T53: #N/A | U53: #N/A
...

Sheet Global
B2: For Index Value Type | E2: Measurement Types | G2: Categories | I2: Riparian Classification
B3: 0 | C3: Poor: LL | E3: Numeric | G3: Good | I3: Forested
B4: 0.29 | C4: Poor: UL | E4: Categorical | G4: Fair | I4: Scrub-shrub
B5: 0.3 | C5: Fair: LL | G5: Poor | I5: Herbacious
B6: 0.69 | C6: Fair: UL
B7: 0.7 | C7: Good: LL
B8: 1 | C8: Good: UL
