Workbook
Name curve_keys: 'Reference'!$A$58:$A$91
Name curve_x1: 'Reference'!$G$58:$G$91
Name curve_y1: 'Reference'!$L$58:$L$91
Name curve_x2: 'Reference'!$H$58:$H$91
Name curve_y2: 'Reference'!$M$58:$M$91
Name curve_x3: 'Reference'!$I$58:$I$91
Name curve_y3: 'Reference'!$N$58:$N$91
Name curve_x4: 'Reference'!$J$58:$J$91
Name curve_y4: 'Reference'!$O$58:$O$91
Name curve_x5: 'Reference'!$K$58:$K$91
Name curve_y5: 'Reference'!$P$58:$P$91
Name curve_x39: 'Reference'!$T$58:$T$91
Name curve_x69: 'Reference'!$U$58:$U$91
Name anchor_good: 'Reference'!$B$102
Name score_good: 'Reference'!$C$102
Name anchor_fair: 'Reference'!$B$103
Name score_fair: 'Reference'!$C$103
Name anchor_poor: 'Reference'!$B$104
Name score_poor: 'Reference'!$C$104
Name nutrient_regions: 'Reference'!$A$186:$A$194
Name nutrient_tn_gf: 'Reference'!$B$186:$B$194
Name nutrient_tn_fp: 'Reference'!$C$186:$C$194
Name nutrient_tp_gf: 'Reference'!$D$186:$D$194
Name nutrient_tp_fp: 'Reference'!$E$186:$E$194
Name attains_keys: 'Reference'!$A$198:$A$204
Name attains_ratings: 'Reference'!$B$198:$B$204
Name site_name: 'Scenario'!$B$2
Name site_assessor: 'Scenario'!$G$2
Name site_comid: 'Scenario'!$K$2
Name site_coords: 'Scenario'!$B$3
Name site_date: 'Scenario'!$G$3
Name ctx_region: 'Scenario'!$K$3
Name ctx_fcode: 'Scenario'!$B$4
Name ctx_slope_override: 'Scenario'!$G$4
Name calc_slope_class: 'Scenario'!$K$4
Name in_impervious: 'Scenario'!$J$8
Name in_agriculture: 'Scenario'!$J$9
Name ov_m01_rating: 'Scenario'!$J$10
Name in_woodyWetland: 'Scenario'!$J$11
Name in_herbaceousWetland: 'Scenario'!$J$12
Name ov_m02_rating: 'Scenario'!$J$14
Name in_roadDensity: 'Scenario'!$J$15
Name ov_m03_rating: 'Scenario'!$J$16
Name in_storage: 'Scenario'!$J$17
Name in_runoff: 'Scenario'!$J$18
Name ov_m04_rating: 'Scenario'!$J$20
Name in_flowCv: 'Scenario'!$J$21
Name ov_m05_rating: 'Scenario'!$J$22
Name in_bhr: 'Scenario'!$J$23
Name ov_m06_rating: 'Scenario'!$J$24
Name in_er: 'Scenario'!$J$25
Name in_slope: 'Scenario'!$J$26
Name ov_m07_rating: 'Scenario'!$J$27
Name in_sinuosity: 'Scenario'!$J$29
Name ov_m08_rating: 'Scenario'!$J$30
Name ov_stageClass: 'Scenario'!$J$33
Name ov_indicators: 'Scenario'!$J$34
Name ov_m09_rating: 'Scenario'!$J$35
Name ov_erodingBankPct: 'Scenario'!$J$37
Name ov_armoredBankPct: 'Scenario'!$J$38

Sheet Instructions
A1: Model Name | B1: Ecosystem Assessment Screening Index (EASI) | I1: Color Coding Key:
A2: Developers | B2: Leanne M. Stepchinski, Gabrielle C. David, Samantha R. Wiest, and Garrett T. Menichino | I2: User Input
B3: U.S. Army Engineer Research and Development Center, Environmental Laboratory | I3: Calculated
B4: Vicksburg, MS | I4: Linked to Another Cell
B5: Leanne.M.Stepchinski@usace.army.mil, Gabrielle.C.David@usace.army.mil, Samantha.R.Wiest@erdc.dren.mil, Garrett.T.Menichino@usace.army.mil | I5: Override Score Row
I6: Protect/unprotect password:
A7: Model Version | B7: EASI v1.0 | I7: easi
A8: Date of Last Update | B8: 46318
A10: Waiver | B10: This model is provided for free as part of the USACE Technical Report "Ecosystem Assessment Screening Index (EASI)" by Leanne M. Stepchinski, Gabrielle C. David, Samantha R. Wiest, and Garrett T. Menichino.
B11: None of the authors nor the US Army Corps of Engineers accepts responsibility or liability for the model's use by third parties.
A15: Instructions | D15: EASI Index Scoring | G15: Function Scoring | I15: Rating to Function Score
A16: 1) | B16: Add the site information into the orange cells at the top of each scenario worksheet. | D16: 1.0 | E16: Functioning | G16: 15 | H16: Functioning | I16: 13 Good (Functioning)
A17: 2) | B17: Enter each metric value in the orange cells of the Value column (column J). The Source column names where each value comes from, and selecting a cell shows its guidance note. Grey cells repeat a value entered higher in the table. | D17: 0.7 | G17: 11 | I17: 8 Fair (Functioning At-Risk)
A18: 3) | B18: Leave a cell blank when a value is unavailable, and never enter zero for an unknown value. A blank metric leaves its function unrated, and unrated functions drop out of the sub-indices and the EASI Index. | E18: Functioning At-Risk | G18: 10 | H18: Functioning At-Risk | I18: 3 Poor (Non-Functioning)
A19: 4) | B19: Optional. Pick an Override Score (Good, Fair or Poor) in the last row of a function to replace its computed rating, and enter observed channel and bank conditions in their rows when you have field observations. | D19: 0.4 | G19: 6 | I19: Not rated: left out of the sub-indices and the index
A20: 5) | B20: Once the metric values are entered, the ratings and Function Scores (columns G and H), the Functional Categories, the Outcomes and the overall EASI Index (column A) will auto-populate. The scoring summary table and the bar charts to the right of the table will also auto-populate. | E20: Non-Functioning | G20: 5 | H20: Non-Functioning
A21: 6) | B21: Record other metrics, notes, or sources in the grey box at the bottom of the worksheet. | D21: 0.0 | G21: 0
A23: Comments/Assumptions
A24: 1) | B24: The calculator scores exactly as the EASI web application does, with the same criteria, reference curves, weights and rounding. The same inputs give the same ratings, Function Scores, sub-indices and EASI Index.
A25: 2) | B25: The Metrics sheet shows how each rating was reached, beside the Good, Fair and Poor ranges of every metric. The Reference sheet plots the reference curves and holds the tables the calculator reads. Nothing is entered on either sheet.
A26: 3) | B26: The optional monthly flow helper below the table computes the monthly flow variability from the twelve EROM mean monthly flows. Copy its result into the Low flow and baseflow dynamics row.
A27: 4) | B27: Derived values are rounded to twelve decimals before they are rated, and displayed indices to two decimals, as in the web application. When a sub-index lands exactly on a half-hundredth, Excel rounds away from zero and the web application rounds to the even digit, so a displayed value can differ by 0.01 while the class stays the same.
A28: 5) | B28: The calculator does not retrieve data, delineate a watershed or draw cross-sections. An Override Score replaces the computed rating and score of its function, as a rating changed in the web application does, and the Metrics sheet keeps the computed rating beside it.
A29: 6) | B29: EASI is a screening-level desktop estimate, not a field-validated assessment. The reference curves express regional expectations derived from least-disturbed reaches, and several proxies remain unvalidated. The technical report states each metric's limitations.

Sheet Summary
A1: EASI assessment summary
A3: Reach name | B3: =IF(ISBLANK(Scenario!B2),"",Scenario!B2)
A4: Assessment tier | B4: Screening
A5: Reach length
A6: Drainage area
A7: Stream order (Strahler)
A8: NARS-9 region | B8: =IF(ISBLANK(Scenario!K3),"",Scenario!K3)
A9: EPA Level I ecoregion
A10: EPA Level II ecoregion
A11: EPA Level III ecoregion
A13: Scores
B14: Scenario
A15: Index
A16: ECI | B16: =IF(ISNUMBER(Results!$D$30),Results!$D$30,"")
A17: Physical | B17: =IF(ISNUMBER(Results!$D$27),Results!$D$27,"")
A18: Chemical | B18: =IF(ISNUMBER(Results!$D$28),Results!$D$28,"")
A19: Biological | B19: =IF(ISNUMBER(Results!$D$29),Results!$D$29,"")
A20: Hydrology
A21: Catchment hydrology | B21: =IF(ISNUMBER(Metrics!$B$13),Metrics!$B$13,"")
A22: Surface water storage | B22: =IF(ISNUMBER(Metrics!$B$25),Metrics!$B$25,"")
A23: Reach inflow | B23: =IF(ISNUMBER(Metrics!$B$35),Metrics!$B$35,"")
A24: Streamflow regime | B24: =IF(ISNUMBER(Metrics!$B$47),Metrics!$B$47,"")
A25: Hydraulics
A26: Low flow and baseflow dynamics | B26: =IF(ISNUMBER(Metrics!$B$60),Metrics!$B$60,"")
A27: High flow dynamics | B27: =IF(ISNUMBER(Metrics!$B$70),Metrics!$B$70,"")
A28: Floodplain connectivity | B28: =IF(ISNUMBER(Metrics!$B$82),Metrics!$B$82,"")
A29: Hyporheic connectivity | B29: =IF(ISNUMBER(Metrics!$B$95),Metrics!$B$95,"")
A30: Geomorphology
A31: Channel evolution | B31: =IF(ISNUMBER(Metrics!$B$109),Metrics!$B$109,"")
A32: Channel and floodplain dynamics | B32: =IF(ISNUMBER(Metrics!$B$121),Metrics!$B$121,"")
A33: Sediment continuity | B33: =IF(ISNUMBER(Metrics!$B$135),Metrics!$B$135,"")
A34: Bed composition and large wood | B34: =IF(ISNUMBER(Metrics!$B$145),Metrics!$B$145,"")
A35: Physicochemistry
A36: Light & thermal regime | B36: =IF(ISNUMBER(Metrics!$B$160),Metrics!$B$160,"")
A37: Carbon processing | B37: =IF(ISNUMBER(Metrics!$B$176),Metrics!$B$176,"")
A38: Nutrient cycling | B38: =IF(ISNUMBER(Metrics!$B$188),Metrics!$B$188,"")
A39: Water & soil quality | B39: =IF(ISNUMBER(Metrics!$B$199),Metrics!$B$199,"")
A40: Biology
A41: Habitat provision | B41: =IF(ISNUMBER(Metrics!$B$212),Metrics!$B$212,"")
A42: Population support | B42: =IF(ISNUMBER(Metrics!$B$225),Metrics!$B$225,"")
...

Sheet Scenario
A1: Ecosystem Assessment Screening Index (EASI) Worksheet
A2: Reach ID | F2: Assessor(s) | J2: COMID
A3: Lat/Long | F3: Date | J3: NARS-9 region
A4: NHD FCODE | F4: Slope class override | J4: Slope class used | K4: =IF('Scenario'!$G$4<>"",'Scenario'!$G$4,IF(NOT(ISNUMBER('Scenario'!$J$26)),"national",IF('Scenario'!$J$26<0,"national",IF('Scenario'!$J$26<0.005,"lt_0.5",IF('Scenario'!$J$26<0.02,"0.5_to_2","ge_2")))))
A5: EASI | B5: Outcomes | D5: Functional Categories | F5: Functions | I5: Metrics | O5: Scoring Summary | R5: Outcomes | V5: EASI Index Scoring | Y5: Function Scoring
A6: Index Score | B6: Name | C6: Sub-Index Score | D6: Name | E6: Functions Rated | F6: Name | G6: Rating | H6: Function Score | I6: Name | J6: Value | K6: Units | L6: Input Rating | M6: Source | O6: Functional Categories | P6: Functions | Q6: Score | R6: Physical | S6: Chemical | T6: Biological | V6: 1.00 | W6: Functioning | Y6: 15 | Z6: Functioning
A8: =IF('Results'!$E$30="","",'Results'!$E$30) | B8: Physical | C8: =IF('Results'!$E$27="","",'Results'!$E$27) | D8: Hydrology | E8: =COUNT('Scenario'!$H$8:$H$20) | F8: Catchment hydrology | G8: ='Metrics'!$F$12 | H8: ='Metrics'!$B$13 | I8: Impervious cover of the watershed | K8: % | L8: ='Metrics'!$F$5 | M8: StreamCat pctimp2019ws | O8: Hydrology | P8: Catchment hydrology | Q8: =IF('Scenario'!$H$8="","",'Scenario'!$H$8) | R8: D | S8: i | T8: i | V8: 0.70 | Y8: 11
I9: Agricultural cover of the watershed (crop, hay and pasture) | K9: % | L9: ='Metrics'!$F$6 | M9: StreamCat pctcrop2019ws + pcthay2019ws | P9: Surface water storage | Q9: =IF('Scenario'!$H$11="","",'Scenario'!$H$11) | R9: D | S9: i | T9: i | W9: Functioning At-Risk | Y9: 10 | Z9: Functioning At-Risk
I10: Override Score (Optional) | M10: User-defined override | P10: Reach inflow | Q10: =IF('Scenario'!$H$15="","",'Scenario'!$H$15) | R10: D | S10: i | T10: i
F11: Surface water storage | G11: ='Metrics'!$F$24 | H11: ='Metrics'!$B$25 | I11: Woody wetland cover of the watershed | K11: % | M11: StreamCat pctwdwet2019ws | P11: Streamflow regime | Q11: =IF('Scenario'!$H$17="","",'Scenario'!$H$17) | R11: D | S11: i | T11: i | V11: 0.40 | Y11: 6
I12: Herbaceous wetland cover of the watershed | K12: % | M12: StreamCat pcthbwet2019ws | O12: Hydraulics | P12: Low flow and baseflow dynamics | Q12: =IF('Scenario'!$H$21="","",'Scenario'!$H$21) | R12: D | S12: i | T12: i | W12: Non-Functioning | Y12: 5 | Z12: Non-Functioning
I13: Wetland extent (sum, capped at 100) | J13: =IF('Metrics'!$B$20="","",'Metrics'!$B$20) | K13: % | L13: ='Metrics'!$F$22 | M13: Computed from the entries above | P13: High flow dynamics | Q13: =IF('Scenario'!$H$23="","",'Scenario'!$H$23) | R13: D | S13: i | T13: i
I14: Override Score (Optional) | M14: User-defined override | P14: Floodplain connectivity | Q14: =IF('Scenario'!$H$25="","",'Scenario'!$H$25) | R14: D | S14: i | T14: i | V14: 0.00 | Y14: 0
F15: Reach inflow | G15: ='Metrics'!$F$34 | H15: ='Metrics'!$B$35 | I15: Road density of the watershed | K15: km/km2 | L15: ='Metrics'!$F$32 | M15: StreamCat rddensws | P15: Hyporheic connectivity | Q15: =IF('Scenario'!$H$28="","",'Scenario'!$H$28) | R15: D | S15: i | T15: i
I16: Override Score (Optional) | M16: User-defined override | O16: Geomorphology | P16: Channel evolution | Q16: =IF('Scenario'!$H$31="","",'Scenario'!$H$31) | R16: D | S16: i | T16: i
F17: Streamflow regime | G17: ='Metrics'!$F$46 | H17: ='Metrics'!$B$47 | I17: Normalized dam storage upstream | K17: m3/km2 | M17: StreamCat damnrmstorws | P17: Channel and floodplain dynamics | Q17: =IF('Scenario'!$H$36="","",'Scenario'!$H$36) | R17: D | S17: i | T17: i | V17: Rating to Function Score
I18: Mean annual runoff of the watershed | K18: mm | M18: StreamCat runoffws | P18: Sediment continuity | Q18: =IF('Scenario'!$H$40="","",'Scenario'!$H$40) | R18: D | S18: i | T18: i | V18: Rating | Y18: Score
I19: Degree of regulation | J19: =IF('Metrics'!$B$42="","",'Metrics'!$B$42) | K19: % | L19: ='Metrics'!$F$44 | M19: Computed from the entries above | P19: Bed composition and large wood | Q19: =IF('Scenario'!$H$44="","",'Scenario'!$H$44) | R19: D | S19: i | T19: i | V19: Good (Functioning) | Y19: ='Reference'!$C$102
I20: Override Score (Optional) | M20: User-defined override | O20: Physicochemistry | P20: Light & thermal regime | Q20: =IF('Scenario'!$H$46="","",'Scenario'!$H$46) | S20: D | T20: i | V20: Fair (Functioning At-Risk) | Y20: ='Reference'!$C$103
D21: Hydraulics | E21: =COUNT('Scenario'!$H$21:$H$30) | F21: Low flow and baseflow dynamics | G21: ='Metrics'!$F$59 | H21: ='Metrics'!$B$60 | I21: Monthly flow variability (CV of the twelve EROM monthly flows) | K21: ratio | L21: ='Metrics'!$F$57 | M21: NHDPlus V2 EROM QE_01 to QE_12, or the helper below | P21: Carbon processing | Q21: =IF('Scenario'!$H$49="","",'Scenario'!$H$49) | S21: D | T21: i | V21: Poor (Non-Functioning) | Y21: ='Reference'!$C$104
I22: Override Score (Optional) | M22: User-defined override | P22: Nutrient cycling | Q22: =IF('Scenario'!$H$55="","",'Scenario'!$H$55) | R22: i | S22: D | T22: i | V22: Not rated (blank input) | Y22: excluded from the rollup
F23: High flow dynamics | G23: ='Metrics'!$F$69 | H23: ='Metrics'!$B$70 | I23: Bank-height ratio (reach median) | K23: ratio | L23: ='Metrics'!$F$67 | M23: EASI report cross-section block or a field survey | P23: Water & soil quality | Q23: =IF('Scenario'!$H$60="","",'Scenario'!$H$60) | R23: i | S23: D | T23: i
I24: Override Score (Optional) | M24: User-defined override | O24: Biology | P24: Habitat provision | Q24: =IF('Scenario'!$H$64="","",'Scenario'!$H$64) | T24: D
F25: Floodplain connectivity | G25: ='Metrics'!$F$81 | H25: ='Metrics'!$B$82 | I25: Entrenchment ratio (reach median) | K25: ratio | L25: ='Metrics'!$F$79 | M25: EASI report cross-section block or a field survey | P25: Population support | Q25: =IF('Scenario'!$H$66="","",'Scenario'!$H$66) | R25: i | S25: i | T25: D
I26: Channel slope | K26: m/m | M26: NHDPlus V2 VAA slope | P26: Community dynamics | Q26: =IF('Scenario'!$H$82="","",'Scenario'!$H$82) | R26: i | S26: i | T26: D
I27: Override Score (Optional) | M27: User-defined override | P27: Watershed connectivity | Q27: =IF('Scenario'!$H$84="","",'Scenario'!$H$84) | R27: i | T27: D
F28: Hyporheic connectivity | G28: ='Metrics'!$F$94 | H28: ='Metrics'!$B$95 | I28: Channel slope | J28: =IF('Scenario'!$J$26="","",'Scenario'!$J$26) | K28: m/m | L28: ='Metrics'!$F$87 | M28: NHDPlus V2 VAA slope | O28: Sub-index Scores | R28: =IF('Results'!$E$27="","",'Results'!$E$27) | S28: =IF('Results'!$E$28="","",'Results'!$E$28) | T28: =IF('Results'!$E$29="","",'Results'!$E$29)
I29: Reach sinuosity | K29: ratio | L29: ='Metrics'!$F$88 | M29: Reach geometry (channel length over straight-line length) | O29: EASI Index | R29: =IF('Results'!$E$30="","",'Results'!$E$30)
I30: Override Score (Optional) | M30: User-defined override | O30: Functions rated | R30: ='Results'!$B$33
D31: Geomorphology | E31: =COUNT('Scenario'!$H$31:$H$45) | F31: Channel evolution | G31: ='Metrics'!$F$108 | H31: ='Metrics'!$B$109 | I31: Bank-height ratio (reach median) | J31: =IF('Scenario'!$J$23="","",'Scenario'!$J$23) | K31: ratio | L31: ='Metrics'!$F$100 | M31: EASI report cross-section block or a field survey | O31: Coverage | R31: ='Results'!$B$37
I32: Entrenchment ratio (reach median) | J32: =IF('Scenario'!$J$25="","",'Scenario'!$J$25) | K32: ratio | L32: ='Metrics'!$F$103 | M32: EASI report cross-section block or a field survey | O32: Provisional result | R32: =IF('Results'!$B$36="yes","yes (coverage below 0.70)","no")
I33: Observed channel-evolution class (optional) | M33: Field assessment or verified imagery
I34: Observed channel-evolution indicators (note) (optional) | M34: Field assessment or verified imagery
I35: Override Score (Optional) | M35: User-defined override
F36: Channel and floodplain dynamics | G36: ='Metrics'!$F$120 | H36: ='Metrics'!$B$121 | I36: Bank-height ratio (reach median) | J36: =IF('Scenario'!$J$23="","",'Scenario'!$J$23) | K36: ratio | M36: EASI report cross-section block or a field survey
I37: Observed eroding bank (optional) | K37: % | L37: ='Metrics'!$F$115 | M37: Field assessment or verified imagery
I38: Observed armored bank (optional) | K38: % | L38: ='Metrics'!$F$116 | M38: Field assessment or verified imagery
I39: Override Score (Optional) | M39: User-defined override
F40: Sediment continuity | G40: ='Metrics'!$F$134 | H40: ='Metrics'!$B$135 | I40: Agricultural cover of the watershed (crop, hay and pasture) | J40: =IF('Scenario'!$J$9="","",'Scenario'!$J$9) | K40: % | L40: ='Metrics'!$F$126 | M40: StreamCat pctcrop2019ws + pcthay2019ws
I41: Soil erodibility (K factor) of the watershed | L41: ='Metrics'!$F$127 | M41: StreamCat kffactws
...

Sheet Metrics
A1: EASI calculator: metric scoring | C1: **DO NOT INPUT VALUES HERE**
A3: 1. Catchment hydrology | B3: Catchment hydrology (land-cover pressure) (catchment-land-cover-pressure, worst_index)
A4: Item | B4: Value | C4: Good | D4: Fair | E4: Poor | F4: Rating | G4: Index | H4: Note
A5: Watershed impervious cover | B5: =IF('Scenario'!$J$8="","",'Scenario'!$J$8) | C5: <10% | D5: 10-25% | E5: >25% | F5: =IF(NOT(ISNUMBER('Scenario'!$J$8)),"",IF('Scenario'!$J$8<10,"Good",IF(AND('Scenario'!$J$8>=10,'Scenario'!$J$8<=25),"Fair",IF('Scenario'!$J$8>25,"Poor","")))) | G5: =IF('Metrics'!$F$5="Good",'Reference'!$B$102,IF('Metrics'!$F$5="Fair",'Reference'!$B$103,IF('Metrics'!$F$5="Poor",'Reference'!$B$104,"")))
A6: Watershed agricultural cover | B6: =IF('Scenario'!$J$9="","",'Scenario'!$J$9) | C6: <30% | D6: 30-50% | E6: >50% | F6: =IF(NOT(ISNUMBER('Scenario'!$J$9)),"",IF('Scenario'!$J$9<30,"Good",IF(AND('Scenario'!$J$9>=30,'Scenario'!$J$9<=50),"Fair",IF('Scenario'!$J$9>50,"Poor","")))) | G6: =IF('Metrics'!$F$6="Good",'Reference'!$B$102,IF('Metrics'!$F$6="Fair",'Reference'!$B$103,IF('Metrics'!$F$6="Poor",'Reference'!$B$104,"")))
A7: Governing input | B7: =IF('Metrics'!$B$8="","",INDEX('Metrics'!$A$5:$A$6,MATCH('Metrics'!$B$8,'Metrics'!$G$5:$G$6,0)))
A8: Combined rating index (the more limiting input) | B8: =IF(COUNT('Metrics'!$G$5:$G$6)=0,"",MIN('Metrics'!$G$5:$G$6))
A9: Route that applied | B9: =IF(OR('Scenario'!$J$10="Good",'Scenario'!$J$10="Fair",'Scenario'!$J$10="Poor"),"override score","automatic method")
A10: Computed rating (before the override score) | F10: =IF(NOT(ISNUMBER('Metrics'!$B$8)),"",IF('Metrics'!$B$8='Reference'!$B$102,"Good",IF('Metrics'!$B$8='Reference'!$B$103,"Fair",IF('Metrics'!$B$8='Reference'!$B$104,"Poor",""))))
A11: Override score (optional entry on the Scenario sheet) | B11: =IF('Scenario'!$J$10="","",'Scenario'!$J$10) | H11: Replaces the computed rating, as a rating changed in the web application does.
A12: Function rating | F12: =IF(OR('Scenario'!$J$10="Good",'Scenario'!$J$10="Fair",'Scenario'!$J$10="Poor"),'Scenario'!$J$10,'Metrics'!$F$10) | G12: =IF('Metrics'!$F$12="Good",'Reference'!$B$102,IF('Metrics'!$F$12="Fair",'Reference'!$B$103,IF('Metrics'!$F$12="Poor",'Reference'!$B$104,""))) | H12: Partial rating allowed when one input is missing.
A13: Function score (0 to 15) | B13: =IF('Metrics'!$F$12="Good",'Reference'!$C$102,IF('Metrics'!$F$12="Fair",'Reference'!$C$103,IF('Metrics'!$F$12="Poor",'Reference'!$C$104,"")))
A14: Status | B14: =IF(OR('Scenario'!$J$10="Good",'Scenario'!$J$10="Fair",'Scenario'!$J$10="Poor"),"override score",IF(COUNT('Metrics'!$G$5:$G$6)=0,"not rated",IF(COUNT('Metrics'!$G$5:$G$6)<2,"partial","complete")))
A16: 2. Surface water storage | B16: Wetland extent (watershed-wetland-extent, sum_capped)
A17: Item | B17: Value | C17: Good | D17: Fair | E17: Poor | F17: Rating | G17: Index | H17: Note
A18: Woody wetland cover | B18: =IF('Scenario'!$J$11="","",'Scenario'!$J$11)
A19: Herbaceous wetland cover | B19: =IF('Scenario'!$J$12="","",'Scenario'!$J$12)
A20: Combined value (sum capped at 100) | B20: =IF(AND(ISNUMBER('Scenario'!$J$11),ISNUMBER('Scenario'!$J$12)),ROUND(MIN('Scenario'!$J$11+'Scenario'!$J$12,100),12),"") | C20: >5% | D20: 1-5% | E20: <1%
A21: Route that applied | B21: =IF(OR('Scenario'!$J$14="Good",'Scenario'!$J$14="Fair",'Scenario'!$J$14="Poor"),"override score","automatic method")
A22: Computed rating (before the override score) | F22: =IF(NOT(ISNUMBER('Metrics'!$B$20)),"",IF('Metrics'!$B$20<1,"Poor",IF(AND('Metrics'!$B$20>=1,'Metrics'!$B$20<=5),"Fair",IF('Metrics'!$B$20>5,"Good",""))))
A23: Override score (optional entry on the Scenario sheet) | B23: =IF('Scenario'!$J$14="","",'Scenario'!$J$14) | H23: Replaces the computed rating, as a rating changed in the web application does.
A24: Function rating | F24: =IF(OR('Scenario'!$J$14="Good",'Scenario'!$J$14="Fair",'Scenario'!$J$14="Poor"),'Scenario'!$J$14,'Metrics'!$F$22) | G24: =IF('Metrics'!$F$24="Good",'Reference'!$B$102,IF('Metrics'!$F$24="Fair",'Reference'!$B$103,IF('Metrics'!$F$24="Poor",'Reference'!$B$104,""))) | H24: All classes are required. A missing class is unknown, not zero.
A25: Function score (0 to 15) | B25: =IF('Metrics'!$F$24="Good",'Reference'!$C$102,IF('Metrics'!$F$24="Fair",'Reference'!$C$103,IF('Metrics'!$F$24="Poor",'Reference'!$C$104,"")))
A26: Status | B26: =IF(OR('Scenario'!$J$14="Good",'Scenario'!$J$14="Fair",'Scenario'!$J$14="Poor"),"override score",IF('Metrics'!$F$24="","not rated","complete"))
A28: 3. Reach inflow | B28: Road-density proxy for concentrated inflow pressure (road-density-inflow-pressure, threshold)
A29: Item | B29: Value | C29: Good | D29: Fair | E29: Poor | F29: Rating | G29: Index | H29: Note
A30: Watershed road density | B30: =IF('Scenario'!$J$15="","",'Scenario'!$J$15) | C30: <1 km/km² | D30: 1-<3 km/km² | E30: ≥3 km/km²
A31: Route that applied | B31: =IF(OR('Scenario'!$J$16="Good",'Scenario'!$J$16="Fair",'Scenario'!$J$16="Poor"),"override score","automatic method")
A32: Computed rating (before the override score) | F32: =IF(NOT(ISNUMBER('Scenario'!$J$15)),"",IF('Scenario'!$J$15<1,"Good",IF(AND('Scenario'!$J$15>=1,'Scenario'!$J$15<3),"Fair",IF('Scenario'!$J$15>=3,"Poor",""))))
A33: Override score (optional entry on the Scenario sheet) | B33: =IF('Scenario'!$J$16="","",'Scenario'!$J$16) | H33: Replaces the computed rating, as a rating changed in the web application does.
A34: Function rating | F34: =IF(OR('Scenario'!$J$16="Good",'Scenario'!$J$16="Fair",'Scenario'!$J$16="Poor"),'Scenario'!$J$16,'Metrics'!$F$32) | G34: =IF('Metrics'!$F$34="Good",'Reference'!$B$102,IF('Metrics'!$F$34="Fair",'Reference'!$B$103,IF('Metrics'!$F$34="Poor",'Reference'!$B$104,"")))
A35: Function score (0 to 15) | B35: =IF('Metrics'!$F$34="Good",'Reference'!$C$102,IF('Metrics'!$F$34="Fair",'Reference'!$C$103,IF('Metrics'!$F$34="Poor",'Reference'!$C$104,"")))
A36: Status | B36: =IF(OR('Scenario'!$J$16="Good",'Scenario'!$J$16="Fair",'Scenario'!$J$16="Poor"),"override score",IF('Metrics'!$F$34="","not rated","complete"))
A38: 4. Streamflow regime | B38: Flow alteration (degree of regulation) (degree-of-regulation, ratio)
A39: Item | B39: Value | C39: Good | D39: Fair | E39: Poor | F39: Rating | G39: Index | H39: Note
A40: Upstream normalized storage | B40: =IF('Scenario'!$J$17="","",'Scenario'!$J$17)
A41: Annual runoff | B41: =IF('Scenario'!$J$18="","",'Scenario'!$J$18)
A42: Degree of regulation (%) | B42: =IF(AND(ISNUMBER('Scenario'!$J$17),ISNUMBER('Scenario'!$J$18),'Scenario'!$J$18<>0,'Scenario'!$J$18>0),ROUND((100*'Scenario'!$J$17)/(1000*'Scenario'!$J$18),12),"") | C42: <2% | D42: 2-15% | E42: >15%
A43: Route that applied | B43: =IF(OR('Scenario'!$J$20="Good",'Scenario'!$J$20="Fair",'Scenario'!$J$20="Poor"),"override score","automatic method")
A44: Computed rating (before the override score) | F44: =IF(NOT(ISNUMBER('Metrics'!$B$42)),"",IF('Metrics'!$B$42<2,"Good",IF(AND('Metrics'!$B$42>=2,'Metrics'!$B$42<=15),"Fair",IF('Metrics'!$B$42>15,"Poor",""))))
...

Sheet Reference
A1: Reference tables generated from the EASI scoring definitions | F1: **DO NOT INPUT VALUES HERE**
A3: Reference curves
A4: Each line is the curve of one NARS-9 region or slope class. A value scores the index of its curve: Good at 0.69 and above, Fair at 0.39 and above, Poor below. The Good, Fair and Poor ranges of every curve are in the table under the charts.
A56: Reference curves (frozen), one row per curve, knots padded to five
A57: Key | B57: Set | C57: Stratum | D57: Higher is better | E57: n | F57: Members | G57: x1 | H57: x2 | I57: x3 | J57: x4 | K57: x5 | L57: y1 | M57: y2 | N57: y3 | O57: y4 | P57: y5 | Q57: Good | R57: Fair | S57: Poor | T57: x39 | U57: x69 | V57: q25 | W57: q50 | X57: q75 | Y57: Tier
A58: corridor-natural|CPL | B58: corridor-natural | C58: CPL | D58: TRUE | E58: 6106 | F58: 6130 | G58: 0 | H58: 39.775713 | I58: 92.809998 | J58: 99.220001 | K58: 100 | L58: 0 | M58: 0.3 | N58: 0.7 | O58: 1 | P58: 1 | Q58: ≥91.5% | R58: 51.7-<91.5% | S58: <51.7% | T58: 51.708427 | U58: 91.48414 | V58: 92.809998 | W58: 96.949997 | X58: 99.220001 | Y58: complete
A59: corridor-natural|NAP | B59: corridor-natural | C59: NAP | D59: TRUE | E59: 3002 | F59: 3005 | G59: 0 | H59: 38.549999 | I59: 89.949997 | J59: 98.457499 | K59: 100 | L59: 0 | M59: 0.3 | N59: 0.7 | O59: 1 | P59: 1 | Q59: ≥88.7% | R59: 50.1-<88.7% | S59: <50.1% | T59: 50.114998 | U59: 88.664997 | V59: 89.949997 | W59: 95.244999 | X59: 98.457499 | Y59: complete
A60: corridor-natural|NPL | B60: corridor-natural | C60: NPL | D60: TRUE | E60: 4318 | F60: 4319 | G60: 0 | H60: 41.7225 | I60: 97.352499 | J60: 100 | K60: 100 | L60: 0 | M60: 0.3 | N60: 0.7 | O60: 1 | P60: 1 | Q60: ≥96% | R60: 54.2-<96% | S60: <54.2% | T60: 54.239249 | U60: 95.961749 | V60: 97.352499 | W60: 99.580002 | X60: 100 | Y60: complete
A61: corridor-natural|SAP | B61: corridor-natural | C61: SAP | D61: TRUE | E61: 6246 | F61: 6246 | G61: 0 | H61: 37.654286 | I61: 87.860001 | J61: 99.099998 | K61: 100 | L61: 0 | M61: 0.3 | N61: 0.7 | O61: 1 | P61: 1 | Q61: ≥86.6% | R61: 49-<86.6% | S61: <49% | T61: 48.950572 | U61: 86.604858 | V61: 87.860001 | W61: 95.190002 | X61: 99.099998 | Y61: complete
A62: corridor-natural|SPL | B62: corridor-natural | C62: SPL | D62: TRUE | E62: 5959 | F62: 5960 | G62: 0 | H62: 41.138571 | I62: 95.989998 | J62: 99.949997 | K62: 100 | L62: 0 | M62: 0.3 | N62: 0.7 | O62: 1 | P62: 1 | Q62: ≥94.6% | R62: 53.5-<94.6% | S62: <53.5% | T62: 53.480142 | U62: 94.618712 | V62: 95.989998 | W62: 98.639999 | X62: 99.949997 | Y62: complete
A63: corridor-natural|TPL | B63: corridor-natural | C63: TPL | D63: TRUE | E63: 870 | F63: 874 | G63: 0 | H63: 38.562858 | I63: 89.980001 | J63: 98.800003 | K63: 100 | L63: 0 | M63: 0.3 | N63: 0.7 | O63: 1 | P63: 1 | Q63: ≥88.7% | R63: 50.1-<88.7% | S63: <50.1% | T63: 50.131715 | U63: 88.694573 | V63: 89.980001 | W63: 95.25 | X63: 98.800003 | Y63: complete
A64: corridor-natural|UMW | B64: corridor-natural | C64: UMW | D64: TRUE | E64: 2431 | F64: 2432 | G64: 0 | H64: 39.462856 | I64: 92.079998 | J64: 98.514999 | K64: 100 | L64: 0 | M64: 0.3 | N64: 0.7 | O64: 1 | P64: 1 | Q64: ≥90.8% | R64: 51.3-<90.8% | S64: <51.3% | T64: 51.301713 | U64: 90.764569 | V64: 92.079998 | W64: 96.190002 | X64: 98.514999 | Y64: complete
A65: corridor-natural|WMT | B65: corridor-natural | C65: WMT | D65: TRUE | E65: 12592 | F65: 12592 | G65: 0 | H65: 41.807144 | I65: 97.550003 | J65: 100 | K65: 100 | L65: 0 | M65: 0.3 | N65: 0.7 | O65: 1 | P65: 1 | Q65: ≥96.2% | R65: 54.3-<96.2% | S65: <54.3% | T65: 54.349287 | U65: 96.156432 | V65: 97.550003 | W65: 99.900002 | X65: 100 | Y65: complete
A66: corridor-natural|XER | B66: corridor-natural | C66: XER | D66: TRUE | E66: 14653 | F66: 14654 | G66: 0 | H66: 41.952857 | I66: 97.889999 | J66: 100 | K66: 100 | L66: 0 | M66: 0.3 | N66: 0.7 | O66: 1 | P66: 1 | Q66: ≥96.5% | R66: 54.5-<96.5% | S66: <54.5% | T66: 54.538714 | U66: 96.491571 | V66: 97.889999 | W66: 99.879997 | X66: 100 | Y66: complete
A67: corridor-natural|national | B67: corridor-natural | C67: national | D67: TRUE | E67: 53175 | F67: 53210 | G67: 0 | H67: 40.675716 | I67: 94.910004 | J67: 100 | K67: 100 | L67: 0 | M67: 0.3 | N67: 0.7 | O67: 1 | P67: 1 | Q67: ≥93.6% | R67: 52.9-<93.6% | S67: <52.9% | T67: 52.878431 | U67: 93.554146 | V67: 94.910004 | W67: 98.870003 | X67: 100 | Y67: complete
A68: corridor-woody|CPL | B68: corridor-woody | C68: CPL | D68: TRUE | E68: 6106 | F68: 6130 | G68: 0 | H68: 35.38607 | I68: 82.567497 | J68: 97.227503 | K68: 100 | L68: 0 | M68: 0.3 | N68: 0.7 | O68: 1 | P68: 1 | Q68: ≥81.4% | R68: 46-<81.4% | S68: <46% | T68: 46.001891 | U68: 81.387962 | V68: 82.567497 | W68: 92.5 | X68: 97.227503 | Y68: complete
A69: corridor-woody|NAP | B69: corridor-woody | C69: NAP | D69: TRUE | E69: 3002 | F69: 3005 | G69: 0 | H69: 36.962142 | I69: 86.244999 | J69: 96.647501 | K69: 99.768252 | L69: 0 | M69: 0.3 | N69: 0.7 | O69: 1 | P69: 1 | Q69: ≥85% | R69: 48.1-<85% | S69: <48.1% | T69: 48.050785 | U69: 85.012928 | V69: 86.244999 | W69: 92.514999 | X69: 96.647501 | Y69: complete
... A91: flow-variability|national | B91: flow-variability | C91: national | D91: FALSE | E91: 53197 | F91: 53210 | G91: 0.38078 | H91: 0.630809 | I91: 1.464239 | J91: 2.575479 | K91: 3.408909 | L91: 1 | M91: 1 | N91: 0.7 | O91: 0.3 | P91: 0 | Q91: ≤1.49 | R91: >1.49-≤2.33 | S91: >2.33 | T91: 2.32545 | U91: 1.49202 | V91: 0.630809 | W91: 1.00673 | X91: 1.464239 | Y91: complete
A93: Rating lines of the curve charts
A94: Set | B94: Value from | C94: Value to | D94: Index 0.39 | E94: Index 0.39 | F94: Index 0.69 | G94: Index 0.69
A95: corridor-natural | B95: 0 | C95: 100 | D95: 0.39 | E95: 0.39 | F95: 0.69 | G95: 0.69
A96: corridor-woody | B96: 0 | C96: 100 | D96: 0.39 | E96: 0.39 | F96: 0.69 | G96: 0.69
A97: entrenchment | B97: 0 | C97: 2.94425 | D97: 0.39 | E97: 0.39 | F97: 0.69 | G97: 0.69
A98: flow-variability | B98: 0.293031 | C98: 5.201354 | D98: 0.39 | E98: 0.39 | F98: 0.69 | G98: 0.69
A100: Rating anchors and function scores
A101: Rating | B101: Index anchor | C101: Function score | D101: Score class
A102: Good | B102: 0.85 | C102: 13 | D102: Functioning
A103: Fair | B103: 0.545 | C103: 8 | D103: Functioning-at-Risk
A104: Poor | B104: 0.195 | C104: 3 | D104: Non-Functioning
A106: Condition classes
A107: Index at or below | B107: Class | C107: Function score at or below
A108: 0.39 | B108: Non-Functioning | C108: 5
A109: 0.69 | B109: Functioning-at-Risk | C109: 10
A110: 1 | B110: Functioning | C110: 15
A112: Fixed bands per input (informational; the Metrics formulas carry the same tests)
A113: Method | B113: Input | C113: Rating | D113: Min | E113: Min inclusive | F113: Max | G113: Max inclusive | H113: Label
A114: catchment-land-cover-pressure | B114: impervious | C114: Good | E114: FALSE | F114: 10 | G114: FALSE | H114: <10%
A115: catchment-land-cover-pressure | B115: impervious | C115: Fair | D115: 10 | E115: TRUE | F115: 25 | G115: TRUE | H115: 10-25%
A116: catchment-land-cover-pressure | B116: impervious | C116: Poor | D116: 25 | E116: FALSE | G116: FALSE | H116: >25%
A117: catchment-land-cover-pressure | B117: agriculture | C117: Good | E117: FALSE | F117: 30 | G117: FALSE | H117: <30%
...

Sheet Results
A1: EASI calculator: results
A2: Engine sheet (hidden). Function scores, outcome sub-indices and the Ecosystem Condition Index, computed with the STAF rollup: unrated functions leave both the numerator and the denominator. The Scenario sheet displays these cells.
A4: Function | B4: Discipline | C4: Metric | D4: Rating | E4: Score | F4: Class | G4: Physical | H4: Chemical | I4: Biological | J4: Score or 0 | K4: Rated | L4: Route
A5: Catchment hydrology | B5: Hydrology | C5: Watershed Land-Cover Pressure | D5: ='Metrics'!$F$12 | E5: ='Metrics'!$B$13 | F5: =IF(NOT(ISNUMBER('Results'!$E$5)),"Not assessed",IF('Results'!$E$5<=5,"Non-Functioning",IF('Results'!$E$5<=10,"Functioning-at-Risk","Functioning"))) | G5: 1 | H5: 0.1 | I5: 0.1 | J5: =IF(ISNUMBER('Results'!$E$5),'Results'!$E$5,0) | K5: =IF(ISNUMBER('Results'!$E$5),1,0) | L5: ='Metrics'!$B$9
A6: Surface water storage | B6: Hydrology | C6: Percent Wetlands in Watershed | D6: ='Metrics'!$F$24 | E6: ='Metrics'!$B$25 | F6: =IF(NOT(ISNUMBER('Results'!$E$6)),"Not assessed",IF('Results'!$E$6<=5,"Non-Functioning",IF('Results'!$E$6<=10,"Functioning-at-Risk","Functioning"))) | G6: 1 | H6: 0.1 | I6: 0.1 | J6: =IF(ISNUMBER('Results'!$E$6),'Results'!$E$6,0) | K6: =IF(ISNUMBER('Results'!$E$6),1,0) | L6: ='Metrics'!$B$21
A7: Reach inflow | B7: Hydrology | C7: Concentrated Runoff / Stormwater Inputs | D7: ='Metrics'!$F$34 | E7: ='Metrics'!$B$35 | F7: =IF(NOT(ISNUMBER('Results'!$E$7)),"Not assessed",IF('Results'!$E$7<=5,"Non-Functioning",IF('Results'!$E$7<=10,"Functioning-at-Risk","Functioning"))) | G7: 1 | H7: 0.1 | I7: 0.1 | J7: =IF(ISNUMBER('Results'!$E$7),'Results'!$E$7,0) | K7: =IF(ISNUMBER('Results'!$E$7),1,0) | L7: ='Metrics'!$B$31
A8: Streamflow regime | B8: Hydrology | C8: Flow Alteration (Regulation / Water Use) | D8: ='Metrics'!$F$46 | E8: ='Metrics'!$B$47 | F8: =IF(NOT(ISNUMBER('Results'!$E$8)),"Not assessed",IF('Results'!$E$8<=5,"Non-Functioning",IF('Results'!$E$8<=10,"Functioning-at-Risk","Functioning"))) | G8: 1 | H8: 0.1 | I8: 0.1 | J8: =IF(ISNUMBER('Results'!$E$8),'Results'!$E$8,0) | K8: =IF(ISNUMBER('Results'!$E$8),1,0) | L8: ='Metrics'!$B$43
A9: Low flow and baseflow dynamics | B9: Hydraulics | C9: Low-flow Wetted Connectivity | D9: ='Metrics'!$F$59 | E9: ='Metrics'!$B$60 | F9: =IF(NOT(ISNUMBER('Results'!$E$9)),"Not assessed",IF('Results'!$E$9<=5,"Non-Functioning",IF('Results'!$E$9<=10,"Functioning-at-Risk","Functioning"))) | G9: 1 | H9: 0.1 | I9: 0.1 | J9: =IF(ISNUMBER('Results'!$E$9),'Results'!$E$9,0) | K9: =IF(ISNUMBER('Results'!$E$9),1,0) | L9: ='Metrics'!$B$56
A10: High flow dynamics | B10: Hydraulics | C10: Floodplain Engagement Frequency (bankfull recurrence) | D10: ='Metrics'!$F$69 | E10: ='Metrics'!$B$70 | F10: =IF(NOT(ISNUMBER('Results'!$E$10)),"Not assessed",IF('Results'!$E$10<=5,"Non-Functioning",IF('Results'!$E$10<=10,"Functioning-at-Risk","Functioning"))) | G10: 1 | H10: 0.1 | I10: 0.1 | J10: =IF(ISNUMBER('Results'!$E$10),'Results'!$E$10,0) | K10: =IF(ISNUMBER('Results'!$E$10),1,0) | L10: ='Metrics'!$B$66
A11: Floodplain connectivity | B11: Hydraulics | C11: Floodplain Access / Entrenchment | D11: ='Metrics'!$F$81 | E11: ='Metrics'!$B$82 | F11: =IF(NOT(ISNUMBER('Results'!$E$11)),"Not assessed",IF('Results'!$E$11<=5,"Non-Functioning",IF('Results'!$E$11<=10,"Functioning-at-Risk","Functioning"))) | G11: 1 | H11: 0.1 | I11: 0.1 | J11: =IF(ISNUMBER('Results'!$E$11),'Results'!$E$11,0) | K11: =IF(ISNUMBER('Results'!$E$11),1,0) | L11: ='Metrics'!$B$78
A12: Hyporheic connectivity | B12: Hydraulics | C12: Hyporheic Exchange Indicators | D12: ='Metrics'!$F$94 | E12: ='Metrics'!$B$95 | F12: =IF(NOT(ISNUMBER('Results'!$E$12)),"Not assessed",IF('Results'!$E$12<=5,"Non-Functioning",IF('Results'!$E$12<=10,"Functioning-at-Risk","Functioning"))) | G12: 1 | H12: 0.1 | I12: 0.1 | J12: =IF(ISNUMBER('Results'!$E$12),'Results'!$E$12,0) | K12: =IF(ISNUMBER('Results'!$E$12),1,0) | L12: ='Metrics'!$B$91
A13: Channel evolution | B13: Geomorphology | C13: Channel Evolution Stage & Trends | D13: ='Metrics'!$F$108 | E13: ='Metrics'!$B$109 | F13: =IF(NOT(ISNUMBER('Results'!$E$13)),"Not assessed",IF('Results'!$E$13<=5,"Non-Functioning",IF('Results'!$E$13<=10,"Functioning-at-Risk","Functioning"))) | G13: 1 | H13: 0.1 | I13: 0.1 | J13: =IF(ISNUMBER('Results'!$E$13),'Results'!$E$13,0) | K13: =IF(ISNUMBER('Results'!$E$13),1,0) | L13: ='Metrics'!$B$105
A14: Channel and floodplain dynamics | B14: Geomorphology | C14: Bank Erosion & Armoring Condition | D14: ='Metrics'!$F$120 | E14: ='Metrics'!$B$121 | F14: =IF(NOT(ISNUMBER('Results'!$E$14)),"Not assessed",IF('Results'!$E$14<=5,"Non-Functioning",IF('Results'!$E$14<=10,"Functioning-at-Risk","Functioning"))) | G14: 1 | H14: 0.1 | I14: 0.1 | J14: =IF(ISNUMBER('Results'!$E$14),'Results'!$E$14,0) | K14: =IF(ISNUMBER('Results'!$E$14),1,0) | L14: ='Metrics'!$B$117
A15: Sediment continuity | B15: Geomorphology | C15: Sediment Supply Potential (watershed/banks) | D15: ='Metrics'!$F$134 | E15: ='Metrics'!$B$135 | F15: =IF(NOT(ISNUMBER('Results'!$E$15)),"Not assessed",IF('Results'!$E$15<=5,"Non-Functioning",IF('Results'!$E$15<=10,"Functioning-at-Risk","Functioning"))) | G15: 1 | H15: 0.1 | I15: 0.1 | J15: =IF(ISNUMBER('Results'!$E$15),'Results'!$E$15,0) | K15: =IF(ISNUMBER('Results'!$E$15),1,0) | L15: ='Metrics'!$B$131
A16: Bed composition and large wood | B16: Geomorphology | C16: Substrate Condition (grain size/embeddedness/fines/consolidation) | D16: ='Metrics'!$F$144 | E16: ='Metrics'!$B$145 | F16: =IF(NOT(ISNUMBER('Results'!$E$16)),"Not assessed",IF('Results'!$E$16<=5,"Non-Functioning",IF('Results'!$E$16<=10,"Functioning-at-Risk","Functioning"))) | G16: 1 | H16: 0.1 | I16: 0.1 | J16: =IF(ISNUMBER('Results'!$E$16),'Results'!$E$16,0) | K16: =IF(ISNUMBER('Results'!$E$16),1,0) | L16: ='Metrics'!$B$141
A17: Light & thermal regime | B17: Physicochemistry | C17: Stream Temperature | D17: ='Metrics'!$F$159 | E17: ='Metrics'!$B$160 | F17: =IF(NOT(ISNUMBER('Results'!$E$17)),"Not assessed",IF('Results'!$E$17<=5,"Non-Functioning",IF('Results'!$E$17<=10,"Functioning-at-Risk","Functioning"))) | G17: 0 | H17: 1 | I17: 0.1 | J17: =IF(ISNUMBER('Results'!$E$17),'Results'!$E$17,0) | K17: =IF(ISNUMBER('Results'!$E$17),1,0) | L17: ='Metrics'!$B$156
A18: Carbon processing | B18: Physicochemistry | C18: Detrital Processing (CPOM retention / shredders) | D18: ='Metrics'!$F$175 | E18: ='Metrics'!$B$176 | F18: =IF(NOT(ISNUMBER('Results'!$E$18)),"Not assessed",IF('Results'!$E$18<=5,"Non-Functioning",IF('Results'!$E$18<=10,"Functioning-at-Risk","Functioning"))) | G18: 0 | H18: 1 | I18: 0.1 | J18: =IF(ISNUMBER('Results'!$E$18),'Results'!$E$18,0) | K18: =IF(ISNUMBER('Results'!$E$18),1,0) | L18: ='Metrics'!$B$172
A19: Nutrient cycling | B19: Physicochemistry | C19: Nitrogen & Phosphorus Concentrations | D19: ='Metrics'!$F$187 | E19: ='Metrics'!$B$188 | F19: =IF(NOT(ISNUMBER('Results'!$E$19)),"Not assessed",IF('Results'!$E$19<=5,"Non-Functioning",IF('Results'!$E$19<=10,"Functioning-at-Risk","Functioning"))) | G19: 0.1 | H19: 1 | I19: 0.1 | J19: =IF(ISNUMBER('Results'!$E$19),'Results'!$E$19,0) | K19: =IF(ISNUMBER('Results'!$E$19),1,0) | L19: ='Metrics'!$B$184
A20: Water & soil quality | B20: Physicochemistry | C20: Regulatory Impairment Status (305b/303d/TMDL) | D20: ='Metrics'!$F$198 | E20: ='Metrics'!$B$199 | F20: =IF(NOT(ISNUMBER('Results'!$E$20)),"Not assessed",IF('Results'!$E$20<=5,"Non-Functioning",IF('Results'!$E$20<=10,"Functioning-at-Risk","Functioning"))) | G20: 0.1 | H20: 1 | I20: 0.1 | J20: =IF(ISNUMBER('Results'!$E$20),'Results'!$E$20,0) | K20: =IF(ISNUMBER('Results'!$E$20),1,0) | L20: ='Metrics'!$B$195
A21: Habitat provision | B21: Biology | C21: In-stream Habitat Complexity & Cover | D21: ='Metrics'!$F$211 | E21: ='Metrics'!$B$212 | F21: =IF(NOT(ISNUMBER('Results'!$E$21)),"Not assessed",IF('Results'!$E$21<=5,"Non-Functioning",IF('Results'!$E$21<=10,"Functioning-at-Risk","Functioning"))) | G21: 0 | H21: 0 | I21: 1 | J21: =IF(ISNUMBER('Results'!$E$21),'Results'!$E$21,0) | K21: =IF(ISNUMBER('Results'!$E$21),1,0) | L21: ='Metrics'!$B$208
A22: Population support | B22: Biology | C22: Biological Integrity (IBI / community condition) | D22: ='Metrics'!$F$224 | E22: ='Metrics'!$B$225 | F22: =IF(NOT(ISNUMBER('Results'!$E$22)),"Not assessed",IF('Results'!$E$22<=5,"Non-Functioning",IF('Results'!$E$22<=10,"Functioning-at-Risk","Functioning"))) | G22: 0.1 | H22: 0.1 | I22: 1 | J22: =IF(ISNUMBER('Results'!$E$22),'Results'!$E$22,0) | K22: =IF(ISNUMBER('Results'!$E$22),1,0) | L22: ='Metrics'!$B$221
A23: Community dynamics | B23: Biology | C23: Invasive / Non-native Species Presence | D23: ='Metrics'!$F$234 | E23: ='Metrics'!$B$235 | F23: =IF(NOT(ISNUMBER('Results'!$E$23)),"Not assessed",IF('Results'!$E$23<=5,"Non-Functioning",IF('Results'!$E$23<=10,"Functioning-at-Risk","Functioning"))) | G23: 0.1 | H23: 0.1 | I23: 1 | J23: =IF(ISNUMBER('Results'!$E$23),'Results'!$E$23,0) | K23: =IF(ISNUMBER('Results'!$E$23),1,0) | L23: ='Metrics'!$B$231
A24: Watershed connectivity | B24: Biology | C24: Fish Passage & Barrier Effects (longitudinal connectivity) | D24: ='Metrics'!$F$244 | E24: ='Metrics'!$B$245 | F24: =IF(NOT(ISNUMBER('Results'!$E$24)),"Not assessed",IF('Results'!$E$24<=5,"Non-Functioning",IF('Results'!$E$24<=10,"Functioning-at-Risk","Functioning"))) | G24: 0.1 | H24: 0 | I24: 1 | J24: =IF(ISNUMBER('Results'!$E$24),'Results'!$E$24,0) | K24: =IF(ISNUMBER('Results'!$E$24),1,0) | L24: ='Metrics'!$B$241
A26: Outcome | B26: Weighted score | C26: Weighted maximum | D26: Sub-index | E26: Displayed | F26: Class | G26: Coverage
A27: Physical | B27: =SUMPRODUCT('Results'!$J$5:$J$24,'Results'!$G$5:$G$24,'Results'!$K$5:$K$24) | C27: =SUMPRODUCT('Results'!$G$5:$G$24,'Results'!$K$5:$K$24)*15 | D27: =IF('Results'!$C$27=0,"",'Results'!$B$27/'Results'!$C$27) | E27: =IF('Results'!$D$27="","",ROUND('Results'!$D$27,2)) | F27: =IF('Results'!$E$27="","Not assessed",IF('Results'!$E$27<=0.39,"Non-Functioning",IF('Results'!$E$27<=0.69,"Functioning-at-Risk","Functioning"))) | G27: =IF(SUMPRODUCT('Results'!$G$5:$G$24)=0,"",SUMPRODUCT('Results'!$G$5:$G$24,'Results'!$K$5:$K$24)/SUMPRODUCT('Results'!$G$5:$G$24))
A28: Chemical | B28: =SUMPRODUCT('Results'!$J$5:$J$24,'Results'!$H$5:$H$24,'Results'!$K$5:$K$24) | C28: =SUMPRODUCT('Results'!$H$5:$H$24,'Results'!$K$5:$K$24)*15 | D28: =IF('Results'!$C$28=0,"",'Results'!$B$28/'Results'!$C$28) | E28: =IF('Results'!$D$28="","",ROUND('Results'!$D$28,2)) | F28: =IF('Results'!$E$28="","Not assessed",IF('Results'!$E$28<=0.39,"Non-Functioning",IF('Results'!$E$28<=0.69,"Functioning-at-Risk","Functioning"))) | G28: =IF(SUMPRODUCT('Results'!$H$5:$H$24)=0,"",SUMPRODUCT('Results'!$H$5:$H$24,'Results'!$K$5:$K$24)/SUMPRODUCT('Results'!$H$5:$H$24))
A29: Biological | B29: =SUMPRODUCT('Results'!$J$5:$J$24,'Results'!$I$5:$I$24,'Results'!$K$5:$K$24) | C29: =SUMPRODUCT('Results'!$I$5:$I$24,'Results'!$K$5:$K$24)*15 | D29: =IF('Results'!$C$29=0,"",'Results'!$B$29/'Results'!$C$29) | E29: =IF('Results'!$D$29="","",ROUND('Results'!$D$29,2)) | F29: =IF('Results'!$E$29="","Not assessed",IF('Results'!$E$29<=0.39,"Non-Functioning",IF('Results'!$E$29<=0.69,"Functioning-at-Risk","Functioning"))) | G29: =IF(SUMPRODUCT('Results'!$I$5:$I$24)=0,"",SUMPRODUCT('Results'!$I$5:$I$24,'Results'!$K$5:$K$24)/SUMPRODUCT('Results'!$I$5:$I$24))
A30: Ecosystem Condition Index | D30: =IF(COUNT('Results'!$D$27,'Results'!$D$28,'Results'!$D$29)=0,"",AVERAGE('Results'!$D$27,'Results'!$D$28,'Results'!$D$29)) | E30: =IF('Results'!$D$30="","",ROUND('Results'!$D$30,2)) | F30: =IF('Results'!$E$30="","Not assessed",IF('Results'!$E$30<=0.39,"Non-Functioning",IF('Results'!$E$30<=0.69,"Functioning-at-Risk","Functioning")))
A32: Coverage | B32: Value
A33: Functions rated | B33: =SUM('Results'!$K$5:$K$24)
A34: Functions selected | B34: 20
A35: Overall coverage | B35: ='Results'!$B$33/'Results'!$B$34
A36: Provisional (coverage below 0.70 overall or for an outcome) | B36: =IF(OR(AND(ISNUMBER('Results'!$B$35),'Results'!$B$35<0.7),AND(ISNUMBER('Results'!$G$27),'Results'!$G$27<0.7),AND(ISNUMBER('Results'!$G$28),'Results'!$G$28<0.7),AND(ISNUMBER('Results'!$G$29),'Results'!$G$29<0.7)),"yes","no")
A37: Status | B37: =IF('Results'!$B$35=1,"Complete screening coverage","Partial screening coverage")

Sheet ChartData
A1: Chart series (hidden). One column per class so each bar takes the class colour.
A2: Function | B2: Score | C2: Non-Functioning (0-5) | D2: Functioning At-Risk (6-10) | E2: Functioning (11-15)
A3: Catchment hydrology | B3: =IF('Scenario'!$H$8="","",'Scenario'!$H$8) | C3: =IF(ISNUMBER('ChartData'!$B$3),IF('ChartData'!$B$3<=5,'ChartData'!$B$3,NA()),NA()) | D3: =IF(ISNUMBER('ChartData'!$B$3),IF(AND('ChartData'!$B$3>5,'ChartData'!$B$3<=10),'ChartData'!$B$3,NA()),NA()) | E3: =IF(ISNUMBER('ChartData'!$B$3),IF('ChartData'!$B$3>10,'ChartData'!$B$3,NA()),NA())
A4: Surface water storage | B4: =IF('Scenario'!$H$11="","",'Scenario'!$H$11) | C4: =IF(ISNUMBER('ChartData'!$B$4),IF('ChartData'!$B$4<=5,'ChartData'!$B$4,NA()),NA()) | D4: =IF(ISNUMBER('ChartData'!$B$4),IF(AND('ChartData'!$B$4>5,'ChartData'!$B$4<=10),'ChartData'!$B$4,NA()),NA()) | E4: =IF(ISNUMBER('ChartData'!$B$4),IF('ChartData'!$B$4>10,'ChartData'!$B$4,NA()),NA())
A5: Reach inflow | B5: =IF('Scenario'!$H$15="","",'Scenario'!$H$15) | C5: =IF(ISNUMBER('ChartData'!$B$5),IF('ChartData'!$B$5<=5,'ChartData'!$B$5,NA()),NA()) | D5: =IF(ISNUMBER('ChartData'!$B$5),IF(AND('ChartData'!$B$5>5,'ChartData'!$B$5<=10),'ChartData'!$B$5,NA()),NA()) | E5: =IF(ISNUMBER('ChartData'!$B$5),IF('ChartData'!$B$5>10,'ChartData'!$B$5,NA()),NA())
A6: Streamflow regime | B6: =IF('Scenario'!$H$17="","",'Scenario'!$H$17) | C6: =IF(ISNUMBER('ChartData'!$B$6),IF('ChartData'!$B$6<=5,'ChartData'!$B$6,NA()),NA()) | D6: =IF(ISNUMBER('ChartData'!$B$6),IF(AND('ChartData'!$B$6>5,'ChartData'!$B$6<=10),'ChartData'!$B$6,NA()),NA()) | E6: =IF(ISNUMBER('ChartData'!$B$6),IF('ChartData'!$B$6>10,'ChartData'!$B$6,NA()),NA())
A7: Low flow and baseflow dynamics | B7: =IF('Scenario'!$H$21="","",'Scenario'!$H$21) | C7: =IF(ISNUMBER('ChartData'!$B$7),IF('ChartData'!$B$7<=5,'ChartData'!$B$7,NA()),NA()) | D7: =IF(ISNUMBER('ChartData'!$B$7),IF(AND('ChartData'!$B$7>5,'ChartData'!$B$7<=10),'ChartData'!$B$7,NA()),NA()) | E7: =IF(ISNUMBER('ChartData'!$B$7),IF('ChartData'!$B$7>10,'ChartData'!$B$7,NA()),NA())
A8: High flow dynamics | B8: =IF('Scenario'!$H$23="","",'Scenario'!$H$23) | C8: =IF(ISNUMBER('ChartData'!$B$8),IF('ChartData'!$B$8<=5,'ChartData'!$B$8,NA()),NA()) | D8: =IF(ISNUMBER('ChartData'!$B$8),IF(AND('ChartData'!$B$8>5,'ChartData'!$B$8<=10),'ChartData'!$B$8,NA()),NA()) | E8: =IF(ISNUMBER('ChartData'!$B$8),IF('ChartData'!$B$8>10,'ChartData'!$B$8,NA()),NA())
A9: Floodplain connectivity | B9: =IF('Scenario'!$H$25="","",'Scenario'!$H$25) | C9: =IF(ISNUMBER('ChartData'!$B$9),IF('ChartData'!$B$9<=5,'ChartData'!$B$9,NA()),NA()) | D9: =IF(ISNUMBER('ChartData'!$B$9),IF(AND('ChartData'!$B$9>5,'ChartData'!$B$9<=10),'ChartData'!$B$9,NA()),NA()) | E9: =IF(ISNUMBER('ChartData'!$B$9),IF('ChartData'!$B$9>10,'ChartData'!$B$9,NA()),NA())
A10: Hyporheic connectivity | B10: =IF('Scenario'!$H$28="","",'Scenario'!$H$28) | C10: =IF(ISNUMBER('ChartData'!$B$10),IF('ChartData'!$B$10<=5,'ChartData'!$B$10,NA()),NA()) | D10: =IF(ISNUMBER('ChartData'!$B$10),IF(AND('ChartData'!$B$10>5,'ChartData'!$B$10<=10),'ChartData'!$B$10,NA()),NA()) | E10: =IF(ISNUMBER('ChartData'!$B$10),IF('ChartData'!$B$10>10,'ChartData'!$B$10,NA()),NA())
A11: Channel evolution | B11: =IF('Scenario'!$H$31="","",'Scenario'!$H$31) | C11: =IF(ISNUMBER('ChartData'!$B$11),IF('ChartData'!$B$11<=5,'ChartData'!$B$11,NA()),NA()) | D11: =IF(ISNUMBER('ChartData'!$B$11),IF(AND('ChartData'!$B$11>5,'ChartData'!$B$11<=10),'ChartData'!$B$11,NA()),NA()) | E11: =IF(ISNUMBER('ChartData'!$B$11),IF('ChartData'!$B$11>10,'ChartData'!$B$11,NA()),NA())
A12: Channel and floodplain dynamics | B12: =IF('Scenario'!$H$36="","",'Scenario'!$H$36) | C12: =IF(ISNUMBER('ChartData'!$B$12),IF('ChartData'!$B$12<=5,'ChartData'!$B$12,NA()),NA()) | D12: =IF(ISNUMBER('ChartData'!$B$12),IF(AND('ChartData'!$B$12>5,'ChartData'!$B$12<=10),'ChartData'!$B$12,NA()),NA()) | E12: =IF(ISNUMBER('ChartData'!$B$12),IF('ChartData'!$B$12>10,'ChartData'!$B$12,NA()),NA())
A13: Sediment continuity | B13: =IF('Scenario'!$H$40="","",'Scenario'!$H$40) | C13: =IF(ISNUMBER('ChartData'!$B$13),IF('ChartData'!$B$13<=5,'ChartData'!$B$13,NA()),NA()) | D13: =IF(ISNUMBER('ChartData'!$B$13),IF(AND('ChartData'!$B$13>5,'ChartData'!$B$13<=10),'ChartData'!$B$13,NA()),NA()) | E13: =IF(ISNUMBER('ChartData'!$B$13),IF('ChartData'!$B$13>10,'ChartData'!$B$13,NA()),NA())
A14: Bed composition and large wood | B14: =IF('Scenario'!$H$44="","",'Scenario'!$H$44) | C14: =IF(ISNUMBER('ChartData'!$B$14),IF('ChartData'!$B$14<=5,'ChartData'!$B$14,NA()),NA()) | D14: =IF(ISNUMBER('ChartData'!$B$14),IF(AND('ChartData'!$B$14>5,'ChartData'!$B$14<=10),'ChartData'!$B$14,NA()),NA()) | E14: =IF(ISNUMBER('ChartData'!$B$14),IF('ChartData'!$B$14>10,'ChartData'!$B$14,NA()),NA())
A15: Light & thermal regime | B15: =IF('Scenario'!$H$46="","",'Scenario'!$H$46) | C15: =IF(ISNUMBER('ChartData'!$B$15),IF('ChartData'!$B$15<=5,'ChartData'!$B$15,NA()),NA()) | D15: =IF(ISNUMBER('ChartData'!$B$15),IF(AND('ChartData'!$B$15>5,'ChartData'!$B$15<=10),'ChartData'!$B$15,NA()),NA()) | E15: =IF(ISNUMBER('ChartData'!$B$15),IF('ChartData'!$B$15>10,'ChartData'!$B$15,NA()),NA())
A16: Carbon processing | B16: =IF('Scenario'!$H$49="","",'Scenario'!$H$49) | C16: =IF(ISNUMBER('ChartData'!$B$16),IF('ChartData'!$B$16<=5,'ChartData'!$B$16,NA()),NA()) | D16: =IF(ISNUMBER('ChartData'!$B$16),IF(AND('ChartData'!$B$16>5,'ChartData'!$B$16<=10),'ChartData'!$B$16,NA()),NA()) | E16: =IF(ISNUMBER('ChartData'!$B$16),IF('ChartData'!$B$16>10,'ChartData'!$B$16,NA()),NA())
A17: Nutrient cycling | B17: =IF('Scenario'!$H$55="","",'Scenario'!$H$55) | C17: =IF(ISNUMBER('ChartData'!$B$17),IF('ChartData'!$B$17<=5,'ChartData'!$B$17,NA()),NA()) | D17: =IF(ISNUMBER('ChartData'!$B$17),IF(AND('ChartData'!$B$17>5,'ChartData'!$B$17<=10),'ChartData'!$B$17,NA()),NA()) | E17: =IF(ISNUMBER('ChartData'!$B$17),IF('ChartData'!$B$17>10,'ChartData'!$B$17,NA()),NA())
A18: Water & soil quality | B18: =IF('Scenario'!$H$60="","",'Scenario'!$H$60) | C18: =IF(ISNUMBER('ChartData'!$B$18),IF('ChartData'!$B$18<=5,'ChartData'!$B$18,NA()),NA()) | D18: =IF(ISNUMBER('ChartData'!$B$18),IF(AND('ChartData'!$B$18>5,'ChartData'!$B$18<=10),'ChartData'!$B$18,NA()),NA()) | E18: =IF(ISNUMBER('ChartData'!$B$18),IF('ChartData'!$B$18>10,'ChartData'!$B$18,NA()),NA())
A19: Habitat provision | B19: =IF('Scenario'!$H$64="","",'Scenario'!$H$64) | C19: =IF(ISNUMBER('ChartData'!$B$19),IF('ChartData'!$B$19<=5,'ChartData'!$B$19,NA()),NA()) | D19: =IF(ISNUMBER('ChartData'!$B$19),IF(AND('ChartData'!$B$19>5,'ChartData'!$B$19<=10),'ChartData'!$B$19,NA()),NA()) | E19: =IF(ISNUMBER('ChartData'!$B$19),IF('ChartData'!$B$19>10,'ChartData'!$B$19,NA()),NA())
A20: Population support | B20: =IF('Scenario'!$H$66="","",'Scenario'!$H$66) | C20: =IF(ISNUMBER('ChartData'!$B$20),IF('ChartData'!$B$20<=5,'ChartData'!$B$20,NA()),NA()) | D20: =IF(ISNUMBER('ChartData'!$B$20),IF(AND('ChartData'!$B$20>5,'ChartData'!$B$20<=10),'ChartData'!$B$20,NA()),NA()) | E20: =IF(ISNUMBER('ChartData'!$B$20),IF('ChartData'!$B$20>10,'ChartData'!$B$20,NA()),NA())
A21: Community dynamics | B21: =IF('Scenario'!$H$82="","",'Scenario'!$H$82) | C21: =IF(ISNUMBER('ChartData'!$B$21),IF('ChartData'!$B$21<=5,'ChartData'!$B$21,NA()),NA()) | D21: =IF(ISNUMBER('ChartData'!$B$21),IF(AND('ChartData'!$B$21>5,'ChartData'!$B$21<=10),'ChartData'!$B$21,NA()),NA()) | E21: =IF(ISNUMBER('ChartData'!$B$21),IF('ChartData'!$B$21>10,'ChartData'!$B$21,NA()),NA())
A22: Watershed connectivity | B22: =IF('Scenario'!$H$84="","",'Scenario'!$H$84) | C22: =IF(ISNUMBER('ChartData'!$B$22),IF('ChartData'!$B$22<=5,'ChartData'!$B$22,NA()),NA()) | D22: =IF(ISNUMBER('ChartData'!$B$22),IF(AND('ChartData'!$B$22>5,'ChartData'!$B$22<=10),'ChartData'!$B$22,NA()),NA()) | E22: =IF(ISNUMBER('ChartData'!$B$22),IF('ChartData'!$B$22>10,'ChartData'!$B$22,NA()),NA())
A24: Outcome | B24: Score | C24: Non-Functioning (0.00-0.39) | D24: Functioning At-Risk (0.40-0.69) | E24: Functioning (0.70-1.00)
A25: Physical | B25: =IF('Results'!$E$27="","",'Results'!$E$27) | C25: =IF(ISNUMBER('ChartData'!$B$25),IF('ChartData'!$B$25<=0.39,'ChartData'!$B$25,NA()),NA()) | D25: =IF(ISNUMBER('ChartData'!$B$25),IF(AND('ChartData'!$B$25>0.39,'ChartData'!$B$25<=0.69),'ChartData'!$B$25,NA()),NA()) | E25: =IF(ISNUMBER('ChartData'!$B$25),IF('ChartData'!$B$25>0.69,'ChartData'!$B$25,NA()),NA())
A26: Chemical | B26: =IF('Results'!$E$28="","",'Results'!$E$28) | C26: =IF(ISNUMBER('ChartData'!$B$26),IF('ChartData'!$B$26<=0.39,'ChartData'!$B$26,NA()),NA()) | D26: =IF(ISNUMBER('ChartData'!$B$26),IF(AND('ChartData'!$B$26>0.39,'ChartData'!$B$26<=0.69),'ChartData'!$B$26,NA()),NA()) | E26: =IF(ISNUMBER('ChartData'!$B$26),IF('ChartData'!$B$26>0.69,'ChartData'!$B$26,NA()),NA())
A27: Biological | B27: =IF('Results'!$E$29="","",'Results'!$E$29) | C27: =IF(ISNUMBER('ChartData'!$B$27),IF('ChartData'!$B$27<=0.39,'ChartData'!$B$27,NA()),NA()) | D27: =IF(ISNUMBER('ChartData'!$B$27),IF(AND('ChartData'!$B$27>0.39,'ChartData'!$B$27<=0.69),'ChartData'!$B$27,NA()),NA()) | E27: =IF(ISNUMBER('ChartData'!$B$27),IF('ChartData'!$B$27>0.69,'ChartData'!$B$27,NA()),NA())
